Workbook
Name Financial_Summary: #REF!
Name IQ_CH: 110000
Name IQ_CQ: 5000
Name IQ_CY: 10000
Name IQ_DAILY: 500000
Name IQ_FH: 100000
Name IQ_FQ: 500
Name IQ_FY: 1000
Name IQ_LTM: 2000
Name IQ_MONTH: 15000
Name IQ_NTM: 6000
Name IQ_WEEK: 50000
Name IQ_YTD: 3000

Sheet Sheet4
A1: Picture
D2: Stats
D3: Rent Roll
A4: Address | D4: Unit Count
D5: Yields

Sheet Diligence and Notes
B3: Notes
B4: 1 | C4: [This is a space to take notes on the deal]
B5: 2
B6: 3
B8: Diligence Questions
B9: 1 | C9: [This is a space to record diligence questions / items on the deal]
B10: 2
B11: 3

Sheet Underwriting Assumptions
C3: Underwriting Assumptions
J4: Monthly | K4: Annual | M4: Notes
C5: Pro Forma Rent Roll | J5: =+K5/12 -> 165312.07 | K5: =+Assumptions!K124 -> 1983744.8 | M5: Current Rent Roll
C6: ="Plus: "&Assumptions!B131 -> Plus: Total Amenity Income | J6: =+K6/12 -> 7721 | K6: =+Assumptions!J131 -> 92652 | M6: Laundry Currently
C7: Less: Vacancy, Turnover, Bad Debt | G7: =-Assumptions!G148-Assumptions!G147-Assumptions!K146 -> -0.076666667 | J7: =+$G$7*J5 -> -12673.925 | K7: =+$G$7*K5 -> -152087.1 | M7: 5% Vacancy + 20% Turnover
C8: Effective Gross Income | J8: =SUM(J5:J7) -> 160359.14 | K8: =SUM(K5:K7) -> 1924309.7
C10: =Assumptions!B150 -> Operating Expenses | H10: =Assumptions!G150 -> Factor | I10: =Assumptions!H150 -> Statistic | J10: =Assumptions!I150 -> Monthly | K10: =Assumptions!J150 -> Annual
C11: =Assumptions!B151 -> Property Taxes | H11: =Assumptions!G151 -> 3815.7179 | I11: =Assumptions!H151 -> 78 | J11: =Assumptions!I151 -> 24802.167 | K11: =Assumptions!J151 -> 297626 | M11: Broker
C12: =Assumptions!B152 -> Insurance | H12: =Assumptions!G152 -> 910 | I12: =Assumptions!H152 -> 78 | J12: =Assumptions!I152 -> 5915 | K12: =Assumptions!J152 -> 70980 | M12: Estimate
C13: =Assumptions!B153 -> Water / Sewer | H13: =Assumptions!G153 -> 600.89744 | I13: =Assumptions!H153 -> 78 | J13: =Assumptions!I153 -> 3905.8333 | K13: =Assumptions!J153 -> 46870 | M13: Estimate
C14: =Assumptions!B154 -> Repairs & Maintenance | H14: =Assumptions!G154 -> 500 | I14: =Assumptions!H154 -> 78 | J14: =Assumptions!I154 -> 3250 | K14: =Assumptions!J154 -> 39000 | M14: Estimate
C15: =Assumptions!B155 -> Bank fees | J15: =Assumptions!I155 -> 162.5 | K15: =Assumptions!J155 -> 1950 | M15: Estimate
C16: =Assumptions!B156 -> Trash | J16: =Assumptions!I156 -> 200 | K16: =Assumptions!J156 -> 2400 | M16: Estimate (NEW)
C17: =Assumptions!B158 -> Security, Internet | J17: =Assumptions!I158 -> 200 | K17: =Assumptions!J158 -> 2400 | M17: Estimate (NEW)
C18: =Assumptions!B159 -> Pest Control | H18: =Assumptions!G159 -> 75 | I18: =Assumptions!H159 -> 78 | J18: =Assumptions!I159 -> 487.5 | K18: =Assumptions!J159 -> 5850 | M18: Estimate (NEW)
C19: =Assumptions!B162 -> Common Area Electric | H19: =Assumptions!G162 -> 0.67009901 | I19: =Assumptions!H162 -> 5050 | J19: =Assumptions!I162 -> 282 | K19: =Assumptions!J162 -> 3384 | M19: Broker
C20: =Assumptions!B163 -> Landscaping / Snow Removal | J20: =Assumptions!I163 -> 1250 | K20: =Assumptions!J163 -> 15000 | M20: Estimate
C21: =Assumptions!B164 -> Property Management | H21: =Assumptions!G164 -> 0.03 | I21: =Assumptions!H164 -> 1937970.4 | J21: =Assumptions!I164 -> 4844.926 | K21: =Assumptions!J164 -> 58139.112 | M21: PCG PM Fee
C22: =Assumptions!B165 -> Accounting / Legal | J22: =Assumptions!I165 -> 291.66667 | K22: =Assumptions!J165 -> 3500 | M22: Estimate (NEW)
C23: =+Assumptions!B166 -> Total Operating Expenses | J23: =Assumptions!I166 -> 55431.926 | K23: =Assumptions!J166 -> 665183.11
C24: Operating Expense Margin | K24: =+K23/K8 -> 0.34567362
C26: Net Operating Income | J26: =+J8-J23 -> 104927.22 | K26: =+K8-K23 -> 1259126.6
C27: ="Implied Stabilized Cap Rate at "&TEXT(Assumptions!G22,"$#,##0")&" Purchase" -> Implied Stabilized Cap Rate at $14,900,000 Purchase | K27: =+K26/Assumptions!G22 -> 0.084505143

Sheet NOI
C3: Net Operating Income Summary
G4: 1 | H4: =+G4+1 -> 2 | I4: =+H4+1 -> 3 | J4: =+I4+1 -> 4 | K4: =+J4+1 -> 5
C5: ='NOI Walk'!B20 -> Gross Potential Rent | G5: =+SUMIFS('NOI Walk'!$E20:$CW20,'NOI Walk'!$E$14:$CW$14,NOI!G$4) -> 2010814.3 | H5: =+SUMIFS('NOI Walk'!$E20:$CW20,'NOI Walk'!$E$14:$CW$14,NOI!H$4) -> 2061664.7 | I5: =+SUMIFS('NOI Walk'!$E20:$CW20,'NOI Walk'!$E$14:$CW$14,NOI!I$4) -> 2113801 | J5: =+SUMIFS('NOI Walk'!$E20:$CW20,'NOI Walk'!$E$14:$CW$14,NOI!J$4) -> 2167255.8 | K5: =+SUMIFS('NOI Walk'!$E20:$CW20,'NOI Walk'!$E$14:$CW$14,NOI!K$4) -> 2222062.4
C6: Loss-to-Lease | G6: =+SUMIFS('NOI Walk'!$E21:$CW21,'NOI Walk'!$E$14:$CW$14,NOI!G$4) -> -459561.05 | H6: =+SUMIFS('NOI Walk'!$E21:$CW21,'NOI Walk'!$E$14:$CW$14,NOI!H$4) -> -212925.15 | I6: =+SUMIFS('NOI Walk'!$E21:$CW21,'NOI Walk'!$E$14:$CW$14,NOI!I$4) -> 34561.397 | J6: =+SUMIFS('NOI Walk'!$E21:$CW21,'NOI Walk'!$E$14:$CW$14,NOI!J$4) -> 99676.363 | K6: =+SUMIFS('NOI Walk'!$E21:$CW21,'NOI Walk'!$E$14:$CW$14,NOI!K$4) -> 101023.89
C7: Vacancy | G7: =+SUMIFS('NOI Walk'!$E22:$CW22,'NOI Walk'!$E$14:$CW$14,NOI!G$4) -> -150388.05 | H7: =+SUMIFS('NOI Walk'!$E22:$CW22,'NOI Walk'!$E$14:$CW$14,NOI!H$4) -> -223199.3 | I7: =+SUMIFS('NOI Walk'!$E22:$CW22,'NOI Walk'!$E$14:$CW$14,NOI!I$4) -> -154449.3 | J7: =+SUMIFS('NOI Walk'!$E22:$CW22,'NOI Walk'!$E$14:$CW$14,NOI!J$4) -> -107949.15 | K7: =+SUMIFS('NOI Walk'!$E22:$CW22,'NOI Walk'!$E$14:$CW$14,NOI!K$4) -> -110623.15
C8: ='NOI Walk'!B23 -> Vacancy | G8: =-G7/G5 -> 0.074789623 | H8: =-H7/H5 -> 0.10826169 | I8: =-I7/I5 -> 0.073067096 | J8: =-J7/J5 -> 0.049809141 | K8: =-K7/K5 -> 0.049784001
C9: Rental Income | G9: =+SUMIFS('NOI Walk'!$E24:$CW24,'NOI Walk'!$E$14:$CW$14,NOI!G$4) -> 1400865.2 | H9: =+SUMIFS('NOI Walk'!$E24:$CW24,'NOI Walk'!$E$14:$CW$14,NOI!H$4) -> 1625540.3 | I9: =+SUMIFS('NOI Walk'!$E24:$CW24,'NOI Walk'!$E$14:$CW$14,NOI!I$4) -> 1993913.1 | J9: =+SUMIFS('NOI Walk'!$E24:$CW24,'NOI Walk'!$E$14:$CW$14,NOI!J$4) -> 2158983 | K9: =+SUMIFS('NOI Walk'!$E24:$CW24,'NOI Walk'!$E$14:$CW$14,NOI!K$4) -> 2212463.1
C10: ='NOI Walk'!B25 -> Parking Income | G10: =+SUMIFS('NOI Walk'!$E25:$CW25,'NOI Walk'!$E$14:$CW$14,NOI!G$4) -> 4870.1051 | H10: =+SUMIFS('NOI Walk'!$E25:$CW25,'NOI Walk'!$E$14:$CW$14,NOI!H$4) -> 60474.335 | I10: =+SUMIFS('NOI Walk'!$E25:$CW25,'NOI Walk'!$E$14:$CW$14,NOI!I$4) -> 66738.292 | J10: =+SUMIFS('NOI Walk'!$E25:$CW25,'NOI Walk'!$E$14:$CW$14,NOI!J$4) -> 71582.162 | K10: =+SUMIFS('NOI Walk'!$E25:$CW25,'NOI Walk'!$E$14:$CW$14,NOI!K$4) -> 73027.002
C11: ='NOI Walk'!B26 -> Storage Income | G11: =+SUMIFS('NOI Walk'!$E26:$CW26,'NOI Walk'!$E$14:$CW$14,NOI!G$4) -> 2597.3894 | H11: =+SUMIFS('NOI Walk'!$E26:$CW26,'NOI Walk'!$E$14:$CW$14,NOI!H$4) -> 32252.978 | I11: =+SUMIFS('NOI Walk'!$E26:$CW26,'NOI Walk'!$E$14:$CW$14,NOI!I$4) -> 35593.755 | J11: =+SUMIFS('NOI Walk'!$E26:$CW26,'NOI Walk'!$E$14:$CW$14,NOI!J$4) -> 38177.153 | K11: =+SUMIFS('NOI Walk'!$E26:$CW26,'NOI Walk'!$E$14:$CW$14,NOI!K$4) -> 38947.734
C12: ='NOI Walk'!B27 -> Laundry Income | G12: =+SUMIFS('NOI Walk'!$E27:$CW27,'NOI Walk'!$E$14:$CW$14,NOI!G$4) -> 1883.1871 | H12: =+SUMIFS('NOI Walk'!$E27:$CW27,'NOI Walk'!$E$14:$CW$14,NOI!H$4) -> 1867.2777 | I12: =+SUMIFS('NOI Walk'!$E27:$CW27,'NOI Walk'!$E$14:$CW$14,NOI!I$4) -> 2060.6911 | J12: =+SUMIFS('NOI Walk'!$E27:$CW27,'NOI Walk'!$E$14:$CW$14,NOI!J$4) -> 2210.2562 | K12: =+SUMIFS('NOI Walk'!$E27:$CW27,'NOI Walk'!$E$14:$CW$14,NOI!K$4) -> 2254.8688
C13: ='NOI Walk'!B28 -> Gym / Amenity Space Income | G13: =+SUMIFS('NOI Walk'!$E28:$CW28,'NOI Walk'!$E$14:$CW$14,NOI!G$4) -> 42799.706 | H13: =+SUMIFS('NOI Walk'!$E28:$CW28,'NOI Walk'!$E$14:$CW$14,NOI!H$4) -> 42438.129 | I13: =+SUMIFS('NOI Walk'!$E28:$CW28,'NOI Walk'!$E$14:$CW$14,NOI!I$4) -> 46833.889 | J13: =+SUMIFS('NOI Walk'!$E28:$CW28,'NOI Walk'!$E$14:$CW$14,NOI!J$4) -> 50233.096 | K13: =+SUMIFS('NOI Walk'!$E28:$CW28,'NOI Walk'!$E$14:$CW$14,NOI!K$4) -> 51247.019
C14: ='NOI Walk'!B29 -> Turnover Costs | G14: =+SUMIFS('NOI Walk'!$E29:$CW29,'NOI Walk'!$E$14:$CW$14,NOI!G$4) -> 0 | H14: =+SUMIFS('NOI Walk'!$E29:$CW29,'NOI Walk'!$E$14:$CW$14,NOI!H$4) -> 0 | I14: =+SUMIFS('NOI Walk'!$E29:$CW29,'NOI Walk'!$E$14:$CW$14,NOI!I$4) -> -17664.032 | J14: =+SUMIFS('NOI Walk'!$E29:$CW29,'NOI Walk'!$E$14:$CW$14,NOI!J$4) -> -35983.05 | K14: =+SUMIFS('NOI Walk'!$E29:$CW29,'NOI Walk'!$E$14:$CW$14,NOI!K$4) -> -36874.385
C15: ='NOI Walk'!B31 -> Effective Gross Income | G15: =+SUMIFS('NOI Walk'!$E31:$CW31,'NOI Walk'!$E$14:$CW$14,NOI!G$4) -> 1438485.5 | H15: =+SUMIFS('NOI Walk'!$E31:$CW31,'NOI Walk'!$E$14:$CW$14,NOI!H$4) -> 1744947.3 | I15: =+SUMIFS('NOI Walk'!$E31:$CW31,'NOI Walk'!$E$14:$CW$14,NOI!I$4) -> 2106024.3 | J15: =+SUMIFS('NOI Walk'!$E31:$CW31,'NOI Walk'!$E$14:$CW$14,NOI!J$4) -> 2261990.8 | K15: =+SUMIFS('NOI Walk'!$E31:$CW31,'NOI Walk'!$E$14:$CW$14,NOI!K$4) -> 2317285.9
C17: ='NOI Walk'!B33 -> Operating Expenses
C18: ='NOI Walk'!B34 -> Property Taxes | G18: =+SUMIFS('NOI Walk'!$E34:$CW34,'NOI Walk'!$E$14:$CW$14,NOI!G$4) -> 300870.07 | H18: =+SUMIFS('NOI Walk'!$E34:$CW34,'NOI Walk'!$E$14:$CW$14,NOI!H$4) -> 306942.94 | I18: =+SUMIFS('NOI Walk'!$E34:$CW34,'NOI Walk'!$E$14:$CW$14,NOI!I$4) -> 313138.38 | J18: =+SUMIFS('NOI Walk'!$E34:$CW34,'NOI Walk'!$E$14:$CW$14,NOI!J$4) -> 319458.88 | K18: =+SUMIFS('NOI Walk'!$E34:$CW34,'NOI Walk'!$E$14:$CW$14,NOI!K$4) -> 325906.95
C19: ='NOI Walk'!B35 -> Insurance | G19: =+SUMIFS('NOI Walk'!$E35:$CW35,'NOI Walk'!$E$14:$CW$14,NOI!G$4) -> 71753.669 | H19: =+SUMIFS('NOI Walk'!$E35:$CW35,'NOI Walk'!$E$14:$CW$14,NOI!H$4) -> 73201.97 | I19: =+SUMIFS('NOI Walk'!$E35:$CW35,'NOI Walk'!$E$14:$CW$14,NOI!I$4) -> 74679.505 | J19: =+SUMIFS('NOI Walk'!$E35:$CW35,'NOI Walk'!$E$14:$CW$14,NOI!J$4) -> 76186.863 | K19: =+SUMIFS('NOI Walk'!$E35:$CW35,'NOI Walk'!$E$14:$CW$14,NOI!K$4) -> 77724.645
C20: ='NOI Walk'!B36 -> Water / Sewer | G20: =+SUMIFS('NOI Walk'!$E36:$CW36,'NOI Walk'!$E$14:$CW$14,NOI!G$4) -> 42863.723 | H20: =+SUMIFS('NOI Walk'!$E36:$CW36,'NOI Walk'!$E$14:$CW$14,NOI!H$4) -> 42501.605 | I20: =+SUMIFS('NOI Walk'!$E36:$CW36,'NOI Walk'!$E$14:$CW$14,NOI!I$4) -> 46903.939 | J20: =+SUMIFS('NOI Walk'!$E36:$CW36,'NOI Walk'!$E$14:$CW$14,NOI!J$4) -> 50308.231 | K20: =+SUMIFS('NOI Walk'!$E36:$CW36,'NOI Walk'!$E$14:$CW$14,NOI!K$4) -> 51323.67
C21: ='NOI Walk'!B37 -> Repairs & Maintenance | G21: =+SUMIFS('NOI Walk'!$E37:$CW37,'NOI Walk'!$E$14:$CW$14,NOI!G$4) -> 35666.422 | H21: =+SUMIFS('NOI Walk'!$E37:$CW37,'NOI Walk'!$E$14:$CW$14,NOI!H$4) -> 35365.108 | I21: =+SUMIFS('NOI Walk'!$E37:$CW37,'NOI Walk'!$E$14:$CW$14,NOI!I$4) -> 39028.241 | J21: =+SUMIFS('NOI Walk'!$E37:$CW37,'NOI Walk'!$E$14:$CW$14,NOI!J$4) -> 41860.914 | K21: =+SUMIFS('NOI Walk'!$E37:$CW37,'NOI Walk'!$E$14:$CW$14,NOI!K$4) -> 42705.849
C22: ='NOI Walk'!B38 -> Bank fees | G22: =+SUMIFS('NOI Walk'!$E38:$CW38,'NOI Walk'!$E$14:$CW$14,NOI!G$4) -> 1971.2546 | H22: =+SUMIFS('NOI Walk'!$E38:$CW38,'NOI Walk'!$E$14:$CW$14,NOI!H$4) -> 2011.0431 | I22: =+SUMIFS('NOI Walk'!$E38:$CW38,'NOI Walk'!$E$14:$CW$14,NOI!I$4) -> 2051.6348 | J22: =+SUMIFS('NOI Walk'!$E38:$CW38,'NOI Walk'!$E$14:$CW$14,NOI!J$4) -> 2093.0457 | K22: =+SUMIFS('NOI Walk'!$E38:$CW38,'NOI Walk'!$E$14:$CW$14,NOI!K$4) -> 2135.2925
C23: ='NOI Walk'!B39 -> Trash | G23: =+SUMIFS('NOI Walk'!$E39:$CW39,'NOI Walk'!$E$14:$CW$14,NOI!G$4) -> 2426.1596 | H23: =+SUMIFS('NOI Walk'!$E39:$CW39,'NOI Walk'!$E$14:$CW$14,NOI!H$4) -> 2475.13 | I23: =+SUMIFS('NOI Walk'!$E39:$CW39,'NOI Walk'!$E$14:$CW$14,NOI!I$4) -> 2525.0889 | J23: =+SUMIFS('NOI Walk'!$E39:$CW39,'NOI Walk'!$E$14:$CW$14,NOI!J$4) -> 2576.0562 | K23: =+SUMIFS('NOI Walk'!$E39:$CW39,'NOI Walk'!$E$14:$CW$14,NOI!K$4) -> 2628.0523
C24: ='NOI Walk'!B40 -> Cleaning | G24: =+SUMIFS('NOI Walk'!$E40:$CW40,'NOI Walk'!$E$14:$CW$14,NOI!G$4) -> 11827.528 | H24: =+SUMIFS('NOI Walk'!$E40:$CW40,'NOI Walk'!$E$14:$CW$14,NOI!H$4) -> 12066.259 | I24: =+SUMIFS('NOI Walk'!$E40:$CW40,'NOI Walk'!$E$14:$CW$14,NOI!I$4) -> 12309.809 | J24: =+SUMIFS('NOI Walk'!$E40:$CW40,'NOI Walk'!$E$14:$CW$14,NOI!J$4) -> 12558.274 | K24: =+SUMIFS('NOI Walk'!$E40:$CW40,'NOI Walk'!$E$14:$CW$14,NOI!K$4) -> 12811.755
C25: ='NOI Walk'!B41 -> Security, Internet | G25: =+SUMIFS('NOI Walk'!$E41:$CW41,'NOI Walk'!$E$14:$CW$14,NOI!G$4) -> 2426.1596 | H25: =+SUMIFS('NOI Walk'!$E41:$CW41,'NOI Walk'!$E$14:$CW$14,NOI!H$4) -> 2475.13 | I25: =+SUMIFS('NOI Walk'!$E41:$CW41,'NOI Walk'!$E$14:$CW$14,NOI!I$4) -> 2525.0889 | J25: =+SUMIFS('NOI Walk'!$E41:$CW41,'NOI Walk'!$E$14:$CW$14,NOI!J$4) -> 2576.0562 | K25: =+SUMIFS('NOI Walk'!$E41:$CW41,'NOI Walk'!$E$14:$CW$14,NOI!K$4) -> 2628.0523
C26: ='NOI Walk'!B42 -> Pest Control | G26: =+SUMIFS('NOI Walk'!$E42:$CW42,'NOI Walk'!$E$14:$CW$14,NOI!G$4) -> 5913.7639 | H26: =+SUMIFS('NOI Walk'!$E42:$CW42,'NOI Walk'!$E$14:$CW$14,NOI!H$4) -> 6033.1294 | I26: =+SUMIFS('NOI Walk'!$E42:$CW42,'NOI Walk'!$E$14:$CW$14,NOI!I$4) -> 6154.9043 | J26: =+SUMIFS('NOI Walk'!$E42:$CW42,'NOI Walk'!$E$14:$CW$14,NOI!J$4) -> 6279.137 | K26: =+SUMIFS('NOI Walk'!$E42:$CW42,'NOI Walk'!$E$14:$CW$14,NOI!K$4) -> 6405.8774
C27: ='NOI Walk'!B43 -> Super (Payroll) | G27: =+SUMIFS('NOI Walk'!$E43:$CW43,'NOI Walk'!$E$14:$CW$14,NOI!G$4) -> 39425.093 | H27: =+SUMIFS('NOI Walk'!$E43:$CW43,'NOI Walk'!$E$14:$CW$14,NOI!H$4) -> 40220.863 | I27: =+SUMIFS('NOI Walk'!$E43:$CW43,'NOI Walk'!$E$14:$CW$14,NOI!I$4) -> 41032.695 | J27: =+SUMIFS('NOI Walk'!$E43:$CW43,'NOI Walk'!$E$14:$CW$14,NOI!J$4) -> 41860.914 | K27: =+SUMIFS('NOI Walk'!$E43:$CW43,'NOI Walk'!$E$14:$CW$14,NOI!K$4) -> 42705.849
C28: ='NOI Walk'!B44 -> Heat (Gas) | G28: =+SUMIFS('NOI Walk'!$E44:$CW44,'NOI Walk'!$E$14:$CW$14,NOI!G$4) -> 68118.473 | H28: =+SUMIFS('NOI Walk'!$E44:$CW44,'NOI Walk'!$E$14:$CW$14,NOI!H$4) -> 69493.401 | I28: =+SUMIFS('NOI Walk'!$E44:$CW44,'NOI Walk'!$E$14:$CW$14,NOI!I$4) -> 70896.08 | J28: =+SUMIFS('NOI Walk'!$E44:$CW44,'NOI Walk'!$E$14:$CW$14,NOI!J$4) -> 72327.072 | K28: =+SUMIFS('NOI Walk'!$E44:$CW44,'NOI Walk'!$E$14:$CW$14,NOI!K$4) -> 73786.947
C29: ='NOI Walk'!B45 -> Common Area Electric | G29: =+SUMIFS('NOI Walk'!$E45:$CW45,'NOI Walk'!$E$14:$CW$14,NOI!G$4) -> 3420.885 | H29: =+SUMIFS('NOI Walk'!$E45:$CW45,'NOI Walk'!$E$14:$CW$14,NOI!H$4) -> 3489.9333 | I29: =+SUMIFS('NOI Walk'!$E45:$CW45,'NOI Walk'!$E$14:$CW$14,NOI!I$4) -> 3560.3754 | J29: =+SUMIFS('NOI Walk'!$E45:$CW45,'NOI Walk'!$E$14:$CW$14,NOI!J$4) -> 3632.2393 | K29: =+SUMIFS('NOI Walk'!$E45:$CW45,'NOI Walk'!$E$14:$CW$14,NOI!K$4) -> 3705.5537
... C35: ='NOI Walk'!B51 -> Multifamily NOI | G35: =+SUMIFS('NOI Walk'!$E51:$CW51,'NOI Walk'!$E$14:$CW$14,NOI!G$4) -> 789946.05 | H35: =+SUMIFS('NOI Walk'!$E51:$CW51,'NOI Walk'!$E$14:$CW$14,NOI!H$4) -> 1077243.2 | I35: =+SUMIFS('NOI Walk'!$E51:$CW51,'NOI Walk'!$E$14:$CW$14,NOI!I$4) -> 1408573.6 | J35: =+SUMIFS('NOI Walk'!$E51:$CW51,'NOI Walk'!$E$14:$CW$14,NOI!J$4) -> 1542556.3 | K35: =+SUMIFS('NOI Walk'!$E51:$CW51,'NOI Walk'!$E$14:$CW$14,NOI!K$4) -> 1583041
C36: ='NOI Walk'!B55 -> Reserves | G36: =-SUMIFS('NOI Walk'!$E56:$CW56,'NOI Walk'!$E$14:$CW$14,NOI!G$4) -> -14384.855 | H36: =-SUMIFS('NOI Walk'!$E56:$CW56,'NOI Walk'!$E$14:$CW$14,NOI!H$4) -> -17449.473 | I36: =-SUMIFS('NOI Walk'!$E56:$CW56,'NOI Walk'!$E$14:$CW$14,NOI!I$4) -> -21060.243 | J36: =-SUMIFS('NOI Walk'!$E56:$CW56,'NOI Walk'!$E$14:$CW$14,NOI!J$4) -> -22619.908 | K36: =-SUMIFS('NOI Walk'!$E56:$CW56,'NOI Walk'!$E$14:$CW$14,NOI!K$4) -> -23172.859
C37: Total Property NOI, net of reserves | G37: =SUM(G35:G36) -> 775561.2 | H37: =SUM(H35:H36) -> 1059793.7 | I37: =SUM(I35:I36) -> 1387513.4 | J37: =SUM(J35:J36) -> 1519936.4 | K37: =SUM(K35:K36) -> 1559868.1
C38: Yield on Cost | G38: =+G37/Assumptions!$F$17 -> 0.046538605 | H38: =+H37/Assumptions!$F$17 -> 0.063594366 | I38: =+I37/Assumptions!$F$17 -> 0.08325963 | J38: =+J37/Assumptions!$F$17 -> 0.091205851 | K38: =+K37/Assumptions!$F$17 -> 0.093602009

Sheet Cash Flow and Exit
B2: CASH FLOW
F3: 0 | G3: =+F3+1 -> 1 | H3: =+G3+1 -> 2 | I3: =+H3+1 -> 3 | J3: =+I3+1 -> 4 | K3: =+J3+1 -> 5
F5: Closing | G5: =+G3 -> 1 | H5: =+H3 -> 2 | I5: =+I3 -> 3 | J5: =+J3 -> 4 | K5: =+K3 -> 5
B6: Net Operating Income, After Reserves | F6: =+SUMIFS(Model!$G26:$DW26,Model!$G$3:$DW$3,'Cash Flow and Exit'!F$3) -> 0 | G6: =+SUMIFS(Model!$G26:$DW26,Model!$G$3:$DW$3,'Cash Flow and Exit'!G$3) -> 775561.2 | H6: =+SUMIFS(Model!$G26:$DW26,Model!$G$3:$DW$3,'Cash Flow and Exit'!H$3) -> 1059793.7 | I6: =+SUMIFS(Model!$G26:$DW26,Model!$G$3:$DW$3,'Cash Flow and Exit'!I$3) -> 1387513.4 | J6: =+SUMIFS(Model!$G26:$DW26,Model!$G$3:$DW$3,'Cash Flow and Exit'!J$3) -> 1519936.4 | K6: =+SUMIFS(Model!$G26:$DW26,Model!$G$3:$DW$3,'Cash Flow and Exit'!K$3) -> 1559868.1
B8: Acquisition Loan Draw | F8: =+SUMIFS(Model!$G40:$DW40,Model!$G$3:$DW$3,'Cash Flow and Exit'!F$3) -> 10430000 | G8: =+SUMIFS(Model!$G40:$DW40,Model!$G$3:$DW$3,'Cash Flow and Exit'!G$3) -> -471651.98 | H8: =+SUMIFS(Model!$G40:$DW40,Model!$G$3:$DW$3,'Cash Flow and Exit'!H$3) -> 102967.95 | I8: =+SUMIFS(Model!$G40:$DW40,Model!$G$3:$DW$3,'Cash Flow and Exit'!I$3) -> 0 | J8: =+SUMIFS(Model!$G40:$DW40,Model!$G$3:$DW$3,'Cash Flow and Exit'!J$3) -> 0 | K8: =+SUMIFS(Model!$G40:$DW40,Model!$G$3:$DW$3,'Cash Flow and Exit'!K$3) -> 0
B9: Acqusition Loan Debt Service | F9: =-SUMIFS(Model!$G41:$DW41,Model!$G$3:$DW$3,'Cash Flow and Exit'!F$3)+SUMIFS(Model!$G47:$DW47,Model!$G$3:$DW$3,'Cash Flow and Exit'!F$3) -> 0 | G9: =-SUMIFS(Model!$G41:$DW41,Model!$G$3:$DW$3,'Cash Flow and Exit'!G$3)+SUMIFS(Model!$G47:$DW47,Model!$G$3:$DW$3,'Cash Flow and Exit'!G$3) -> 875136.88 | H9: =-SUMIFS(Model!$G41:$DW41,Model!$G$3:$DW$3,'Cash Flow and Exit'!H$3)+SUMIFS(Model!$G47:$DW47,Model!$G$3:$DW$3,'Cash Flow and Exit'!H$3) -> 875136.88 | I9: =-SUMIFS(Model!$G41:$DW41,Model!$G$3:$DW$3,'Cash Flow and Exit'!I$3)+SUMIFS(Model!$G47:$DW47,Model!$G$3:$DW$3,'Cash Flow and Exit'!I$3) -> 875136.88 | J9: =-SUMIFS(Model!$G41:$DW41,Model!$G$3:$DW$3,'Cash Flow and Exit'!J$3)+SUMIFS(Model!$G47:$DW47,Model!$G$3:$DW$3,'Cash Flow and Exit'!J$3) -> 0 | K9: =-SUMIFS(Model!$G41:$DW41,Model!$G$3:$DW$3,'Cash Flow and Exit'!K$3)+SUMIFS(Model!$G47:$DW47,Model!$G$3:$DW$3,'Cash Flow and Exit'!K$3) -> 0
B10: Acqusition Loan Paydown | F10: =+SUMIFS(Model!$G42:$DW42,Model!$G$3:$DW$3,'Cash Flow and Exit'!F$3) -> 0 | G10: =+SUMIFS(Model!$G42:$DW42,Model!$G$3:$DW$3,'Cash Flow and Exit'!G$3) -> 0 | H10: =+SUMIFS(Model!$G42:$DW42,Model!$G$3:$DW$3,'Cash Flow and Exit'!H$3) -> 0 | I10: =+SUMIFS(Model!$G42:$DW42,Model!$G$3:$DW$3,'Cash Flow and Exit'!I$3) -> -9749902 | J10: =+SUMIFS(Model!$G42:$DW42,Model!$G$3:$DW$3,'Cash Flow and Exit'!J$3) -> 0 | K10: =+SUMIFS(Model!$G42:$DW42,Model!$G$3:$DW$3,'Cash Flow and Exit'!K$3) -> 0
B12: Refi Loan Draw | F12: =+SUMIFS(Model!$G59:$DW59,Model!$G$3:$DW$3,'Cash Flow and Exit'!F$3) -> 0 | G12: =+SUMIFS(Model!$G59:$DW59,Model!$G$3:$DW$3,'Cash Flow and Exit'!G$3) -> 0 | H12: =+SUMIFS(Model!$G59:$DW59,Model!$G$3:$DW$3,'Cash Flow and Exit'!H$3) -> 0 | I12: =+SUMIFS(Model!$G59:$DW59,Model!$G$3:$DW$3,'Cash Flow and Exit'!I$3) -> 17127872 | J12: =+SUMIFS(Model!$G59:$DW59,Model!$G$3:$DW$3,'Cash Flow and Exit'!J$3) -> 0 | K12: =+SUMIFS(Model!$G59:$DW59,Model!$G$3:$DW$3,'Cash Flow and Exit'!K$3) -> 0
B13: Refi Loan Debt Service | F13: =-SUMIFS(Model!$G60:$DW60,Model!$G$3:$DW$3,'Cash Flow and Exit'!F$3)-SUMIFS(Model!$G62:$DW62,Model!$G$3:$DW$3,'Cash Flow and Exit'!F$3) -> 0 | G13: =-SUMIFS(Model!$G60:$DW60,Model!$G$3:$DW$3,'Cash Flow and Exit'!G$3)-SUMIFS(Model!$G62:$DW62,Model!$G$3:$DW$3,'Cash Flow and Exit'!G$3) -> 0 | H13: =-SUMIFS(Model!$G60:$DW60,Model!$G$3:$DW$3,'Cash Flow and Exit'!H$3)-SUMIFS(Model!$G62:$DW62,Model!$G$3:$DW$3,'Cash Flow and Exit'!H$3) -> 0 | I13: =-SUMIFS(Model!$G60:$DW60,Model!$G$3:$DW$3,'Cash Flow and Exit'!I$3)-SUMIFS(Model!$G62:$DW62,Model!$G$3:$DW$3,'Cash Flow and Exit'!I$3) -> 0 | J13: =-SUMIFS(Model!$G60:$DW60,Model!$G$3:$DW$3,'Cash Flow and Exit'!J$3)-SUMIFS(Model!$G62:$DW62,Model!$G$3:$DW$3,'Cash Flow and Exit'!J$3) -> -749522.19 | K13: =-SUMIFS(Model!$G60:$DW60,Model!$G$3:$DW$3,'Cash Flow and Exit'!K$3)-SUMIFS(Model!$G62:$DW62,Model!$G$3:$DW$3,'Cash Flow and Exit'!K$3) -> -723498.27
B14: Refi Loan Paydown | F14: =+SUMIFS(Model!$G61:$DW61,Model!$G$3:$DW$3,'Cash Flow and Exit'!F$3) -> 0 | G14: =+SUMIFS(Model!$G61:$DW61,Model!$G$3:$DW$3,'Cash Flow and Exit'!G$3) -> 0 | H14: =+SUMIFS(Model!$G61:$DW61,Model!$G$3:$DW$3,'Cash Flow and Exit'!H$3) -> 0 | I14: =+SUMIFS(Model!$G61:$DW61,Model!$G$3:$DW$3,'Cash Flow and Exit'!I$3) -> 0 | J14: =+SUMIFS(Model!$G61:$DW61,Model!$G$3:$DW$3,'Cash Flow and Exit'!J$3) -> 0 | K14: =+SUMIFS(Model!$G61:$DW61,Model!$G$3:$DW$3,'Cash Flow and Exit'!K$3) -> -16670621
B16: Exit Proceeds | F16: =+SUMIFS(Model!$G18:$DW18,Model!$G$3:$DW$3,'Cash Flow and Exit'!F$3) -> 0 | G16: =+SUMIFS(Model!$G18:$DW18,Model!$G$3:$DW$3,'Cash Flow and Exit'!G$3) -> 0 | H16: =+SUMIFS(Model!$G18:$DW18,Model!$G$3:$DW$3,'Cash Flow and Exit'!H$3) -> 0 | I16: =+SUMIFS(Model!$G18:$DW18,Model!$G$3:$DW$3,'Cash Flow and Exit'!I$3) -> 0 | J16: =+SUMIFS(Model!$G18:$DW18,Model!$G$3:$DW$3,'Cash Flow and Exit'!J$3) -> 0 | K16: =+SUMIFS(Model!$G18:$DW18,Model!$G$3:$DW$3,'Cash Flow and Exit'!K$3) -> 26327178
B18: Levered Cash Flow | F18: =+SUMIFS(Model!$G65:$DW65,Model!$G$3:$DW$3,'Cash Flow and Exit'!F$3) -> -5340556.3 | G18: =+SUMIFS(Model!$G65:$DW65,Model!$G$3:$DW$3,'Cash Flow and Exit'!G$3) -> -945265.11 | H18: =+SUMIFS(Model!$G65:$DW65,Model!$G$3:$DW$3,'Cash Flow and Exit'!H$3) -> -33380.037 | I18: =+SUMIFS(Model!$G65:$DW65,Model!$G$3:$DW$3,'Cash Flow and Exit'!I$3) -> 7603725.7 | J18: =+SUMIFS(Model!$G65:$DW65,Model!$G$3:$DW$3,'Cash Flow and Exit'!J$3) -> 326174.52 | K18: =+SUMIFS(Model!$G65:$DW65,Model!$G$3:$DW$3,'Cash Flow and Exit'!K$3) -> 10022664
B19: Cash-on-Cash | G19: =-G18/$F$18 -> -0.1769975 | H19: =-H18/$F$18 -> -0.0062502921 | I19: =-I18/$F$18 -> 1.4237704 | J19: =-J18/$F$18 -> 0.061075008 | K19: =-K18/$F$18 -> 1.8767079
B21: Total Equity Invested | E21: =-Model!$G$66 -> 6794409.5 | H21: Unlevered Returns | K21: =+TEXT(Model!F31,"0.0%")&" / "&TEXT(Model!F32,"0.00x") -> 16.5% / 2.02x
B22: Totel Equity Returned | E22: =+E23+E21 -> 17977607 | H22: Levered Gross Returns | K22: =+TEXT(Model!G68,"0.0%")&" / "&TEXT(Model!G69,"0.00x") -> 30.4% / 2.65x
B23: Gross Profit | E23: =+Model!G67 -> 11183197 | H23: Levered Net Returns | K23: =+TEXT(Model!E95,"0.0%")&" / "&TEXT(Model!E96,"0.00x") -> 22.8% / 2.20x
M24: =+Assumptions!B174 -> Multifamily
M25: =+Assumptions!B175 -> Exit (June 30, 2030) | P25: =+Assumptions!E175 -> 60
M26: =+Assumptions!B176 -> NTM NOI in Month 60 | P26: =+Assumptions!E176 -> 1628485.3
M27: =+Assumptions!B177 -> Applied Exit Cap Rate | P27: =+Assumptions!E177 -> 0.06
M28: =+Assumptions!B178 -> Implied Asset Value | P28: =+Assumptions!E178 -> 27141421
M29: =+Assumptions!B179 -> Less: Selling Costs | P29: =+Assumptions!E179 -> 0.03
M30: =+Assumptions!B180 -> Less: Selling Costs | P30: =+Assumptions!E180 -> -814242.63
M31: =+Assumptions!B181 -> Net Reversion Proceeds | P31: =+Assumptions!E181 -> 26327178
M32: =+Assumptions!B182 -> $ / Unit | P32: =+Assumptions!E182 -> 347966.94
Q34: Exit Cap Rate | R34: Implied Valuation | S34: $ / Unit | T34: $ / SF | U34: Gross Returns
Q35: 0.08 | R35: =+$P$26/Q35 -> 20356066 | S35: =+R35/Assumptions!$E$124 -> 260975.2 | T35: =+R35/Assumptions!$G$24 -> 370.11029 | U35: =+TEXT(Assumptions!G191,"0.0%")&" / "&TEXT(Assumptions!G201,"0.0x") -> 36.4% / 3.2x
Q36: =+Q35-0.25% -> 0.0775 | R36: =+$P$26/Q36 -> 21012713 | S36: =+R36/Assumptions!$E$124 -> 269393.76 | T36: =+R36/Assumptions!$G$24 -> 382.04933 | U36: =+TEXT(Assumptions!G192,"0.0%")&" / "&TEXT(Assumptions!G202,"0.0x") -> 34.7% / 3.0x
Q37: =+Q36-0.25% -> 0.075 | R37: =+$P$26/Q37 -> 21713137 | S37: =+R37/Assumptions!$E$124 -> 278373.55 | T37: =+R37/Assumptions!$G$24 -> 394.78431 | U37: =+TEXT(Assumptions!G193,"0.0%")&" / "&TEXT(Assumptions!G203,"0.0x") -> 33.1% / 2.8x
Q38: =+Q37-0.25% -> 0.0725 | R38: =+$P$26/Q38 -> 22461866 | S38: =+R38/Assumptions!$E$124 -> 287972.64 | T38: =+R38/Assumptions!$G$24 -> 408.39756 | U38: =+TEXT(Assumptions!G194,"0.0%")&" / "&TEXT(Assumptions!G204,"0.0x") -> 31.5% / 2.7x
Q39: =+Q38-0.25% -> 0.07 | R39: =+$P$26/Q39 -> 23264075 | S39: =+R39/Assumptions!$E$124 -> 298257.37 | T39: =+R39/Assumptions!$G$24 -> 422.98318 | U39: =+TEXT(Assumptions!G195,"0.0%")&" / "&TEXT(Assumptions!G205,"0.0x") -> 29.9% / 2.5x

Sheet Model
EM1: x
G2: =+Assumptions!F2 -> 45838 | H2: =+EOMONTH(G2,1) -> 45869 | I2: =+EOMONTH(H2,1) -> 45900 | J2: =+EOMONTH(I2,1) -> 45930 | K2: =+EOMONTH(J2,1) -> 45961 | L2: =+EOMONTH(K2,1) -> 45991 | M2: =+EOMONTH(L2,1) -> 46022 | N2: =+EOMONTH(M2,1) -> 46053 | O2: =+EOMONTH(N2,1) -> 46081 | ... EI2: =+EOMONTH(EH2,1) -> 49856 | EM2: x
G3: =ROUNDUP(G4/12,0) -> 0 | H3: =ROUNDUP(H4/12,0) -> 1 | I3: =ROUNDUP(I4/12,0) -> 1 | J3: =ROUNDUP(J4/12,0) -> 1 | K3: =ROUNDUP(K4/12,0) -> 1 | L3: =ROUNDUP(L4/12,0) -> 1 | M3: =ROUNDUP(M4/12,0) -> 1 | N3: =ROUNDUP(N4/12,0) -> 1 | ... EI3: =ROUNDUP(EI4/12,0) -> 11 | EM3: x
G4: 0 | H4: =+G4+1 -> 1 | I4: =+H4+1 -> 2 | J4: =+I4+1 -> 3 | K4: =+J4+1 -> 4 | L4: =+K4+1 -> 5 | M4: =+L4+1 -> 6 | N4: =+M4+1 -> 7 | O4: =+N4+1 -> 8 | ... EI4: =+EH4+1 -> 132 | EM4: x
B5: =SUM(G5:EI5) -> 14900000 | D5: Acquisition of Property | G5: =+IF(G4=Assumptions!$G$23,Assumptions!$G$22,0) -> 14900000 | H5: =+IF(H4=Assumptions!$G$23,Assumptions!$G$22,0) -> 0 | I5: =+IF(I4=Assumptions!$G$23,Assumptions!$G$22,0) -> 0 | J5: =+IF(J4=Assumptions!$G$23,Assumptions!$G$22,0) -> 0 | K5: =+IF(K4=Assumptions!$G$23,Assumptions!$G$22,0) -> 0 | L5: =+IF(L4=Assumptions!$G$23,Assumptions!$G$22,0) -> 0 | M5: =+IF(M4=Assumptions!$G$23,Assumptions!$G$22,0) -> 0 | N5: =+IF(N4=Assumptions!$G$23,Assumptions!$G$22,0) -> 0 | ... EI5: =+IF(EI4=Assumptions!$G$23,Assumptions!$G$22,0) -> 0 | EM5: x
B6: =SUM(G6:EI6) -> 646260.72 | D6: =+'Closing Costs'!B4 -> Closing Costs | G6: {=INDEX('Closing Costs'!$J$18:$EL$18,,MATCH(Model!G$4,'Closing Costs'!$J$4:$EL$4,0))} -> 646260.72 | H6: {=INDEX('Closing Costs'!$J$18:$EL$18,,MATCH(Model!H$4,'Closing Costs'!$J$4:$EL$4,0))} -> 0 | I6: {=INDEX('Closing Costs'!$J$18:$EL$18,,MATCH(Model!I$4,'Closing Costs'!$J$4:$EL$4,0))} -> 0 | J6: {=INDEX('Closing Costs'!$J$18:$EL$18,,MATCH(Model!J$4,'Closing Costs'!$J$4:$EL$4,0))} -> 0 | K6: {=INDEX('Closing Costs'!$J$18:$EL$18,,MATCH(Model!K$4,'Closing Costs'!$J$4:$EL$4,0))} -> 0 | L6: {=INDEX('Closing Costs'!$J$18:$EL$18,,MATCH(Model!L$4,'Closing Costs'!$J$4:$EL$4,0))} -> 0 | M6: {=INDEX('Closing Costs'!$J$18:$EL$18,,MATCH(Model!M$4,'Closing Costs'!$J$4:$EL$4,0))} -> 0 | N6: {=INDEX('Closing Costs'!$J$18:$EL$18,,MATCH(Model!N$4,'Closing Costs'!$J$4:$EL$4,0))} -> 0 | ... EI6: {=INDEX('Closing Costs'!$J$18:$EL$18,,MATCH(Model!EI$4,'Closing Costs'!$J$4:$EL$4,0))} -> 0 | EM6: x
B7: =SUM(G7:EI7) -> 34650 | D7: =+'Legal and Pre-Dev'!B4 -> Legal and Setup Costs | G7: {=INDEX('Legal and Pre-Dev'!$J$12:$EL$12,,MATCH(Model!G$4,'Legal and Pre-Dev'!$J$4:$EL$4,0))} -> 34650 | H7: {=INDEX('Legal and Pre-Dev'!$J$12:$EL$12,,MATCH(Model!H$4,'Legal and Pre-Dev'!$J$4:$EL$4,0))} -> 0 | I7: {=INDEX('Legal and Pre-Dev'!$J$12:$EL$12,,MATCH(Model!I$4,'Legal and Pre-Dev'!$J$4:$EL$4,0))} -> 0 | J7: {=INDEX('Legal and Pre-Dev'!$J$12:$EL$12,,MATCH(Model!J$4,'Legal and Pre-Dev'!$J$4:$EL$4,0))} -> 0 | K7: {=INDEX('Legal and Pre-Dev'!$J$12:$EL$12,,MATCH(Model!K$4,'Legal and Pre-Dev'!$J$4:$EL$4,0))} -> 0 | L7: {=INDEX('Legal and Pre-Dev'!$J$12:$EL$12,,MATCH(Model!L$4,'Legal and Pre-Dev'!$J$4:$EL$4,0))} -> 0 | M7: {=INDEX('Legal and Pre-Dev'!$J$12:$EL$12,,MATCH(Model!M$4,'Legal and Pre-Dev'!$J$4:$EL$4,0))} -> 0 | N7: {=INDEX('Legal and Pre-Dev'!$J$12:$EL$12,,MATCH(Model!N$4,'Legal and Pre-Dev'!$J$4:$EL$4,0))} -> 0 | ... EI7: {=INDEX('Legal and Pre-Dev'!$J$12:$EL$12,,MATCH(Model!EI$4,'Legal and Pre-Dev'!$J$4:$EL$4,0))} -> 0 | EM7: x
B8: =SUM(G8:EI8) -> 386152.2 | D8: =+Reserves!B4 -> Reserves | G8: {=INDEX(Reserves!$J$12:$EL$12,,MATCH(Model!G$4,Reserves!$J$4:$EL$4,0))} -> 119645.55 | H8: {=INDEX(Reserves!$J$12:$EL$12,,MATCH(Model!H$4,Reserves!$J$4:$EL$4,0))} -> 7012.1788 | I8: {=INDEX(Reserves!$J$12:$EL$12,,MATCH(Model!I$4,Reserves!$J$4:$EL$4,0))} -> 7012.1788 | J8: {=INDEX(Reserves!$J$12:$EL$12,,MATCH(Model!J$4,Reserves!$J$4:$EL$4,0))} -> 7012.1788 | K8: {=INDEX(Reserves!$J$12:$EL$12,,MATCH(Model!K$4,Reserves!$J$4:$EL$4,0))} -> 7012.1788 | L8: {=INDEX(Reserves!$J$12:$EL$12,,MATCH(Model!L$4,Reserves!$J$4:$EL$4,0))} -> 7012.1788 | M8: {=INDEX(Reserves!$J$12:$EL$12,,MATCH(Model!M$4,Reserves!$J$4:$EL$4,0))} -> 7012.1788 | N8: {=INDEX(Reserves!$J$12:$EL$12,,MATCH(Model!N$4,Reserves!$J$4:$EL$4,0))} -> 7012.1788 | ... EI8: {=INDEX(Reserves!$J$12:$EL$12,,MATCH(Model!EI$4,Reserves!$J$4:$EL$4,0))} -> 0 | EM8: x
B9: =SUM(G9:EI9) -> 596750 | D9: =+'Hard Costs'!B4 -> Hard Costs | G9: {=INDEX('Hard Costs'!$J$17:$EL$17,,MATCH(Model!G$4,'Hard Costs'!$J$4:$EL$4,0))} -> 70000 | H9: {=INDEX('Hard Costs'!$J$17:$EL$17,,MATCH(Model!H$4,'Hard Costs'!$J$4:$EL$4,0))} -> 0 | I9: {=INDEX('Hard Costs'!$J$17:$EL$17,,MATCH(Model!I$4,'Hard Costs'!$J$4:$EL$4,0))} -> 16217.391 | J9: {=INDEX('Hard Costs'!$J$17:$EL$17,,MATCH(Model!J$4,'Hard Costs'!$J$4:$EL$4,0))} -> 16217.391 | K9: {=INDEX('Hard Costs'!$J$17:$EL$17,,MATCH(Model!K$4,'Hard Costs'!$J$4:$EL$4,0))} -> 16217.391 | L9: {=INDEX('Hard Costs'!$J$17:$EL$17,,MATCH(Model!L$4,'Hard Costs'!$J$4:$EL$4,0))} -> 77467.391 | M9: {=INDEX('Hard Costs'!$J$17:$EL$17,,MATCH(Model!M$4,'Hard Costs'!$J$4:$EL$4,0))} -> 47467.391 | N9: {=INDEX('Hard Costs'!$J$17:$EL$17,,MATCH(Model!N$4,'Hard Costs'!$J$4:$EL$4,0))} -> 16217.391 | ... EI9: {=INDEX('Hard Costs'!$J$17:$EL$17,,MATCH(Model!EI$4,'Hard Costs'!$J$4:$EL$4,0))} -> 0 | EM9: x
B10: =SUM(G10:EI10) -> -16563813 | D10: Total Project Costs | G10: =-SUM(G5:G9) -> -15770556 | H10: =-SUM(H5:H9) -> -7012.1788 | I10: =-SUM(I5:I9) -> -23229.57 | J10: =-SUM(J5:J9) -> -23229.57 | K10: =-SUM(K5:K9) -> -23229.57 | L10: =-SUM(L5:L9) -> -84479.57 | M10: =-SUM(M5:M9) -> -54479.57 | N10: =-SUM(N5:N9) -> -23229.57 | ... EI10: =-SUM(EI5:EI9) -> 0 | EM10: x
EM11: x
D12: Retail Sale | G12: =IF(G$4=Assumptions!$J$175,Assumptions!$J$178,0) -> 0 | H12: =IF(H$4=Assumptions!$J$175,Assumptions!$J$178,0) -> 0 | I12: =IF(I$4=Assumptions!$J$175,Assumptions!$J$178,0) -> 0 | J12: =IF(J$4=Assumptions!$J$175,Assumptions!$J$178,0) -> 0 | K12: =IF(K$4=Assumptions!$J$175,Assumptions!$J$178,0) -> 0 | L12: =IF(L$4=Assumptions!$J$175,Assumptions!$J$178,0) -> 0 | M12: =IF(M$4=Assumptions!$J$175,Assumptions!$J$178,0) -> 0 | N12: =IF(N$4=Assumptions!$J$175,Assumptions!$J$178,0) -> 0 | ... EI12: =IF(EI$4=Assumptions!$J$175,Assumptions!$J$178,0) -> 0 | EM12: x
D13: Less: Selling Costs | G13: =IF(G$4=Assumptions!$J$175,Assumptions!$J$180,0) -> 0 | H13: =IF(H$4=Assumptions!$J$175,Assumptions!$J$180,0) -> 0 | I13: =IF(I$4=Assumptions!$J$175,Assumptions!$J$180,0) -> 0 | J13: =IF(J$4=Assumptions!$J$175,Assumptions!$J$180,0) -> 0 | K13: =IF(K$4=Assumptions!$J$175,Assumptions!$J$180,0) -> 0 | L13: =IF(L$4=Assumptions!$J$175,Assumptions!$J$180,0) -> 0 | M13: =IF(M$4=Assumptions!$J$175,Assumptions!$J$180,0) -> 0 | N13: =IF(N$4=Assumptions!$J$175,Assumptions!$J$180,0) -> 0 | ... EI13: =IF(EI$4=Assumptions!$J$175,Assumptions!$J$180,0) -> 0 | EM13: x
D14: Retail Proceeds, net | G14: =IF(G$4=Assumptions!$J$175,Assumptions!$J$181,0) -> 0 | H14: =IF(H$4=Assumptions!$J$175,Assumptions!$J$181,0) -> 0 | I14: =IF(I$4=Assumptions!$J$175,Assumptions!$J$181,0) -> 0 | J14: =IF(J$4=Assumptions!$J$175,Assumptions!$J$181,0) -> 0 | K14: =IF(K$4=Assumptions!$J$175,Assumptions!$J$181,0) -> 0 | L14: =IF(L$4=Assumptions!$J$175,Assumptions!$J$181,0) -> 0 | M14: =IF(M$4=Assumptions!$J$175,Assumptions!$J$181,0) -> 0 | N14: =IF(N$4=Assumptions!$J$175,Assumptions!$J$181,0) -> 0 | ... EI14: =IF(EI$4=Assumptions!$J$175,Assumptions!$J$181,0) -> 0 | EM14: x
EM15: x
D16: Multifamily Sale | G16: =IF(G4=Assumptions!$E$175,Assumptions!$E$178,0) -> 0 | H16: =IF(H4=Assumptions!$E$175,Assumptions!$E$178,0) -> 0 | I16: =IF(I4=Assumptions!$E$175,Assumptions!$E$178,0) -> 0 | J16: =IF(J4=Assumptions!$E$175,Assumptions!$E$178,0) -> 0 | K16: =IF(K4=Assumptions!$E$175,Assumptions!$E$178,0) -> 0 | L16: =IF(L4=Assumptions!$E$175,Assumptions!$E$178,0) -> 0 | M16: =IF(M4=Assumptions!$E$175,Assumptions!$E$178,0) -> 0 | N16: =IF(N4=Assumptions!$E$175,Assumptions!$E$178,0) -> 0 | ... EI16: =IF(EI4=Assumptions!$E$175,Assumptions!$E$178,0) -> 0 | EM16: x
D17: Less: Selling Costs | G17: =IF(G4=Assumptions!$E$175,Assumptions!$E$180,0) -> 0 | H17: =IF(H4=Assumptions!$E$175,Assumptions!$E$180,0) -> 0 | I17: =IF(I4=Assumptions!$E$175,Assumptions!$E$180,0) -> 0 | J17: =IF(J4=Assumptions!$E$175,Assumptions!$E$180,0) -> 0 | K17: =IF(K4=Assumptions!$E$175,Assumptions!$E$180,0) -> 0 | L17: =IF(L4=Assumptions!$E$175,Assumptions!$E$180,0) -> 0 | M17: =IF(M4=Assumptions!$E$175,Assumptions!$E$180,0) -> 0 | N17: =IF(N4=Assumptions!$E$175,Assumptions!$E$180,0) -> 0 | ... EI17: =IF(EI4=Assumptions!$E$175,Assumptions!$E$180,0) -> 0 | EM17: x
D18: Multifamily Proceeds, net | G18: =IF(G4=Assumptions!$E$175,Assumptions!$E$181,0) -> 0 | H18: =IF(H4=Assumptions!$E$175,Assumptions!$E$181,0) -> 0 | I18: =IF(I4=Assumptions!$E$175,Assumptions!$E$181,0) -> 0 | J18: =IF(J4=Assumptions!$E$175,Assumptions!$E$181,0) -> 0 | K18: =IF(K4=Assumptions!$E$175,Assumptions!$E$181,0) -> 0 | L18: =IF(L4=Assumptions!$E$175,Assumptions!$E$181,0) -> 0 | M18: =IF(M4=Assumptions!$E$175,Assumptions!$E$181,0) -> 0 | N18: =IF(N4=Assumptions!$E$175,Assumptions!$E$181,0) -> 0 | ... EI18: =IF(EI4=Assumptions!$E$175,Assumptions!$E$181,0) -> 0 | EM18: x
EM19: x
D20: Retail Income | G20: {=IFERROR(INDEX('NOI Walk'!$E$58:$EF$58,,MATCH(Model!G$4,'NOI Walk'!$E$15:$EF$15,0)),0)} -> 0 | H20: {=IFERROR(INDEX('NOI Walk'!$E$58:$EF$58,,MATCH(Model!H$4,'NOI Walk'!$E$15:$EF$15,0)),0)} -> 0 | I20: {=IFERROR(INDEX('NOI Walk'!$E$58:$EF$58,,MATCH(Model!I$4,'NOI Walk'!$E$15:$EF$15,0)),0)} -> 0 | J20: {=IFERROR(INDEX('NOI Walk'!$E$58:$EF$58,,MATCH(Model!J$4,'NOI Walk'!$E$15:$EF$15,0)),0)} -> 0 | K20: {=IFERROR(INDEX('NOI Walk'!$E$58:$EF$58,,MATCH(Model!K$4,'NOI Walk'!$E$15:$EF$15,0)),0)} -> 0 | L20: {=IFERROR(INDEX('NOI Walk'!$E$58:$EF$58,,MATCH(Model!L$4,'NOI Walk'!$E$15:$EF$15,0)),0)} -> 0 | M20: {=IFERROR(INDEX('NOI Walk'!$E$58:$EF$58,,MATCH(Model!M$4,'NOI Walk'!$E$15:$EF$15,0)),0)} -> 0 | N20: {=IFERROR(INDEX('NOI Walk'!$E$58:$EF$58,,MATCH(Model!N$4,'NOI Walk'!$E$15:$EF$15,0)),0)} -> 0 | ... EI20: {=IFERROR(INDEX('NOI Walk'!$E$58:$EF$58,,MATCH(Model!EI$4,'NOI Walk'!$E$15:$EF$15,0)),0)} -> 0 | EM20: x
D21: Less: Leasing Cost Reserves | G21: {=-IFERROR(INDEX('NOI Walk'!$E$62:$EF$62,,MATCH(Model!G$4,'NOI Walk'!$E$15:$EF$15,0)),0)} -> 0 | H21: {=-IFERROR(INDEX('NOI Walk'!$E$62:$EF$62,,MATCH(Model!H$4,'NOI Walk'!$E$15:$EF$15,0)),0)} -> 0 | I21: {=-IFERROR(INDEX('NOI Walk'!$E$62:$EF$62,,MATCH(Model!I$4,'NOI Walk'!$E$15:$EF$15,0)),0)} -> 0 | J21: {=-IFERROR(INDEX('NOI Walk'!$E$62:$EF$62,,MATCH(Model!J$4,'NOI Walk'!$E$15:$EF$15,0)),0)} -> 0 | K21: {=-IFERROR(INDEX('NOI Walk'!$E$62:$EF$62,,MATCH(Model!K$4,'NOI Walk'!$E$15:$EF$15,0)),0)} -> 0 | L21: {=-IFERROR(INDEX('NOI Walk'!$E$62:$EF$62,,MATCH(Model!L$4,'NOI Walk'!$E$15:$EF$15,0)),0)} -> 0 | M21: {=-IFERROR(INDEX('NOI Walk'!$E$62:$EF$62,,MATCH(Model!M$4,'NOI Walk'!$E$15:$EF$15,0)),0)} -> 0 | N21: {=-IFERROR(INDEX('NOI Walk'!$E$62:$EF$62,,MATCH(Model!N$4,'NOI Walk'!$E$15:$EF$15,0)),0)} -> 0 | ... EI21: {=-IFERROR(INDEX('NOI Walk'!$E$62:$EF$62,,MATCH(Model!EI$4,'NOI Walk'!$E$15:$EF$15,0)),0)} -> 0 | EM21: x
D22: Retail Cash Flow | G22: =SUM(G20:G21) -> 0 | H22: =SUM(H20:H21) -> 0 | I22: =SUM(I20:I21) -> 0 | J22: =SUM(J20:J21) -> 0 | K22: =SUM(K20:K21) -> 0 | L22: =SUM(L20:L21) -> 0 | M22: =SUM(M20:M21) -> 0 | N22: =SUM(N20:N21) -> 0 | ... EI22: =SUM(EI20:EI21) -> 0 | EM22: x
EM23: x
D24: Multifamily NOI | G24: {=IFERROR(INDEX('NOI Walk'!$E$51:$EF$51,,MATCH(Model!G$4,'NOI Walk'!$E$15:$EF$15,0)),0)} -> 0 | H24: {=IFERROR(INDEX('NOI Walk'!$E$51:$EF$51,,MATCH(Model!H$4,'NOI Walk'!$E$15:$EF$15,0)),0)} -> 70898.852 | I24: {=IFERROR(INDEX('NOI Walk'!$E$51:$EF$51,,MATCH(Model!I$4,'NOI Walk'!$E$15:$EF$15,0)),0)} -> 66624.242 | J24: {=IFERROR(INDEX('NOI Walk'!$E$51:$EF$51,,MATCH(Model!J$4,'NOI Walk'!$E$15:$EF$15,0)),0)} -> 66780.797 | K24: {=IFERROR(INDEX('NOI Walk'!$E$51:$EF$51,,MATCH(Model!K$4,'NOI Walk'!$E$15:$EF$15,0)),0)} -> 64365.759 | L24: {=IFERROR(INDEX('NOI Walk'!$E$51:$EF$51,,MATCH(Model!L$4,'NOI Walk'!$E$15:$EF$15,0)),0)} -> 60566.879 | M24: {=IFERROR(INDEX('NOI Walk'!$E$51:$EF$51,,MATCH(Model!M$4,'NOI Walk'!$E$15:$EF$15,0)),0)} -> 64755.397 | N24: {=IFERROR(INDEX('NOI Walk'!$E$51:$EF$51,,MATCH(Model!N$4,'NOI Walk'!$E$15:$EF$15,0)),0)} -> 60694.106 | ... EI24: {=IFERROR(INDEX('NOI Walk'!$E$51:$EF$51,,MATCH(Model!EI$4,'NOI Walk'!$E$15:$EF$15,0)),0)} -> 155913.05 | EM24: x
D25: Less: CapEx | G25: {=-IFERROR(INDEX('NOI Walk'!$E$56:$EF$56,,MATCH(Model!G$4,'NOI Walk'!$E$15:$EF$15,0)),0)} -> 0 | H25: {=-IFERROR(INDEX('NOI Walk'!$E$56:$EF$56,,MATCH(Model!H$4,'NOI Walk'!$E$15:$EF$15,0)),0)} -> -1253.3007 | I25: {=-IFERROR(INDEX('NOI Walk'!$E$56:$EF$56,,MATCH(Model!I$4,'NOI Walk'!$E$15:$EF$15,0)),0)} -> -1207.2563 | J25: {=-IFERROR(INDEX('NOI Walk'!$E$56:$EF$56,,MATCH(Model!J$4,'NOI Walk'!$E$15:$EF$15,0)),0)} -> -1209.7376 | K25: {=-IFERROR(INDEX('NOI Walk'!$E$56:$EF$56,,MATCH(Model!K$4,'NOI Walk'!$E$15:$EF$15,0)),0)} -> -1183.8049 | L25: {=-IFERROR(INDEX('NOI Walk'!$E$56:$EF$56,,MATCH(Model!L$4,'NOI Walk'!$E$15:$EF$15,0)),0)} -> -1142.6472 | M25: {=-IFERROR(INDEX('NOI Walk'!$E$56:$EF$56,,MATCH(Model!M$4,'NOI Walk'!$E$15:$EF$15,0)),0)} -> -1187.6468 | N25: {=-IFERROR(INDEX('NOI Walk'!$E$56:$EF$56,,MATCH(Model!N$4,'NOI Walk'!$E$15:$EF$15,0)),0)} -> -1143.774 | ... EI25: {=-IFERROR(INDEX('NOI Walk'!$E$56:$EF$56,,MATCH(Model!EI$4,'NOI Walk'!$E$15:$EF$15,0)),0)} -> -2257.0803 | EM25: x
D26: Multifamily Cash Flow | G26: =SUM(G24:G25) -> 0 | H26: =SUM(H24:H25) -> 69645.551 | I26: =SUM(I24:I25) -> 65416.985 | J26: =SUM(J24:J25) -> 65571.059 | K26: =SUM(K24:K25) -> 63181.954 | L26: =SUM(L24:L25) -> 59424.232 | M26: =SUM(M24:M25) -> 63567.75 | N26: =SUM(N24:N25) -> 59550.332 | ... EI26: =SUM(EI24:EI25) -> 153655.97 | EM26: x
EM27: x
D28: Total Unlevered Cash Flow | G28: =IF(G4>Assumptions!$E$175,0,SUM(G26,G22,G10,G18,G14)) -> -15770556 | H28: =IF(H4>Assumptions!$E$175,0,SUM(H26,H22,H10,H18,H14)) -> 62633.373 | I28: =IF(I4>Assumptions!$E$175,0,SUM(I26,I22,I10,I18,I14)) -> 42187.415 | J28: =IF(J4>Assumptions!$E$175,0,SUM(J26,J22,J10,J18,J14)) -> 42341.489 | K28: =IF(K4>Assumptions!$E$175,0,SUM(K26,K22,K10,K18,K14)) -> 39952.384 | L28: =IF(L4>Assumptions!$E$175,0,SUM(L26,L22,L10,L18,L14)) -> -25055.338 | M28: =IF(M4>Assumptions!$E$175,0,SUM(M26,M22,M10,M18,M14)) -> 9088.1802 | N28: =IF(N4>Assumptions!$E$175,0,SUM(N26,N22,N10,N18,N14)) -> 36320.762 | ... EI28: =IF(EI4>Assumptions!$E$175,0,SUM(EI26,EI22,EI10,EI18,EI14)) -> 0 | EM28: x
D29: Equity In | F29: =SUM(G29:EI29) -> -16563813 | G29: =+MIN(G10,0) -> -15770556 | H29: =+MIN(H10,0) -> -7012.1788 | I29: =+MIN(I10,0) -> -23229.57 | J29: =+MIN(J10,0) -> -23229.57 | K29: =+MIN(K10,0) -> -23229.57 | L29: =+MIN(L10,0) -> -84479.57 | M29: =+MIN(M10,0) -> -54479.57 | N29: =+MIN(N10,0) -> -23229.57 | ... EI29: =+MIN(EI10,0) -> 0 | EM29: x
D30: Profit | F30: =+SUM(G28:OFFSET(G28,,Assumptions!$E$175)) -> 16066038 | EM30: x
D31: Unlevered IRR | F31: =XIRR(G28:EI28,$G$2:$EI$2) -> 0.16472445 | EM31: x
D32: Unlevered MOIC | F32: =-(F30-G29)/G29 -> 2.0187363 | EM32: x
EM33: x
D34: Financable Costs | G34: =-G5-G9 -> -14970000 | H34: =-H5-H9 -> 0 | I34: =-I5-I9 -> -16217.391 | J34: =-J5-J9 -> -16217.391 | K34: =-K5-K9 -> -16217.391 | L34: =-L5-L9 -> -77467.391 | M34: =-M5-M9 -> -47467.391 | N34: =-N5-N9 -> -16217.391 | ... S34: =-S5-S9 -> -15217.391 | T34: =+T29 -> -22229.57 | U34: =+U29 -> -22229.57 | V34: =+V29 -> -22229.57 | W34: =+W29 -> -22229.57 | X34: =+X29 -> -22229.57 | Y34: =+Y29 -> -22229.57 | Z34: =+Z29 -> -22229.57 | AA34: =+AA29 -> -22229.57 | ... EI34: =+EI29 -> 0 | EM34: x
D35: Remaining Costs | G35: =+G29-G34 -> -800556.28 | H35: =+H29-H34 -> -7012.1788 | I35: =+I29-I34 -> -7012.1788 | J35: =+J29-J34 -> -7012.1788 | K35: =+K29-K34 -> -7012.1788 | L35: =+L29-L34 -> -7012.1788 | M35: =+M29-M34 -> -7012.1788 | N35: =+N29-N34 -> -7012.1788 | ... EI35: =+EI29-EI34 -> 0 | EM35: x
D36: Cash Available for DSCR Loan Paydown | G36: =+G54 -> 0 | H36: =+H54 -> 0 | I36: =+I54 -> 0 | J36: =+J54 -> 0 | K36: =+K54 -> 0 | L36: =+L54 -> 0 | M36: =+M54 -> 0 | N36: =+N54 -> 0 | ... BN36: =+BN54 -> 0 | BO36: =IF(AND(Assumptions!$G$34="No",Model!BO4=Assumptions!$E$175),BO28,BO54) -> 0 | BP36: =+BP54 -> 0 | BQ36: =+BQ54 -> 0 | BR36: =+BR54 -> 0 | BS36: =+BS54 -> 0 | BT36: =+BT54 -> 0 | BU36: =+BU54 -> 0 | BV36: =+BV54 -> 0 | BW36: =+BW54 -> 0 | ... EI36: =+EI54 -> 0 | EM36: x
EM37: x
B38: =+Assumptions!G31 -> 9870490.4 | D38: Bridge Loan | EM38: x
D39: Beginning Balance | H39: =+G43 -> 10430000 | I39: =+H43 -> 9862749.8 | J39: =+I43 -> 9862701.4 | K39: =+J43 -> 9862652.7 | L39: =+K43 -> 9862603.8 | M39: =+L43 -> 9862554.5 | N39: =+M43 -> 9862504.9 | O39: =+N43 -> 9862455 | ... EI39: =+EH43 -> 0 | EM39: x
D40: Draw | G40: =IF(G4=Assumptions!$G$23,Assumptions!$R$30,MIN(G5*Assumptions!$G$29+G9*Assumptions!$G$30,Assumptions!$G$31-G39)) -> 10430000 | H40: =IF(H4=Assumptions!$G$23,Assumptions!$R$30,MIN(H5*Assumptions!$G$29+H9*Assumptions!$G$30,Assumptions!$G$31-H39)) -> -559509.63 | I40: =IF(I4=Assumptions!$G$23,Assumptions!$R$30,MIN(I5*Assumptions!$G$29+I9*Assumptions!$G$30,Assumptions!$G$31-I39)) -> 7740.5732 | J40: =IF(J4=Assumptions!$G$23,Assumptions!$R$30,MIN(J5*Assumptions!$G$29+J9*Assumptions!$G$30,Assumptions!$G$31-J39)) -> 7788.9518 | K40: =IF(K4=Assumptions!$G$23,Assumptions!$R$30,MIN(K5*Assumptions!$G$29+K9*Assumptions!$G$30,Assumptions!$G$31-K39)) -> 7837.6328 | L40: =IF(L4=Assumptions!$G$23,Assumptions!$R$30,MIN(L5*Assumptions!$G$29+L9*Assumptions!$G$30,Assumptions!$G$31-L39)) -> 7886.618 | M40: =IF(M4=Assumptions!$G$23,Assumptions!$R$30,MIN(M5*Assumptions!$G$29+M9*Assumptions!$G$30,Assumptions!$G$31-M39)) -> 7935.9093 | N40: =IF(N4=Assumptions!$G$23,Assumptions!$R$30,MIN(N5*Assumptions!$G$29+N9*Assumptions!$G$30,Assumptions!$G$31-N39)) -> 7985.5088 | ... EI40: =IF(EI4=Assumptions!$G$23,Assumptions!$R$30,MIN(EI5*Assumptions!$G$29+EI9*Assumptions!$G$30,Assumptions!$G$31-EI39)) -> 0 | EM40: x
...

Sheet Assumptions
A1: 123 Main St. New York, NY
B2: Model Start | F2: 45838 | I2: Ownership Splits | N2: Offer | O2: Price | P2: Terms
I3: Sponsor Equity | K3: 0.1 | L3: =+F5 -> 679440.95 | N3: Ask | O3: 15000000
B4: Sources | F4: $ | G4: % | I4: LP Equity | K4: =1-K3 -> 0.9 | L4: =+F6 -> 6114968.5 | N4: Offer 1
B5: Sponsor Equity | F5: =+F8-SUM(F6:F7) -> 679440.95 | G5: =+F5/$F$8 -> 0.040770779 | I5: Total Equity | K5: =SUM(K3:K4) -> 1 | L5: =SUM(L3:L4) -> 6794409.5
B6: LP Equity | F6: =(F8-SUM(F7:F7))*K4 -> 6114968.5 | G6: =+F6/$F$8 -> 0.36693701
B7: =+B27 -> Acquisition Loan | F7: =+G31 -> 9870490.4 | G7: =+F7/$F$8 -> 0.59229221
B8: Total Sources | F8: =+F17 -> 16664900 | G8: =+F8/$F$8 -> 1 | I8: Levered IRR | K8: =+E184 -> 0.30392409
I9: Levered MOIC | K9: =+E185 -> 2.645941
B10: Uses | F10: $ | G10: %
B11: Acquisition of Property | F11: =+G22 -> 14900000 | G11: =+F11/$F$17 -> 0.89409478
B12: Closing Costs | F12: =+'Closing Costs'!E18 -> 646260.72 | G12: =+F12/$F$17 -> 0.038779754
B13: Legal and Setup Costs | F13: =+'Legal and Pre-Dev'!E12 -> 34650 | G13: =+F13/$F$17 -> 0.0020792204
B14: Reserves | F14: =+Reserves!E12 -> 386152.2 | G14: =+F14/$F$17 -> 0.023171588
B15: Hard Costs | F15: =+'Hard Costs'!E17 -> 596750 | G15: =+F15/$F$17 -> 0.035808796
B16: Interest Reserve | F16: =+L31 -> 101086.93 | G16: =+F16/$F$17 -> 0.0060658586
B17: Total Uses | F17: =SUM(F11:F16) -> 16664900 | G17: =+F17/$F$17 -> 1
B21: General Property Assumptions | I21: Going-in Cap Rate | L21: =('NOI Walk'!E51*12)/G22 -> 0.057099747
B22: Acquisition Price | E22: =+G22/E124 -> 191025.64 | F22: =+G22/O3-1 -> -0.0066666667 | G22: 14900000 | I22: Going-in Cash-on-Cash | L22: {=+INDEX(Model!65:65,,MATCH(1,Model!4:4,0))*12/L5} -> -1.0063644
B23: Closing on Property | G23: 0 | I23: Stabilized Yield on Cost | L23: {=INDEX('NOI Walk'!$E$64:$EF$64,,MATCH(Assumptions!G146+1,'NOI Walk'!$E$15:$EF$15,0))*12/F17} -> 0.089156529 | N23: Max DSCR Loan
B24: Buildable SF | G24: 55000 | I24: Re-leased Cash-on-Cash | L24: {=+INDEX(Model!65:65,,MATCH(G146+3,Model!4:4,0))*12/L5} -> 0.090822619 | N24: ="Stabilized Annualized NOI in Month "&1 -> Stabilized Annualized NOI in Month 1 | R24: {=INDEX('NOI Walk'!$E$64:$EF$64,,MATCH(1,'NOI Walk'!$E$15:$EF$15,0))*12} -> 835746.62
B25: Net Rentable SF | G25: =SUM(F46:F123)+'Retail Assumptions'!F19 -> 49950 | I25: Efficiency | L25: =+G25/G24 -> 0.90818182 | N25: Required DSCR Minimum | R25: 1
N26: Max Loan Size Based on DSCR | R26: =+R24/R25/L27 -> 9870490.4
B27: Acquisition Loan | I27: Loan Constant | L27: =IFERROR(PMT(L29,L30,-1),L29) -> 0.084671236
B28: Origination | G28: 0 | I28: Origination Fee | L28: 0.01 | N28: Acquisition Financing | R28: =+G22 -> 14900000
B29: LTC on Property | G29: =+G31/G22 -> 0.66244902 | I29: Rate | K29: =(L29-'1-month Term SOFR'!Q16)*10000 -> 346.375 | L29: 0.075 | N29: LTV Max | R29: 0.7
B30: LTC on Hard Costs | G30: 1 | I30: Amortization | L30: 30 | N30: Max Loan Size Based on LTC | R30: =+R29*R28 -> 10430000
B31: Max Loan Size | G31: =+R33 -> 9870490.4 | I31: Interest Reserve | L31: =-Model!B49 -> 101086.93 | N31: Plus: Hard Cost Advance | R31: =+G30*F15 -> 596750
B33: Permanent Loan | I33: Max Loan as Lesser of… | N33: Max DSCR Loan | R33: =MIN(R30+R31,R26) -> 9870490.4
B34: Permanent Loan Issued? | G34: Yes | I34: DSCR Min. | K34: 1.25 | L34: =+L38/K34/L39 -> 17202326
B35: Seasoning Period Post Stabilization | G35: =+G36-G146 -> 5 | I35: Debt Yield Min. | K35: 0.0875 | L35: =+L38/K35 -> 17127872 | N35: Lender's Minimum Required Interest Reserve | R35: 0
B36: Refinancing Month | G36: 36 | I36: LTV Max | J36: 0.06 | K36: 0.75 | L36: =+L38/J36*K36 -> 18733610
B37: Fixed Interest Rate | G37: {=G38/10000+INDEX(Model!$G$72:$EI$72,,MATCH(Assumptions!G36,Model!$G$4:$EI$4,0))} -> 0.0570644 | I37: Max Perm. Loan | L37: =MIN(L34:L36) -> 17127872
B38: SOFR Spread at Origination | G38: 200 | I38: ="Annualized NOI in Month "&G36 -> Annualized NOI in Month 36 | L38: {=INDEX('NOI Walk'!$E$64:$EF$64,,MATCH(Assumptions!G36,'NOI Walk'!$E$15:$EF$15,0))*12} -> 1498688.8
B39: Amortization | G39: 30 | I39: Loan Factor | L39: =+PMT(G37/12,G39*12,-1)*12 -> 0.069697032
B40: Origination Cost (Includes Title) | G40: 0.011 | I40: Perm Loan Proceeds net of fees | L40: =+L37*(1-G40) -> 16939466
I41: Proceeds from Cashout | L41: {=+INDEX(Model!G65:EI65,,MATCH(Assumptions!G36,Model!$G$4:$EI$4,0))} -> 7241526.2
G43: Unlevered ROI | H43: =((J124-I124)*12)/'Hard Costs'!E15 -> 1.7118172
B44: Rental Assumptions
A45: Unit Name | B45: Units | C45: Rent Type | D45: Vacate=1 Step-up=2 | E45: Layout | F45: Sq. Ft. | G45: Vacated | H45: Vacated | I45: Current Rent | J45: Pro Forma Rent | K45: Annual PF Rent | M45: Market Rent Assumptions | O45: Pro Forma $ Rent | P45: Pro Forma $ / SF | Q45: Avg. Current Rent | R45: Avg. Current $ / SF | S45: Avg. Pro Forma $ Rent | T45: Avg. Pro Forma $ / SF
...

Sheet Rent Roll Model
B2: Rent Type | D2: Growth Rate | J2: Growth Rates by Rent Type
B3: =+Assumptions!B137 -> Fair Market | D3: =+Assumptions!E137 -> 0.025 | F3: =Assumptions!B146 -> Re-Stabilization Occurs | H3: =Assumptions!G146 -> 31 | J3: 1 | K3: =+J3*(1+$D3)^(1/12) -> 1.0020598 | L3: =+K3*(1+$D3)^(1/12) -> 1.0041239 | M3: =+L3*(1+$D3)^(1/12) -> 1.0061922 | N3: =+M3*(1+$D3)^(1/12) -> 1.0082648 | O3: =+N3*(1+$D3)^(1/12) -> 1.0103417 | P3: =+O3*(1+$D3)^(1/12) -> 1.0124228 | Q3: =+P3*(1+$D3)^(1/12) -> 1.0145083 | R3: =+Q3*(1+$D3)^(1/12) -> 1.016598 | ... EK3: =+EJ3*(1+$D3)^(1/12) -> 1.3093895
B4: =+Assumptions!B138 -> Rent Control | D4: =+Assumptions!E138 -> 0.01 | F4: =Assumptions!B148 -> Vacancy | H4: =Assumptions!G148 -> 0.05 | J4: 1 | K4: =+J4*(1+$D4)^(1/12) -> 1.0008295 | L4: =+K4*(1+$D4)^(1/12) -> 1.0016598 | M4: =+L4*(1+$D4)^(1/12) -> 1.0024907 | N4: =+M4*(1+$D4)^(1/12) -> 1.0033223 | O4: =+N4*(1+$D4)^(1/12) -> 1.0041546 | P4: =+O4*(1+$D4)^(1/12) -> 1.0049876 | Q4: =+P4*(1+$D4)^(1/12) -> 1.0058212 | R4: =+Q4*(1+$D4)^(1/12) -> 1.0066556 | ... EK4: =+EJ4*(1+$D4)^(1/12) -> 1.1147436
B5: =+Assumptions!B139 -> Rent Stabilized | D5: =+Assumptions!E139 -> 0.02 | J5: 1 | K5: =+J5*(1+$D5)^(1/12) -> 1.0016516 | L5: =+K5*(1+$D5)^(1/12) -> 1.0033059 | M5: =+L5*(1+$D5)^(1/12) -> 1.0049629 | N5: =+M5*(1+$D5)^(1/12) -> 1.0066227 | O5: =+N5*(1+$D5)^(1/12) -> 1.0082852 | P5: =+O5*(1+$D5)^(1/12) -> 1.0099505 | Q5: =+P5*(1+$D5)^(1/12) -> 1.0116185 | R5: =+Q5*(1+$D5)^(1/12) -> 1.0132893 | ... EK5: =+EJ5*(1+$D5)^(1/12) -> 1.2413242
J7: {=+INDEX(Model!$G$2:$EI$2,,MATCH(J8,Model!$G$4:$EI$4,0))} -> 45869 | K7: =EOMONTH(J7,1) -> 45900 | L7: =EOMONTH(K7,1) -> 45930 | M7: =EOMONTH(L7,1) -> 45961 | N7: =EOMONTH(M7,1) -> 45991 | O7: =EOMONTH(N7,1) -> 46022 | P7: =EOMONTH(O7,1) -> 46053 | Q7: =EOMONTH(P7,1) -> 46081 | R7: =EOMONTH(Q7,1) -> 46112 | ... EK7: =EOMONTH(EJ7,1) -> 49856
B8: =Assumptions!B45 -> Units | C8: =Assumptions!C45 -> Rent Type | D8: =Assumptions!D45 -> Vacate=1 Step-up=2 | E8: =Assumptions!G45 -> Vacated | F8: Re-Leased | G8: =Assumptions!I45 -> Current Rent | H8: =Assumptions!J45 -> Pro Forma Rent | J8: =+'NOI Walk'!E15 -> 1 | K8: =+'NOI Walk'!F15 -> 2 | L8: =+'NOI Walk'!G15 -> 3 | M8: =+'NOI Walk'!H15 -> 4 | N8: =+'NOI Walk'!I15 -> 5 | O8: =+'NOI Walk'!J15 -> 6 | P8: =+'NOI Walk'!K15 -> 7 | Q8: =+'NOI Walk'!L15 -> 8 | ... EK8: =+'NOI Walk'!EF15 -> 132
B9: =Assumptions!B46 -> 1 | C9: =Assumptions!C46 -> Fair Market | D9: =Assumptions!D46 -> 1 | E9: =Assumptions!G46 -> 2 | F9: =IF(D9=1,E9+SUM(Assumptions!$G$142:$G$143),'Rent Roll Model'!E9) -> 6 | G9: =Assumptions!I46 -> 1522.5 | H9: =Assumptions!J46 -> 2600 | J9: =IFERROR(IF($D9=0,$G9,IF(J$8<$E9,$G9,IF(J$8>=$F9,$H9,0)))*INDEX(J$3:J$5,MATCH($C9,$B$3:$B$5,0)),0) -> 1522.5 | K9: =IFERROR(IF($D9=0,$G9,IF(K$8<$E9,$G9,IF(K$8>=$F9,$H9,0)))*INDEX(K$3:K$5,MATCH($C9,$B$3:$B$5,0)),0) -> 0 | L9: =IFERROR(IF($D9=0,$G9,IF(L$8<$E9,$G9,IF(L$8>=$F9,$H9,0)))*INDEX(L$3:L$5,MATCH($C9,$B$3:$B$5,0)),0) -> 0 | M9: =IFERROR(IF($D9=0,$G9,IF(M$8<$E9,$G9,IF(M$8>=$F9,$H9,0)))*INDEX(M$3:M$5,MATCH($C9,$B$3:$B$5,0)),0) -> 0 | N9: =IFERROR(IF($D9=0,$G9,IF(N$8<$E9,$G9,IF(N$8>=$F9,$H9,0)))*INDEX(N$3:N$5,MATCH($C9,$B$3:$B$5,0)),0) -> 0 | O9: =IFERROR(IF($D9=0,$G9,IF(O$8<$E9,$G9,IF(O$8>=$F9,$H9,0)))*INDEX(O$3:O$5,MATCH($C9,$B$3:$B$5,0)),0) -> 2626.8884 | P9: =IFERROR(IF($D9=0,$G9,IF(P$8<$E9,$G9,IF(P$8>=$F9,$H9,0)))*INDEX(P$3:P$5,MATCH($C9,$B$3:$B$5,0)),0) -> 2632.2994 | Q9: =IFERROR(IF($D9=0,$G9,IF(Q$8<$E9,$G9,IF(Q$8>=$F9,$H9,0)))*INDEX(Q$3:Q$5,MATCH($C9,$B$3:$B$5,0)),0) -> 2637.7215 | ... EK9: =IFERROR(IF($D9=0,$G9,IF(EK$8<$E9,$G9,IF(EK$8>=$F9,$H9,0)))*INDEX(EK$3:EK$5,MATCH($C9,$B$3:$B$5,0)),0) -> 3404.4128
B10: =Assumptions!B47 -> 2 | C10: =Assumptions!C47 -> Rent Control | D10: =Assumptions!D47 -> 1 | E10: =Assumptions!G47 -> 2 | F10: =IF(D10=1,E10+SUM(Assumptions!$G$142:$G$143),'Rent Roll Model'!E10) -> 6 | G10: =Assumptions!I47 -> 1764 | H10: =Assumptions!J47 -> 2600 | J10: =IFERROR(IF($D10=0,$G10,IF(J$8<$E10,$G10,IF(J$8>=$F10,$H10,0)))*INDEX(J$3:J$5,MATCH($C10,$B$3:$B$5,0)),0) -> 1764 | K10: =IFERROR(IF($D10=0,$G10,IF(K$8<$E10,$G10,IF(K$8>=$F10,$H10,0)))*INDEX(K$3:K$5,MATCH($C10,$B$3:$B$5,0)),0) -> 0 | L10: =IFERROR(IF($D10=0,$G10,IF(L$8<$E10,$G10,IF(L$8>=$F10,$H10,0)))*INDEX(L$3:L$5,MATCH($C10,$B$3:$B$5,0)),0) -> 0 | M10: =IFERROR(IF($D10=0,$G10,IF(M$8<$E10,$G10,IF(M$8>=$F10,$H10,0)))*INDEX(M$3:M$5,MATCH($C10,$B$3:$B$5,0)),0) -> 0 | N10: =IFERROR(IF($D10=0,$G10,IF(N$8<$E10,$G10,IF(N$8>=$F10,$H10,0)))*INDEX(N$3:N$5,MATCH($C10,$B$3:$B$5,0)),0) -> 0 | O10: =IFERROR(IF($D10=0,$G10,IF(O$8<$E10,$G10,IF(O$8>=$F10,$H10,0)))*INDEX(O$3:O$5,MATCH($C10,$B$3:$B$5,0)),0) -> 2610.8019 | P10: =IFERROR(IF($D10=0,$G10,IF(P$8<$E10,$G10,IF(P$8>=$F10,$H10,0)))*INDEX(P$3:P$5,MATCH($C10,$B$3:$B$5,0)),0) -> 2612.9677 | Q10: =IFERROR(IF($D10=0,$G10,IF(Q$8<$E10,$G10,IF(Q$8>=$F10,$H10,0)))*INDEX(Q$3:Q$5,MATCH($C10,$B$3:$B$5,0)),0) -> 2615.1352 | ... EK10: =IFERROR(IF($D10=0,$G10,IF(EK$8<$E10,$G10,IF(EK$8>=$F10,$H10,0)))*INDEX(EK$3:EK$5,MATCH($C10,$B$3:$B$5,0)),0) -> 2898.3334
B11: =Assumptions!B48 -> 3 | C11: =Assumptions!C48 -> Rent Stabilized | D11: =Assumptions!D48 -> 1 | E11: =Assumptions!G48 -> 2 | F11: =IF(D11=1,E11+SUM(Assumptions!$G$142:$G$143),'Rent Roll Model'!E11) -> 6 | G11: =Assumptions!I48 -> 1457.71 | H11: =Assumptions!J48 -> 2200 | J11: =IFERROR(IF($D11=0,$G11,IF(J$8<$E11,$G11,IF(J$8>=$F11,$H11,0)))*INDEX(J$3:J$5,MATCH($C11,$B$3:$B$5,0)),0) -> 1457.71 | K11: =IFERROR(IF($D11=0,$G11,IF(K$8<$E11,$G11,IF(K$8>=$F11,$H11,0)))*INDEX(K$3:K$5,MATCH($C11,$B$3:$B$5,0)),0) -> 0 | L11: =IFERROR(IF($D11=0,$G11,IF(L$8<$E11,$G11,IF(L$8>=$F11,$H11,0)))*INDEX(L$3:L$5,MATCH($C11,$B$3:$B$5,0)),0) -> 0 | M11: =IFERROR(IF($D11=0,$G11,IF(M$8<$E11,$G11,IF(M$8>=$F11,$H11,0)))*INDEX(M$3:M$5,MATCH($C11,$B$3:$B$5,0)),0) -> 0 | N11: =IFERROR(IF($D11=0,$G11,IF(N$8<$E11,$G11,IF(N$8>=$F11,$H11,0)))*INDEX(N$3:N$5,MATCH($C11,$B$3:$B$5,0)),0) -> 0 | O11: =IFERROR(IF($D11=0,$G11,IF(O$8<$E11,$G11,IF(O$8>=$F11,$H11,0)))*INDEX(O$3:O$5,MATCH($C11,$B$3:$B$5,0)),0) -> 2218.2275 | P11: =IFERROR(IF($D11=0,$G11,IF(P$8<$E11,$G11,IF(P$8>=$F11,$H11,0)))*INDEX(P$3:P$5,MATCH($C11,$B$3:$B$5,0)),0) -> 2221.8911 | Q11: =IFERROR(IF($D11=0,$G11,IF(Q$8<$E11,$G11,IF(Q$8>=$F11,$H11,0)))*INDEX(Q$3:Q$5,MATCH($C11,$B$3:$B$5,0)),0) -> 2225.5607 | ... EK11: =IFERROR(IF($D11=0,$G11,IF(EK$8<$E11,$G11,IF(EK$8>=$F11,$H11,0)))*INDEX(EK$3:EK$5,MATCH($C11,$B$3:$B$5,0)),0) -> 2730.9132
B12: =Assumptions!B49 -> 4 | C12: =Assumptions!C49 -> Fair Market | D12: =Assumptions!D49 -> 0 | E12: =Assumptions!G49 -> 3 | F12: =IF(D12=1,E12+SUM(Assumptions!$G$142:$G$143),'Rent Roll Model'!E12) -> 3 | G12: =Assumptions!I49 -> 1680 | H12: =Assumptions!J49 -> 1680 | J12: =IFERROR(IF($D12=0,$G12,IF(J$8<$E12,$G12,IF(J$8>=$F12,$H12,0)))*INDEX(J$3:J$5,MATCH($C12,$B$3:$B$5,0)),0) -> 1680 | K12: =IFERROR(IF($D12=0,$G12,IF(K$8<$E12,$G12,IF(K$8>=$F12,$H12,0)))*INDEX(K$3:K$5,MATCH($C12,$B$3:$B$5,0)),0) -> 1683.4605 | L12: =IFERROR(IF($D12=0,$G12,IF(L$8<$E12,$G12,IF(L$8>=$F12,$H12,0)))*INDEX(L$3:L$5,MATCH($C12,$B$3:$B$5,0)),0) -> 1686.9282 | M12: =IFERROR(IF($D12=0,$G12,IF(M$8<$E12,$G12,IF(M$8>=$F12,$H12,0)))*INDEX(M$3:M$5,MATCH($C12,$B$3:$B$5,0)),0) -> 1690.403 | N12: =IFERROR(IF($D12=0,$G12,IF(N$8<$E12,$G12,IF(N$8>=$F12,$H12,0)))*INDEX(N$3:N$5,MATCH($C12,$B$3:$B$5,0)),0) -> 1693.8849 | O12: =IFERROR(IF($D12=0,$G12,IF(O$8<$E12,$G12,IF(O$8>=$F12,$H12,0)))*INDEX(O$3:O$5,MATCH($C12,$B$3:$B$5,0)),0) -> 1697.3741 | P12: =IFERROR(IF($D12=0,$G12,IF(P$8<$E12,$G12,IF(P$8>=$F12,$H12,0)))*INDEX(P$3:P$5,MATCH($C12,$B$3:$B$5,0)),0) -> 1700.8704 | Q12: =IFERROR(IF($D12=0,$G12,IF(Q$8<$E12,$G12,IF(Q$8>=$F12,$H12,0)))*INDEX(Q$3:Q$5,MATCH($C12,$B$3:$B$5,0)),0) -> 1704.3739 | ... EK12: =IFERROR(IF($D12=0,$G12,IF(EK$8<$E12,$G12,IF(EK$8>=$F12,$H12,0)))*INDEX(EK$3:EK$5,MATCH($C12,$B$3:$B$5,0)),0) -> 2199.7744
B13: =Assumptions!B50 -> 5 | C13: =Assumptions!C50 -> Fair Market | D13: =Assumptions!D50 -> 0 | E13: =Assumptions!G50 -> 3 | F13: =IF(D13=1,E13+SUM(Assumptions!$G$142:$G$143),'Rent Roll Model'!E13) -> 3 | G13: =Assumptions!I50 -> 1451.66 | H13: =Assumptions!J50 -> 1451.66 | J13: =IFERROR(IF($D13=0,$G13,IF(J$8<$E13,$G13,IF(J$8>=$F13,$H13,0)))*INDEX(J$3:J$5,MATCH($C13,$B$3:$B$5,0)),0) -> 1451.66 | K13: =IFERROR(IF($D13=0,$G13,IF(K$8<$E13,$G13,IF(K$8>=$F13,$H13,0)))*INDEX(K$3:K$5,MATCH($C13,$B$3:$B$5,0)),0) -> 1454.6502 | L13: =IFERROR(IF($D13=0,$G13,IF(L$8<$E13,$G13,IF(L$8>=$F13,$H13,0)))*INDEX(L$3:L$5,MATCH($C13,$B$3:$B$5,0)),0) -> 1457.6465 | M13: =IFERROR(IF($D13=0,$G13,IF(M$8<$E13,$G13,IF(M$8>=$F13,$H13,0)))*INDEX(M$3:M$5,MATCH($C13,$B$3:$B$5,0)),0) -> 1460.649 | N13: =IFERROR(IF($D13=0,$G13,IF(N$8<$E13,$G13,IF(N$8>=$F13,$H13,0)))*INDEX(N$3:N$5,MATCH($C13,$B$3:$B$5,0)),0) -> 1463.6577 | O13: =IFERROR(IF($D13=0,$G13,IF(O$8<$E13,$G13,IF(O$8>=$F13,$H13,0)))*INDEX(O$3:O$5,MATCH($C13,$B$3:$B$5,0)),0) -> 1466.6726 | P13: =IFERROR(IF($D13=0,$G13,IF(P$8<$E13,$G13,IF(P$8>=$F13,$H13,0)))*INDEX(P$3:P$5,MATCH($C13,$B$3:$B$5,0)),0) -> 1469.6937 | Q13: =IFERROR(IF($D13=0,$G13,IF(Q$8<$E13,$G13,IF(Q$8>=$F13,$H13,0)))*INDEX(Q$3:Q$5,MATCH($C13,$B$3:$B$5,0)),0) -> 1472.7211 | ... EK13: =IFERROR(IF($D13=0,$G13,IF(EK$8<$E13,$G13,IF(EK$8>=$F13,$H13,0)))*INDEX(EK$3:EK$5,MATCH($C13,$B$3:$B$5,0)),0) -> 1900.7884
B14: =Assumptions!B51 -> 6 | C14: =Assumptions!C51 -> Fair Market | D14: =Assumptions!D51 -> 0 | E14: =Assumptions!G51 -> 3 | F14: =IF(D14=1,E14+SUM(Assumptions!$G$142:$G$143),'Rent Roll Model'!E14) -> 3 | G14: =Assumptions!I51 -> 1627.5 | H14: =Assumptions!J51 -> 1627.5 | J14: =IFERROR(IF($D14=0,$G14,IF(J$8<$E14,$G14,IF(J$8>=$F14,$H14,0)))*INDEX(J$3:J$5,MATCH($C14,$B$3:$B$5,0)),0) -> 1627.5 | K14: =IFERROR(IF($D14=0,$G14,IF(K$8<$E14,$G14,IF(K$8>=$F14,$H14,0)))*INDEX(K$3:K$5,MATCH($C14,$B$3:$B$5,0)),0) -> 1630.8524 | L14: =IFERROR(IF($D14=0,$G14,IF(L$8<$E14,$G14,IF(L$8>=$F14,$H14,0)))*INDEX(L$3:L$5,MATCH($C14,$B$3:$B$5,0)),0) -> 1634.2117 | M14: =IFERROR(IF($D14=0,$G14,IF(M$8<$E14,$G14,IF(M$8>=$F14,$H14,0)))*INDEX(M$3:M$5,MATCH($C14,$B$3:$B$5,0)),0) -> 1637.5779 | N14: =IFERROR(IF($D14=0,$G14,IF(N$8<$E14,$G14,IF(N$8>=$F14,$H14,0)))*INDEX(N$3:N$5,MATCH($C14,$B$3:$B$5,0)),0) -> 1640.951 | O14: =IFERROR(IF($D14=0,$G14,IF(O$8<$E14,$G14,IF(O$8>=$F14,$H14,0)))*INDEX(O$3:O$5,MATCH($C14,$B$3:$B$5,0)),0) -> 1644.3311 | P14: =IFERROR(IF($D14=0,$G14,IF(P$8<$E14,$G14,IF(P$8>=$F14,$H14,0)))*INDEX(P$3:P$5,MATCH($C14,$B$3:$B$5,0)),0) -> 1647.7182 | Q14: =IFERROR(IF($D14=0,$G14,IF(Q$8<$E14,$G14,IF(Q$8>=$F14,$H14,0)))*INDEX(Q$3:Q$5,MATCH($C14,$B$3:$B$5,0)),0) -> 1651.1122 | ... EK14: =IFERROR(IF($D14=0,$G14,IF(EK$8<$E14,$G14,IF(EK$8>=$F14,$H14,0)))*INDEX(EK$3:EK$5,MATCH($C14,$B$3:$B$5,0)),0) -> 2131.0315
B15: =Assumptions!B52 -> 7 | C15: =Assumptions!C52 -> Fair Market | D15: =Assumptions!D52 -> 2 | E15: =Assumptions!G52 -> 4 | F15: =IF(D15=1,E15+SUM(Assumptions!$G$142:$G$143),'Rent Roll Model'!E15) -> 4 | G15: =Assumptions!I52 -> 1881 | H15: =Assumptions!J52 -> 2200 | J15: =IFERROR(IF($D15=0,$G15,IF(J$8<$E15,$G15,IF(J$8>=$F15,$H15,0)))*INDEX(J$3:J$5,MATCH($C15,$B$3:$B$5,0)),0) -> 1881 | K15: =IFERROR(IF($D15=0,$G15,IF(K$8<$E15,$G15,IF(K$8>=$F15,$H15,0)))*INDEX(K$3:K$5,MATCH($C15,$B$3:$B$5,0)),0) -> 1884.8746 | L15: =IFERROR(IF($D15=0,$G15,IF(L$8<$E15,$G15,IF(L$8>=$F15,$H15,0)))*INDEX(L$3:L$5,MATCH($C15,$B$3:$B$5,0)),0) -> 1888.7571 | M15: =IFERROR(IF($D15=0,$G15,IF(M$8<$E15,$G15,IF(M$8>=$F15,$H15,0)))*INDEX(M$3:M$5,MATCH($C15,$B$3:$B$5,0)),0) -> 2213.6229 | N15: =IFERROR(IF($D15=0,$G15,IF(N$8<$E15,$G15,IF(N$8>=$F15,$H15,0)))*INDEX(N$3:N$5,MATCH($C15,$B$3:$B$5,0)),0) -> 2218.1826 | O15: =IFERROR(IF($D15=0,$G15,IF(O$8<$E15,$G15,IF(O$8>=$F15,$H15,0)))*INDEX(O$3:O$5,MATCH($C15,$B$3:$B$5,0)),0) -> 2222.7517 | P15: =IFERROR(IF($D15=0,$G15,IF(P$8<$E15,$G15,IF(P$8>=$F15,$H15,0)))*INDEX(P$3:P$5,MATCH($C15,$B$3:$B$5,0)),0) -> 2227.3302 | Q15: =IFERROR(IF($D15=0,$G15,IF(Q$8<$E15,$G15,IF(Q$8>=$F15,$H15,0)))*INDEX(Q$3:Q$5,MATCH($C15,$B$3:$B$5,0)),0) -> 2231.9182 | ... EK15: =IFERROR(IF($D15=0,$G15,IF(EK$8<$E15,$G15,IF(EK$8>=$F15,$H15,0)))*INDEX(EK$3:EK$5,MATCH($C15,$B$3:$B$5,0)),0) -> 2880.657
