Workbook
Name Financial_Summary: #REF!
Name IQ_CH: 110000
Name IQ_CQ: 5000
Name IQ_CY: 10000
Name IQ_DAILY: 500000
Name IQ_FH: 100000
Name IQ_FQ: 500
Name IQ_FY: 1000
Name IQ_LTM: 2000
Name IQ_MONTH: 15000
Name IQ_NTM: 6000
Name IQ_WEEK: 50000
Name IQ_YTD: 3000

Sheet Diligence and Notes
B3: Notes
B4: 1 | C4: Sold for $11.5mm in 2018.
B5: 2
B6: 3
B8: Diligence Questions
B9: 1 | C9: Please confirm there are no elevators.
B10: 2 | C10: What are Super's responsibilities?
B11: 3 | C11: How many units have been renovated since acquiring?
B12: 4 | C12: Please share gross Sq Ft of property and approx Sq Ft of the units.
B13: 5 | C13: What is the age of the mechanicals?
B14: 6 | C14: What is approx. age of the roof?
B15: 7 | C15: Please share rent comps.

Sheet Underwriting Assumptions
C3: Underwriting Assumptions
J4: Monthly | K4: Annual | M4: Notes
C5: Pro Forma Rent Roll | J5: =+K5/12 -> 189600 | K5: =+Assumptions!J124 -> 2275200 | M5: Current Rent Roll
C6: ="Plus: "&Assumptions!B131 -> Plus: Total Amenity Income | J6: =+K6/12 -> 10648 | K6: =+Assumptions!J131 -> 127776 | M6: Laundry Currently
C7: Less: Vacancy, Turnover, Bad Debt | G7: =-Assumptions!G146-Assumptions!G145-Assumptions!P144 -> -0.066666667 | J7: =+$G$7*J5 -> -12640 | K7: =+$G$7*K5 -> -151680 | M7: 5% Vacancy + 20% Turnover
C8: Effective Gross Income | J8: =SUM(J5:J7) -> 187608 | K8: =SUM(K5:K7) -> 2251296
C10: =Assumptions!B148 -> Operating Expenses | H10: =Assumptions!G148 -> Factor | I10: =Assumptions!H148 -> Statistic | J10: =Assumptions!I148 -> Monthly | K10: =Assumptions!J148 -> Annual
C11: =Assumptions!B149 -> Property Taxes | H11: =Assumptions!G149 -> 3815.7179 | I11: =Assumptions!H149 -> 78 | J11: =Assumptions!I149 -> 24802.167 | K11: =Assumptions!J149 -> 297626 | M11: Broker
C12: =Assumptions!B150 -> Insurance | H12: =Assumptions!G150 -> 1200 | I12: =Assumptions!H150 -> 78 | J12: =Assumptions!I150 -> 7800 | K12: =Assumptions!J150 -> 93600 | M12: Estimate
C13: =Assumptions!B151 -> Water / Sewer | H13: =Assumptions!G151 -> 600.89744 | I13: =Assumptions!H151 -> 78 | J13: =Assumptions!I151 -> 3905.8333 | K13: =Assumptions!J151 -> 46870 | M13: Estimate
C14: =Assumptions!B152 -> Repairs & Maintenance | H14: =Assumptions!G152 -> 500 | I14: =Assumptions!H152 -> 78 | J14: =Assumptions!I152 -> 3250 | K14: =Assumptions!J152 -> 39000 | M14: Estimate
C15: =Assumptions!B153 -> Elevator Contract | J15: =Assumptions!I153 -> 0 | K15: =Assumptions!J153 -> 0 | M15: Estimate
C16: =Assumptions!B154 -> Trash | J16: =Assumptions!I154 -> 200 | K16: =Assumptions!J154 -> 2400 | M16: Estimate (NEW)
C17: =Assumptions!B156 -> Security, Internet | J17: =Assumptions!I156 -> 200 | K17: =Assumptions!J156 -> 2400 | M17: Estimate (NEW)
C18: =Assumptions!B157 -> Pest Control | H18: =Assumptions!G157 -> 50 | I18: =Assumptions!H157 -> 78 | J18: =Assumptions!I157 -> 325 | K18: =Assumptions!J157 -> 3900 | M18: Estimate (NEW)
C19: =Assumptions!B160 -> Common Area Electric | H19: =Assumptions!G160 -> 0.67009901 | I19: =Assumptions!H160 -> 5050 | J19: =Assumptions!I160 -> 282 | K19: =Assumptions!J160 -> 3384 | M19: Broker
C20: =Assumptions!B161 -> Landscaping / Snow Removal | J20: =Assumptions!I161 -> 500 | K20: =Assumptions!J161 -> 6000 | M20: Estimate
C21: =Assumptions!B162 -> Property Management | H21: =Assumptions!G162 -> 0.03 | I21: =Assumptions!H162 -> 2242777.6 | J21: =Assumptions!I162 -> 5606.944 | K21: =Assumptions!J162 -> 67283.328 | M21: PCG PM Fee
C22: =Assumptions!B163 -> Accounting / Legal | J22: =Assumptions!I163 -> 208.33333 | K22: =Assumptions!J163 -> 2500 | M22: Estimate (NEW)
C23: =+Assumptions!B164 -> Total Operating Expenses | J23: =Assumptions!I164 -> 56920.611 | K23: =Assumptions!J164 -> 683047.33
C24: Operating Expense Margin | K24: =+K23/K8 -> 0.30340183
C26: Net Operating Income | J26: =+J8-J23 -> 130687.39 | K26: =+K8-K23 -> 1568248.7
C27: ="Implied Stabilized Cap Rate at "&TEXT(Assumptions!G23,"$#,##0")&" Purchase" -> Implied Stabilized Cap Rate at $15,000,000 Purchase | K27: =+K26/Assumptions!G23 -> 0.10454991

Sheet NOI
C3: Net Operating Income Summary
G4: 1 | H4: =+G4+1 -> 2 | I4: =+H4+1 -> 3 | J4: =+I4+1 -> 4 | K4: =+J4+1 -> 5
C5: ='NOI Walk'!B22 -> Gross Potential Rent | G5: =+SUMIFS('NOI Walk'!$H22:$CZ22,'NOI Walk'!$H$15:$CZ$15,NOI!G$4) -> 2306246.6 | H5: =+SUMIFS('NOI Walk'!$H22:$CZ22,'NOI Walk'!$H$15:$CZ$15,NOI!H$4) -> 2364568 | I5: =+SUMIFS('NOI Walk'!$H22:$CZ22,'NOI Walk'!$H$15:$CZ$15,NOI!I$4) -> 2424364.3 | J5: =+SUMIFS('NOI Walk'!$H22:$CZ22,'NOI Walk'!$H$15:$CZ$15,NOI!J$4) -> 2485672.7 | K5: =+SUMIFS('NOI Walk'!$H22:$CZ22,'NOI Walk'!$H$15:$CZ$15,NOI!K$4) -> 2548531.5
C6: Loss-to-Lease | G6: =+SUMIFS('NOI Walk'!$H23:$CZ23,'NOI Walk'!$H$15:$CZ$15,NOI!G$4) -> -721212.05 | H6: =+SUMIFS('NOI Walk'!$H23:$CZ23,'NOI Walk'!$H$15:$CZ$15,NOI!H$4) -> -369245.48 | I6: =+SUMIFS('NOI Walk'!$H23:$CZ23,'NOI Walk'!$H$15:$CZ$15,NOI!I$4) -> -40882.296 | J6: =+SUMIFS('NOI Walk'!$H23:$CZ23,'NOI Walk'!$H$15:$CZ$15,NOI!J$4) -> 0 | K6: =+SUMIFS('NOI Walk'!$H23:$CZ23,'NOI Walk'!$H$15:$CZ$15,NOI!K$4) -> 0
C7: Vacancy | G7: =+SUMIFS('NOI Walk'!$H26:$CZ26,'NOI Walk'!$H$15:$CZ$15,NOI!G$4) -> -143581.91 | H7: =+SUMIFS('NOI Walk'!$H26:$CZ26,'NOI Walk'!$H$15:$CZ$15,NOI!H$4) -> -176301.68 | I7: =+SUMIFS('NOI Walk'!$H26:$CZ26,'NOI Walk'!$H$15:$CZ$15,NOI!I$4) -> -130841.15 | J7: =+SUMIFS('NOI Walk'!$H26:$CZ26,'NOI Walk'!$H$15:$CZ$15,NOI!J$4) -> -124283.64 | K7: =+SUMIFS('NOI Walk'!$H26:$CZ26,'NOI Walk'!$H$15:$CZ$15,NOI!K$4) -> -127426.58
C8: ='NOI Walk'!B27 -> Vacancy | G8: =-G7/G5 -> 0.06225783 | H8: =-H7/H5 -> 0.074559786 | I8: =-I7/I5 -> 0.05396926 | J8: =-J7/J5 -> 0.05 | K8: =-K7/K5 -> 0.05
C9: Rental Income | G9: =+SUMIFS('NOI Walk'!$H24:$CZ24,'NOI Walk'!$H$15:$CZ$15,NOI!G$4)+SUMIFS('NOI Walk'!$H25:$CZ25,'NOI Walk'!$H$15:$CZ$15,NOI!G$4) -> 1441452.6 | H9: =+SUMIFS('NOI Walk'!$H24:$CZ24,'NOI Walk'!$H$15:$CZ$15,NOI!H$4)+SUMIFS('NOI Walk'!$H25:$CZ25,'NOI Walk'!$H$15:$CZ$15,NOI!H$4) -> 1819020.8 | I9: =+SUMIFS('NOI Walk'!$H24:$CZ24,'NOI Walk'!$H$15:$CZ$15,NOI!I$4)+SUMIFS('NOI Walk'!$H25:$CZ25,'NOI Walk'!$H$15:$CZ$15,NOI!I$4) -> 2323719.1 | J9: =+SUMIFS('NOI Walk'!$H24:$CZ24,'NOI Walk'!$H$15:$CZ$15,NOI!J$4)+SUMIFS('NOI Walk'!$H25:$CZ25,'NOI Walk'!$H$15:$CZ$15,NOI!J$4) -> 2485672.7 | K9: =+SUMIFS('NOI Walk'!$H24:$CZ24,'NOI Walk'!$H$15:$CZ$15,NOI!K$4)+SUMIFS('NOI Walk'!$H25:$CZ25,'NOI Walk'!$H$15:$CZ$15,NOI!K$4) -> 2548531.5
C10: ='NOI Walk'!B28 -> Parking Income | G10: =+SUMIFS('NOI Walk'!$H28:$CZ28,'NOI Walk'!$H$15:$CZ$15,NOI!G$4) -> 57717.568 | H10: =+SUMIFS('NOI Walk'!$H28:$CZ28,'NOI Walk'!$H$15:$CZ$15,NOI!H$4) -> 57639.59 | I10: =+SUMIFS('NOI Walk'!$H28:$CZ28,'NOI Walk'!$H$15:$CZ$15,NOI!I$4) -> 63932.971 | J10: =+SUMIFS('NOI Walk'!$H28:$CZ28,'NOI Walk'!$H$15:$CZ$15,NOI!J$4) -> 67814.68 | K10: =+SUMIFS('NOI Walk'!$H28:$CZ28,'NOI Walk'!$H$15:$CZ$15,NOI!K$4) -> 69183.476
C11: ='NOI Walk'!B29 -> Storage Income | G11: =+SUMIFS('NOI Walk'!$H29:$CZ29,'NOI Walk'!$H$15:$CZ$15,NOI!G$4) -> 11031.665 | H11: =+SUMIFS('NOI Walk'!$H29:$CZ29,'NOI Walk'!$H$15:$CZ$15,NOI!H$4) -> 19213.197 | I11: =+SUMIFS('NOI Walk'!$H29:$CZ29,'NOI Walk'!$H$15:$CZ$15,NOI!I$4) -> 21310.99 | J11: =+SUMIFS('NOI Walk'!$H29:$CZ29,'NOI Walk'!$H$15:$CZ$15,NOI!J$4) -> 22604.893 | K11: =+SUMIFS('NOI Walk'!$H29:$CZ29,'NOI Walk'!$H$15:$CZ$15,NOI!K$4) -> 23061.159
C12: ='NOI Walk'!B30 -> Laundry Income | G12: =+SUMIFS('NOI Walk'!$H30:$CZ30,'NOI Walk'!$H$15:$CZ$15,NOI!G$4) -> 9405.826 | H12: =+SUMIFS('NOI Walk'!$H30:$CZ30,'NOI Walk'!$H$15:$CZ$15,NOI!H$4) -> 9393.1184 | I12: =+SUMIFS('NOI Walk'!$H30:$CZ30,'NOI Walk'!$H$15:$CZ$15,NOI!I$4) -> 10418.706 | J12: =+SUMIFS('NOI Walk'!$H30:$CZ30,'NOI Walk'!$H$15:$CZ$15,NOI!J$4) -> 11051.281 | K12: =+SUMIFS('NOI Walk'!$H30:$CZ30,'NOI Walk'!$H$15:$CZ$15,NOI!K$4) -> 11274.344
C13: ='NOI Walk'!B31 -> Parking Income | G13: =+SUMIFS('NOI Walk'!$H31:$CZ31,'NOI Walk'!$H$15:$CZ$15,NOI!G$4) -> 76956.758 | H13: =+SUMIFS('NOI Walk'!$H31:$CZ31,'NOI Walk'!$H$15:$CZ$15,NOI!H$4) -> 76852.787 | I13: =+SUMIFS('NOI Walk'!$H31:$CZ31,'NOI Walk'!$H$15:$CZ$15,NOI!I$4) -> 85243.961 | J13: =+SUMIFS('NOI Walk'!$H31:$CZ31,'NOI Walk'!$H$15:$CZ$15,NOI!J$4) -> 90419.573 | K13: =+SUMIFS('NOI Walk'!$H31:$CZ31,'NOI Walk'!$H$15:$CZ$15,NOI!K$4) -> 92244.634
C14: ='NOI Walk'!B32 -> Turnover Costs | G14: =+SUMIFS('NOI Walk'!$H32:$CZ32,'NOI Walk'!$H$15:$CZ$15,NOI!G$4) -> 0 | H14: =+SUMIFS('NOI Walk'!$H32:$CZ32,'NOI Walk'!$H$15:$CZ$15,NOI!H$4) -> 0 | I14: =+SUMIFS('NOI Walk'!$H32:$CZ32,'NOI Walk'!$H$15:$CZ$15,NOI!I$4) -> 0 | J14: =+SUMIFS('NOI Walk'!$H32:$CZ32,'NOI Walk'!$H$15:$CZ$15,NOI!J$4) -> 0 | K14: =+SUMIFS('NOI Walk'!$H32:$CZ32,'NOI Walk'!$H$15:$CZ$15,NOI!K$4) -> 0
C15: ='NOI Walk'!B34 -> Effective Gross Income | G15: =+SUMIFS('NOI Walk'!$H34:$CZ34,'NOI Walk'!$H$15:$CZ$15,NOI!G$4) -> 1596564.4 | H15: =+SUMIFS('NOI Walk'!$H34:$CZ34,'NOI Walk'!$H$15:$CZ$15,NOI!H$4) -> 1982119.5 | I15: =+SUMIFS('NOI Walk'!$H34:$CZ34,'NOI Walk'!$H$15:$CZ$15,NOI!I$4) -> 2504625.7 | J15: =+SUMIFS('NOI Walk'!$H34:$CZ34,'NOI Walk'!$H$15:$CZ$15,NOI!J$4) -> 2677563.1 | K15: =+SUMIFS('NOI Walk'!$H34:$CZ34,'NOI Walk'!$H$15:$CZ$15,NOI!K$4) -> 2744295.1
C17: ='NOI Walk'!B36 -> Operating Expenses
C18: ='NOI Walk'!B37 -> Property Taxes | G18: =+SUMIFS('NOI Walk'!$H37:$CZ37,'NOI Walk'!$H$15:$CZ$15,NOI!G$4) -> 300870.07 | H18: =+SUMIFS('NOI Walk'!$H37:$CZ37,'NOI Walk'!$H$15:$CZ$15,NOI!H$4) -> 306942.94 | I18: =+SUMIFS('NOI Walk'!$H37:$CZ37,'NOI Walk'!$H$15:$CZ$15,NOI!I$4) -> 313138.38 | J18: =+SUMIFS('NOI Walk'!$H37:$CZ37,'NOI Walk'!$H$15:$CZ$15,NOI!J$4) -> 319458.88 | K18: =+SUMIFS('NOI Walk'!$H37:$CZ37,'NOI Walk'!$H$15:$CZ$15,NOI!K$4) -> 325906.95
C19: ='NOI Walk'!B38 -> Insurance | G19: =+SUMIFS('NOI Walk'!$H38:$CZ38,'NOI Walk'!$H$15:$CZ$15,NOI!G$4) -> 94620.223 | H19: =+SUMIFS('NOI Walk'!$H38:$CZ38,'NOI Walk'!$H$15:$CZ$15,NOI!H$4) -> 96530.071 | I19: =+SUMIFS('NOI Walk'!$H38:$CZ38,'NOI Walk'!$H$15:$CZ$15,NOI!I$4) -> 98478.468 | J19: =+SUMIFS('NOI Walk'!$H38:$CZ38,'NOI Walk'!$H$15:$CZ$15,NOI!J$4) -> 100466.19 | K19: =+SUMIFS('NOI Walk'!$H38:$CZ38,'NOI Walk'!$H$15:$CZ$15,NOI!K$4) -> 102494.04
C20: ='NOI Walk'!B39 -> Water / Sewer | G20: =+SUMIFS('NOI Walk'!$H39:$CZ39,'NOI Walk'!$H$15:$CZ$15,NOI!G$4) -> 42817.702 | H20: =+SUMIFS('NOI Walk'!$H39:$CZ39,'NOI Walk'!$H$15:$CZ$15,NOI!H$4) -> 42759.854 | I20: =+SUMIFS('NOI Walk'!$H39:$CZ39,'NOI Walk'!$H$15:$CZ$15,NOI!I$4) -> 47428.59 | J20: =+SUMIFS('NOI Walk'!$H39:$CZ39,'NOI Walk'!$H$15:$CZ$15,NOI!J$4) -> 50308.231 | K20: =+SUMIFS('NOI Walk'!$H39:$CZ39,'NOI Walk'!$H$15:$CZ$15,NOI!K$4) -> 51323.67
C21: ='NOI Walk'!B40 -> Repairs & Maintenance | G21: =+SUMIFS('NOI Walk'!$H40:$CZ40,'NOI Walk'!$H$15:$CZ$15,NOI!G$4) -> 35628.129 | H21: =+SUMIFS('NOI Walk'!$H40:$CZ40,'NOI Walk'!$H$15:$CZ$15,NOI!H$4) -> 35579.994 | I21: =+SUMIFS('NOI Walk'!$H40:$CZ40,'NOI Walk'!$H$15:$CZ$15,NOI!I$4) -> 39464.797 | J21: =+SUMIFS('NOI Walk'!$H40:$CZ40,'NOI Walk'!$H$15:$CZ$15,NOI!J$4) -> 41860.914 | K21: =+SUMIFS('NOI Walk'!$H40:$CZ40,'NOI Walk'!$H$15:$CZ$15,NOI!K$4) -> 42705.849
C22: ='NOI Walk'!B41 -> Elevator Contract | G22: =+SUMIFS('NOI Walk'!$H41:$CZ41,'NOI Walk'!$H$15:$CZ$15,NOI!G$4) -> 0 | H22: =+SUMIFS('NOI Walk'!$H41:$CZ41,'NOI Walk'!$H$15:$CZ$15,NOI!H$4) -> 0 | I22: =+SUMIFS('NOI Walk'!$H41:$CZ41,'NOI Walk'!$H$15:$CZ$15,NOI!I$4) -> 0 | J22: =+SUMIFS('NOI Walk'!$H41:$CZ41,'NOI Walk'!$H$15:$CZ$15,NOI!J$4) -> 0 | K22: =+SUMIFS('NOI Walk'!$H41:$CZ41,'NOI Walk'!$H$15:$CZ$15,NOI!K$4) -> 0
C23: ='NOI Walk'!B42 -> Trash | G23: =+SUMIFS('NOI Walk'!$H42:$CZ42,'NOI Walk'!$H$15:$CZ$15,NOI!G$4) -> 2426.1596 | H23: =+SUMIFS('NOI Walk'!$H42:$CZ42,'NOI Walk'!$H$15:$CZ$15,NOI!H$4) -> 2475.13 | I23: =+SUMIFS('NOI Walk'!$H42:$CZ42,'NOI Walk'!$H$15:$CZ$15,NOI!I$4) -> 2525.0889 | J23: =+SUMIFS('NOI Walk'!$H42:$CZ42,'NOI Walk'!$H$15:$CZ$15,NOI!J$4) -> 2576.0562 | K23: =+SUMIFS('NOI Walk'!$H42:$CZ42,'NOI Walk'!$H$15:$CZ$15,NOI!K$4) -> 2628.0523
C24: ='NOI Walk'!B43 -> Cleaning | G24: =+SUMIFS('NOI Walk'!$H43:$CZ43,'NOI Walk'!$H$15:$CZ$15,NOI!G$4) -> 11827.528 | H24: =+SUMIFS('NOI Walk'!$H43:$CZ43,'NOI Walk'!$H$15:$CZ$15,NOI!H$4) -> 12066.259 | I24: =+SUMIFS('NOI Walk'!$H43:$CZ43,'NOI Walk'!$H$15:$CZ$15,NOI!I$4) -> 12309.809 | J24: =+SUMIFS('NOI Walk'!$H43:$CZ43,'NOI Walk'!$H$15:$CZ$15,NOI!J$4) -> 12558.274 | K24: =+SUMIFS('NOI Walk'!$H43:$CZ43,'NOI Walk'!$H$15:$CZ$15,NOI!K$4) -> 12811.755
C25: ='NOI Walk'!B44 -> Security, Internet | G25: =+SUMIFS('NOI Walk'!$H44:$CZ44,'NOI Walk'!$H$15:$CZ$15,NOI!G$4) -> 2426.1596 | H25: =+SUMIFS('NOI Walk'!$H44:$CZ44,'NOI Walk'!$H$15:$CZ$15,NOI!H$4) -> 2475.13 | I25: =+SUMIFS('NOI Walk'!$H44:$CZ44,'NOI Walk'!$H$15:$CZ$15,NOI!I$4) -> 2525.0889 | J25: =+SUMIFS('NOI Walk'!$H44:$CZ44,'NOI Walk'!$H$15:$CZ$15,NOI!J$4) -> 2576.0562 | K25: =+SUMIFS('NOI Walk'!$H44:$CZ44,'NOI Walk'!$H$15:$CZ$15,NOI!K$4) -> 2628.0523
C26: ='NOI Walk'!B45 -> Pest Control | G26: =+SUMIFS('NOI Walk'!$H45:$CZ45,'NOI Walk'!$H$15:$CZ$15,NOI!G$4) -> 3942.5093 | H26: =+SUMIFS('NOI Walk'!$H45:$CZ45,'NOI Walk'!$H$15:$CZ$15,NOI!H$4) -> 4022.0863 | I26: =+SUMIFS('NOI Walk'!$H45:$CZ45,'NOI Walk'!$H$15:$CZ$15,NOI!I$4) -> 4103.2695 | J26: =+SUMIFS('NOI Walk'!$H45:$CZ45,'NOI Walk'!$H$15:$CZ$15,NOI!J$4) -> 4186.0914 | K26: =+SUMIFS('NOI Walk'!$H45:$CZ45,'NOI Walk'!$H$15:$CZ$15,NOI!K$4) -> 4270.5849
C27: ='NOI Walk'!B46 -> Super (Payroll) | G27: =+SUMIFS('NOI Walk'!$H46:$CZ46,'NOI Walk'!$H$15:$CZ$15,NOI!G$4) -> 39425.093 | H27: =+SUMIFS('NOI Walk'!$H46:$CZ46,'NOI Walk'!$H$15:$CZ$15,NOI!H$4) -> 40220.863 | I27: =+SUMIFS('NOI Walk'!$H46:$CZ46,'NOI Walk'!$H$15:$CZ$15,NOI!I$4) -> 41032.695 | J27: =+SUMIFS('NOI Walk'!$H46:$CZ46,'NOI Walk'!$H$15:$CZ$15,NOI!J$4) -> 41860.914 | K27: =+SUMIFS('NOI Walk'!$H46:$CZ46,'NOI Walk'!$H$15:$CZ$15,NOI!K$4) -> 42705.849
C28: ='NOI Walk'!B47 -> Heat (Gas) | G28: =+SUMIFS('NOI Walk'!$H47:$CZ47,'NOI Walk'!$H$15:$CZ$15,NOI!G$4) -> 68118.473 | H28: =+SUMIFS('NOI Walk'!$H47:$CZ47,'NOI Walk'!$H$15:$CZ$15,NOI!H$4) -> 69493.401 | I28: =+SUMIFS('NOI Walk'!$H47:$CZ47,'NOI Walk'!$H$15:$CZ$15,NOI!I$4) -> 70896.08 | J28: =+SUMIFS('NOI Walk'!$H47:$CZ47,'NOI Walk'!$H$15:$CZ$15,NOI!J$4) -> 72327.072 | K28: =+SUMIFS('NOI Walk'!$H47:$CZ47,'NOI Walk'!$H$15:$CZ$15,NOI!K$4) -> 73786.947
C29: ='NOI Walk'!B48 -> Common Area Electric | G29: =+SUMIFS('NOI Walk'!$H48:$CZ48,'NOI Walk'!$H$15:$CZ$15,NOI!G$4) -> 3420.885 | H29: =+SUMIFS('NOI Walk'!$H48:$CZ48,'NOI Walk'!$H$15:$CZ$15,NOI!H$4) -> 3489.9333 | I29: =+SUMIFS('NOI Walk'!$H48:$CZ48,'NOI Walk'!$H$15:$CZ$15,NOI!I$4) -> 3560.3754 | J29: =+SUMIFS('NOI Walk'!$H48:$CZ48,'NOI Walk'!$H$15:$CZ$15,NOI!J$4) -> 3632.2393 | K29: =+SUMIFS('NOI Walk'!$H48:$CZ48,'NOI Walk'!$H$15:$CZ$15,NOI!K$4) -> 3705.5537
... C35: ='NOI Walk'!B54 -> Multifamily NOI | G35: =+SUMIFS('NOI Walk'!$H54:$CZ54,'NOI Walk'!$H$15:$CZ$15,NOI!G$4) -> 934551.93 | H35: =+SUMIFS('NOI Walk'!$H54:$CZ54,'NOI Walk'!$H$15:$CZ$15,NOI!H$4) -> 1297834.2 | I35: =+SUMIFS('NOI Walk'!$H54:$CZ54,'NOI Walk'!$H$15:$CZ$15,NOI!I$4) -> 1785081.3 | J35: =+SUMIFS('NOI Walk'!$H54:$CZ54,'NOI Walk'!$H$15:$CZ$15,NOI!J$4) -> 1936301.8 | K35: =+SUMIFS('NOI Walk'!$H54:$CZ54,'NOI Walk'!$H$15:$CZ$15,NOI!K$4) -> 1987691.3
C36: ='NOI Walk'!B58 -> Reserves | G36: =-SUMIFS('NOI Walk'!$H59:$CZ59,'NOI Walk'!$H$15:$CZ$15,NOI!G$4) -> -15965.644 | H36: =-SUMIFS('NOI Walk'!$H59:$CZ59,'NOI Walk'!$H$15:$CZ$15,NOI!H$4) -> -19821.195 | I36: =-SUMIFS('NOI Walk'!$H59:$CZ59,'NOI Walk'!$H$15:$CZ$15,NOI!I$4) -> -25046.257 | J36: =-SUMIFS('NOI Walk'!$H59:$CZ59,'NOI Walk'!$H$15:$CZ$15,NOI!J$4) -> -26775.631 | K36: =-SUMIFS('NOI Walk'!$H59:$CZ59,'NOI Walk'!$H$15:$CZ$15,NOI!K$4) -> -27442.951
C37: Total Property NOI, net of reserves | G37: =SUM(G35:G36) -> 918586.29 | H37: =SUM(H35:H36) -> 1278013 | I37: =SUM(I35:I36) -> 1760035 | J37: =SUM(J35:J36) -> 1909526.2 | K37: =SUM(K35:K36) -> 1960248.4
C38: Yield on Cost | G38: =+G37/Assumptions!$F$17 -> 0.046535877 | H38: =+H37/Assumptions!$F$17 -> 0.064744551 | I38: =+I37/Assumptions!$F$17 -> 0.089163942 | J38: =+J37/Assumptions!$F$17 -> 0.096737211 | K38: =+K37/Assumptions!$F$17 -> 0.099306814

Sheet Cash Flow and Exit
B2: CASH FLOW
F3: 0 | G3: =+F3+1 -> 1 | H3: =+G3+1 -> 2 | I3: =+H3+1 -> 3 | J3: =+I3+1 -> 4 | K3: =+J3+1 -> 5
F5: Closing | G5: =+G3 -> 1 | H5: =+H3 -> 2 | I5: =+I3 -> 3 | J5: =+J3 -> 4 | K5: =+K3 -> 5
B6: Net Operating Income, After Reserves | F6: =+SUMIFS(Model!$G30:$DW30,Model!$G$3:$DW$3,'Cash Flow and Exit'!F$3) -> 0 | G6: =+SUMIFS(Model!$G30:$DW30,Model!$G$3:$DW$3,'Cash Flow and Exit'!G$3) -> 918586.29 | H6: =+SUMIFS(Model!$G30:$DW30,Model!$G$3:$DW$3,'Cash Flow and Exit'!H$3) -> 1278013 | I6: =+SUMIFS(Model!$G30:$DW30,Model!$G$3:$DW$3,'Cash Flow and Exit'!I$3) -> 1760035 | J6: =+SUMIFS(Model!$G30:$DW30,Model!$G$3:$DW$3,'Cash Flow and Exit'!J$3) -> 1909526.2 | K6: =+SUMIFS(Model!$G30:$DW30,Model!$G$3:$DW$3,'Cash Flow and Exit'!K$3) -> 1960248.4
B8: Acquisition Loan Draw | F8: =+SUMIFS(Model!$G44:$DW44,Model!$G$3:$DW$3,'Cash Flow and Exit'!F$3) -> 11250000 | G8: =+SUMIFS(Model!$G44:$DW44,Model!$G$3:$DW$3,'Cash Flow and Exit'!G$3) -> 0 | H8: =+SUMIFS(Model!$G44:$DW44,Model!$G$3:$DW$3,'Cash Flow and Exit'!H$3) -> 0 | I8: =+SUMIFS(Model!$G44:$DW44,Model!$G$3:$DW$3,'Cash Flow and Exit'!I$3) -> 0 | J8: =+SUMIFS(Model!$G44:$DW44,Model!$G$3:$DW$3,'Cash Flow and Exit'!J$3) -> 0 | K8: =+SUMIFS(Model!$G44:$DW44,Model!$G$3:$DW$3,'Cash Flow and Exit'!K$3) -> 0
B9: Acqusition Loan Debt Service | F9: =-SUMIFS(Model!$G45:$DW45,Model!$G$3:$DW$3,'Cash Flow and Exit'!F$3)+SUMIFS(Model!$G51:$DW51,Model!$G$3:$DW$3,'Cash Flow and Exit'!F$3) -> 0 | G9: =-SUMIFS(Model!$G45:$DW45,Model!$G$3:$DW$3,'Cash Flow and Exit'!G$3)+SUMIFS(Model!$G51:$DW51,Model!$G$3:$DW$3,'Cash Flow and Exit'!G$3) -> 1184721.6 | H9: =-SUMIFS(Model!$G45:$DW45,Model!$G$3:$DW$3,'Cash Flow and Exit'!H$3)+SUMIFS(Model!$G51:$DW51,Model!$G$3:$DW$3,'Cash Flow and Exit'!H$3) -> 1184721.6 | I9: =-SUMIFS(Model!$G45:$DW45,Model!$G$3:$DW$3,'Cash Flow and Exit'!I$3)+SUMIFS(Model!$G51:$DW51,Model!$G$3:$DW$3,'Cash Flow and Exit'!I$3) -> 888541.21 | J9: =-SUMIFS(Model!$G45:$DW45,Model!$G$3:$DW$3,'Cash Flow and Exit'!J$3)+SUMIFS(Model!$G51:$DW51,Model!$G$3:$DW$3,'Cash Flow and Exit'!J$3) -> 0 | K9: =-SUMIFS(Model!$G45:$DW45,Model!$G$3:$DW$3,'Cash Flow and Exit'!K$3)+SUMIFS(Model!$G51:$DW51,Model!$G$3:$DW$3,'Cash Flow and Exit'!K$3) -> 0
B10: Acqusition Loan Paydown | F10: =+SUMIFS(Model!$G46:$DW46,Model!$G$3:$DW$3,'Cash Flow and Exit'!F$3) -> 0 | G10: =+SUMIFS(Model!$G46:$DW46,Model!$G$3:$DW$3,'Cash Flow and Exit'!G$3) -> 0 | H10: =+SUMIFS(Model!$G46:$DW46,Model!$G$3:$DW$3,'Cash Flow and Exit'!H$3) -> 0 | I10: =+SUMIFS(Model!$G46:$DW46,Model!$G$3:$DW$3,'Cash Flow and Exit'!I$3) -> -11061858 | J10: =+SUMIFS(Model!$G46:$DW46,Model!$G$3:$DW$3,'Cash Flow and Exit'!J$3) -> 0 | K10: =+SUMIFS(Model!$G46:$DW46,Model!$G$3:$DW$3,'Cash Flow and Exit'!K$3) -> 0
B12: Refi Loan Draw | F12: =+SUMIFS(Model!$G63:$DW63,Model!$G$3:$DW$3,'Cash Flow and Exit'!F$3) -> 0 | G12: =+SUMIFS(Model!$G63:$DW63,Model!$G$3:$DW$3,'Cash Flow and Exit'!G$3) -> 0 | H12: =+SUMIFS(Model!$G63:$DW63,Model!$G$3:$DW$3,'Cash Flow and Exit'!H$3) -> 0 | I12: =+SUMIFS(Model!$G63:$DW63,Model!$G$3:$DW$3,'Cash Flow and Exit'!I$3) -> 20678404 | J12: =+SUMIFS(Model!$G63:$DW63,Model!$G$3:$DW$3,'Cash Flow and Exit'!J$3) -> 0 | K12: =+SUMIFS(Model!$G63:$DW63,Model!$G$3:$DW$3,'Cash Flow and Exit'!K$3) -> 0
B13: Refi Loan Debt Service | F13: =-SUMIFS(Model!$G64:$DW64,Model!$G$3:$DW$3,'Cash Flow and Exit'!F$3)-SUMIFS(Model!$G66:$DW66,Model!$G$3:$DW$3,'Cash Flow and Exit'!F$3) -> 0 | G13: =-SUMIFS(Model!$G64:$DW64,Model!$G$3:$DW$3,'Cash Flow and Exit'!G$3)-SUMIFS(Model!$G66:$DW66,Model!$G$3:$DW$3,'Cash Flow and Exit'!G$3) -> 0 | H13: =-SUMIFS(Model!$G64:$DW64,Model!$G$3:$DW$3,'Cash Flow and Exit'!H$3)-SUMIFS(Model!$G66:$DW66,Model!$G$3:$DW$3,'Cash Flow and Exit'!H$3) -> 0 | I13: =-SUMIFS(Model!$G64:$DW64,Model!$G$3:$DW$3,'Cash Flow and Exit'!I$3)-SUMIFS(Model!$G66:$DW66,Model!$G$3:$DW$3,'Cash Flow and Exit'!I$3) -> -259453.77 | J13: =-SUMIFS(Model!$G64:$DW64,Model!$G$3:$DW$3,'Cash Flow and Exit'!J$3)-SUMIFS(Model!$G66:$DW66,Model!$G$3:$DW$3,'Cash Flow and Exit'!J$3) -> -1018899.8 | K13: =-SUMIFS(Model!$G64:$DW64,Model!$G$3:$DW$3,'Cash Flow and Exit'!K$3)-SUMIFS(Model!$G66:$DW66,Model!$G$3:$DW$3,'Cash Flow and Exit'!K$3) -> -987196.75
B14: Refi Loan Paydown | F14: =+SUMIFS(Model!$G65:$DW65,Model!$G$3:$DW$3,'Cash Flow and Exit'!F$3) -> 0 | G14: =+SUMIFS(Model!$G65:$DW65,Model!$G$3:$DW$3,'Cash Flow and Exit'!G$3) -> 0 | H14: =+SUMIFS(Model!$G65:$DW65,Model!$G$3:$DW$3,'Cash Flow and Exit'!H$3) -> 0 | I14: =+SUMIFS(Model!$G65:$DW65,Model!$G$3:$DW$3,'Cash Flow and Exit'!I$3) -> 0 | J14: =+SUMIFS(Model!$G65:$DW65,Model!$G$3:$DW$3,'Cash Flow and Exit'!J$3) -> 0 | K14: =+SUMIFS(Model!$G65:$DW65,Model!$G$3:$DW$3,'Cash Flow and Exit'!K$3) -> -20104331
B16: Exit Proceeds | F16: =+SUMIFS(Model!$G22:$DW22,Model!$G$3:$DW$3,'Cash Flow and Exit'!F$3) -> 0 | G16: =+SUMIFS(Model!$G22:$DW22,Model!$G$3:$DW$3,'Cash Flow and Exit'!G$3) -> 0 | H16: =+SUMIFS(Model!$G22:$DW22,Model!$G$3:$DW$3,'Cash Flow and Exit'!H$3) -> 0 | I16: =+SUMIFS(Model!$G22:$DW22,Model!$G$3:$DW$3,'Cash Flow and Exit'!I$3) -> 0 | J16: =+SUMIFS(Model!$G22:$DW22,Model!$G$3:$DW$3,'Cash Flow and Exit'!J$3) -> 0 | K16: =+SUMIFS(Model!$G22:$DW22,Model!$G$3:$DW$3,'Cash Flow and Exit'!K$3) -> 32998037
B18: Levered Cash Flow | F18: =+SUMIFS(Model!$G69:$DW69,Model!$G$3:$DW$3,'Cash Flow and Exit'!F$3) -> -5651390.8 | G18: =+SUMIFS(Model!$G69:$DW69,Model!$G$3:$DW$3,'Cash Flow and Exit'!G$3) -> -1429309.2 | H18: =+SUMIFS(Model!$G69:$DW69,Model!$G$3:$DW$3,'Cash Flow and Exit'!H$3) -> -1300834.7 | I18: =+SUMIFS(Model!$G69:$DW69,Model!$G$3:$DW$3,'Cash Flow and Exit'!I$3) -> 9901956.3 | J18: =+SUMIFS(Model!$G69:$DW69,Model!$G$3:$DW$3,'Cash Flow and Exit'!J$3) -> 392327.05 | K18: =+SUMIFS(Model!$G69:$DW69,Model!$G$3:$DW$3,'Cash Flow and Exit'!K$3) -> 13336756
B19: Cash-on-Cash | G19: =-G18/$F$18 -> -0.25291283 | H19: =-H18/$F$18 -> -0.23017957 | I19: =-I18/$F$18 -> 1.7521273 | J19: =-J18/$F$18 -> 0.069421328 | K19: =-K18/$F$18 -> 2.3599068
B21: Total Equity Invested | E21: =-Model!$G$70 -> 8489313.8 | H21: Unlevered Returns | K21: =+TEXT(Model!F35,"0.0%")&" / "&TEXT(Model!F36,"0.00x") -> 18.5% / 2.26x
B22: Totel Equity Returned | E22: =+E23+E21 -> 23631039 | H22: Levered Gross Returns | K22: =+TEXT(Model!G72,"0.0%")&" / "&TEXT(Model!G73,"0.00x") -> 33.9% / 2.78x
B23: Gross Profit | E23: =+Model!G71 -> 15141725 | H23: Levered Net Returns | K23: =+TEXT(Model!E99,"0.0%")&" / "&TEXT(Model!E100,"0.00x") -> 23.7% / 2.21x
M24: =+Assumptions!B173 -> Multifamily
M25: =+Assumptions!B174 -> Exit (June 30, 2030) | P25: =+Assumptions!E174 -> 60
M26: =+Assumptions!B175 -> NTM NOI in Month 60 | P26: =+Assumptions!E175 -> 2043222.1
M27: =+Assumptions!B176 -> Applied Exit Cap Rate | P27: =+Assumptions!E176 -> 0.06
M28: =+Assumptions!B177 -> Implied Asset Value | P28: =+Assumptions!E177 -> 34053702
M29: =+Assumptions!B178 -> Less: Selling Costs | P29: =+Assumptions!E178 -> 0.031
M30: =+Assumptions!B179 -> Less: Selling Costs | P30: =+Assumptions!E179 -> -1055664.8
M31: =+Assumptions!B180 -> Net Reversion Proceeds | P31: =+Assumptions!E180 -> 32998037
M32: =+Assumptions!B181 -> $ / Unit | P32: =+Assumptions!E181 -> 436585.92
Q34: Exit Cap Rate | R34: Implied Valuation | S34: $ / Unit | T34: $ / SF | U34: Gross Returns
Q35: 0.08 | R35: =+$P$26/Q35 -> 25540276 | S35: =+R35/Assumptions!$D$124 -> 327439.44 | T35: =+R35/Assumptions!$G$25 -> 464.36866 | U35: =+TEXT(Assumptions!G190,"0.0%")&" / "&TEXT(Assumptions!G200,"0.0x") -> 61.6% / 3.6x
Q36: =+Q35-0.25% -> 0.0775 | R36: =+$P$26/Q36 -> 26364156 | S36: =+R36/Assumptions!$D$124 -> 338002 | T36: =+R36/Assumptions!$G$25 -> 479.3483 | U36: =+TEXT(Assumptions!G191,"0.0%")&" / "&TEXT(Assumptions!G201,"0.0x") -> 62.6% / 3.7x
Q37: =+Q36-0.25% -> 0.075 | R37: =+$P$26/Q37 -> 27242961 | S37: =+R37/Assumptions!$D$124 -> 349268.74 | T37: =+R37/Assumptions!$G$25 -> 495.32657 | U37: =+TEXT(Assumptions!G192,"0.0%")&" / "&TEXT(Assumptions!G202,"0.0x") -> 63.6% / 3.9x
Q38: =+Q37-0.25% -> 0.0725 | R38: =+$P$26/Q38 -> 28182374 | S38: =+R38/Assumptions!$D$124 -> 361312.49 | T38: =+R38/Assumptions!$G$25 -> 512.4068 | U38: =+TEXT(Assumptions!G193,"0.0%")&" / "&TEXT(Assumptions!G203,"0.0x") -> 64.6% / 4.0x
Q39: =+Q38-0.25% -> 0.07 | R39: =+$P$26/Q39 -> 29188887 | S39: =+R39/Assumptions!$D$124 -> 374216.5 | T39: =+R39/Assumptions!$G$25 -> 530.70704 | U39: =+TEXT(Assumptions!G194,"0.0%")&" / "&TEXT(Assumptions!G204,"0.0x") -> 65.7% / 4.2x

Sheet Model
EM1: x
G2: =+Assumptions!F2 -> 45838 | H2: =+EOMONTH(G2,1) -> 45869 | I2: =+EOMONTH(H2,1) -> 45900 | J2: =+EOMONTH(I2,1) -> 45930 | K2: =+EOMONTH(J2,1) -> 45961 | L2: =+EOMONTH(K2,1) -> 45991 | M2: =+EOMONTH(L2,1) -> 46022 | N2: =+EOMONTH(M2,1) -> 46053 | O2: =+EOMONTH(N2,1) -> 46081 | ... EI2: =+EOMONTH(EH2,1) -> 49856 | EM2: x
G3: =ROUNDUP(G4/12,0) -> 0 | H3: =ROUNDUP(H4/12,0) -> 1 | I3: =ROUNDUP(I4/12,0) -> 1 | J3: =ROUNDUP(J4/12,0) -> 1 | K3: =ROUNDUP(K4/12,0) -> 1 | L3: =ROUNDUP(L4/12,0) -> 1 | M3: =ROUNDUP(M4/12,0) -> 1 | N3: =ROUNDUP(N4/12,0) -> 1 | ... EI3: =ROUNDUP(EI4/12,0) -> 11 | EM3: x
G4: 0 | H4: =+G4+1 -> 1 | I4: =+H4+1 -> 2 | J4: =+I4+1 -> 3 | K4: =+J4+1 -> 4 | L4: =+K4+1 -> 5 | M4: =+L4+1 -> 6 | N4: =+M4+1 -> 7 | O4: =+N4+1 -> 8 | ... EI4: =+EH4+1 -> 132 | EM4: x
B5: =SUM(G5:EI5) -> 15000000 | D5: Acquisition of Property | G5: =+IF(G4=Assumptions!$G$24,Assumptions!$G$23,0) -> 15000000 | H5: =+IF(H4=Assumptions!$G$24,Assumptions!$G$23,0) -> 0 | I5: =+IF(I4=Assumptions!$G$24,Assumptions!$G$23,0) -> 0 | J5: =+IF(J4=Assumptions!$G$24,Assumptions!$G$23,0) -> 0 | K5: =+IF(K4=Assumptions!$G$24,Assumptions!$G$23,0) -> 0 | L5: =+IF(L4=Assumptions!$G$24,Assumptions!$G$23,0) -> 0 | M5: =+IF(M4=Assumptions!$G$24,Assumptions!$G$23,0) -> 0 | N5: =+IF(N4=Assumptions!$G$24,Assumptions!$G$23,0) -> 0 | ... EI5: =+IF(EI4=Assumptions!$G$24,Assumptions!$G$23,0) -> 0 | EM5: x
B6: =SUM(G6:EI6) -> 1062339.1 | D6: =+'Closing Costs'!B4 -> Closing Costs | G6: {=INDEX('Closing Costs'!$J$19:$EL$19,,MATCH(Model!G$4,'Closing Costs'!$J$4:$EL$4,0))} -> 1062339.1 | H6: {=INDEX('Closing Costs'!$J$19:$EL$19,,MATCH(Model!H$4,'Closing Costs'!$J$4:$EL$4,0))} -> 0 | I6: {=INDEX('Closing Costs'!$J$19:$EL$19,,MATCH(Model!I$4,'Closing Costs'!$J$4:$EL$4,0))} -> 0 | J6: {=INDEX('Closing Costs'!$J$19:$EL$19,,MATCH(Model!J$4,'Closing Costs'!$J$4:$EL$4,0))} -> 0 | K6: {=INDEX('Closing Costs'!$J$19:$EL$19,,MATCH(Model!K$4,'Closing Costs'!$J$4:$EL$4,0))} -> 0 | L6: {=INDEX('Closing Costs'!$J$19:$EL$19,,MATCH(Model!L$4,'Closing Costs'!$J$4:$EL$4,0))} -> 0 | M6: {=INDEX('Closing Costs'!$J$19:$EL$19,,MATCH(Model!M$4,'Closing Costs'!$J$4:$EL$4,0))} -> 0 | N6: {=INDEX('Closing Costs'!$J$19:$EL$19,,MATCH(Model!N$4,'Closing Costs'!$J$4:$EL$4,0))} -> 0 | ... EI6: {=INDEX('Closing Costs'!$J$19:$EL$19,,MATCH(Model!EI$4,'Closing Costs'!$J$4:$EL$4,0))} -> 0 | EM6: x
B7: =SUM(G7:EI7) -> 29925 | D7: =+'Legal and Pre-Dev'!B4 -> Legal and Pre-Development Costs | G7: {=INDEX('Legal and Pre-Dev'!$J$12:$EL$12,,MATCH(Model!G$4,'Legal and Pre-Dev'!$J$4:$EL$4,0))} -> 29925 | H7: {=INDEX('Legal and Pre-Dev'!$J$12:$EL$12,,MATCH(Model!H$4,'Legal and Pre-Dev'!$J$4:$EL$4,0))} -> 0 | I7: {=INDEX('Legal and Pre-Dev'!$J$12:$EL$12,,MATCH(Model!I$4,'Legal and Pre-Dev'!$J$4:$EL$4,0))} -> 0 | J7: {=INDEX('Legal and Pre-Dev'!$J$12:$EL$12,,MATCH(Model!J$4,'Legal and Pre-Dev'!$J$4:$EL$4,0))} -> 0 | K7: {=INDEX('Legal and Pre-Dev'!$J$12:$EL$12,,MATCH(Model!K$4,'Legal and Pre-Dev'!$J$4:$EL$4,0))} -> 0 | L7: {=INDEX('Legal and Pre-Dev'!$J$12:$EL$12,,MATCH(Model!L$4,'Legal and Pre-Dev'!$J$4:$EL$4,0))} -> 0 | M7: {=INDEX('Legal and Pre-Dev'!$J$12:$EL$12,,MATCH(Model!M$4,'Legal and Pre-Dev'!$J$4:$EL$4,0))} -> 0 | N7: {=INDEX('Legal and Pre-Dev'!$J$12:$EL$12,,MATCH(Model!N$4,'Legal and Pre-Dev'!$J$4:$EL$4,0))} -> 0 | ... EI7: {=INDEX('Legal and Pre-Dev'!$J$12:$EL$12,,MATCH(Model!EI$4,'Legal and Pre-Dev'!$J$4:$EL$4,0))} -> 0 | EM7: x
B8: =SUM(G8:EI8) -> 789126.76 | D8: =+Reserves!B4 -> Reserves | G8: {=INDEX(Reserves!$J$12:$EL$12,,MATCH(Model!G$4,Reserves!$J$4:$EL$4,0))} -> 789126.76 | H8: {=INDEX(Reserves!$J$12:$EL$12,,MATCH(Model!H$4,Reserves!$J$4:$EL$4,0))} -> 0 | I8: {=INDEX(Reserves!$J$12:$EL$12,,MATCH(Model!I$4,Reserves!$J$4:$EL$4,0))} -> 0 | J8: {=INDEX(Reserves!$J$12:$EL$12,,MATCH(Model!J$4,Reserves!$J$4:$EL$4,0))} -> 0 | K8: {=INDEX(Reserves!$J$12:$EL$12,,MATCH(Model!K$4,Reserves!$J$4:$EL$4,0))} -> 0 | L8: {=INDEX(Reserves!$J$12:$EL$12,,MATCH(Model!L$4,Reserves!$J$4:$EL$4,0))} -> 0 | M8: {=INDEX(Reserves!$J$12:$EL$12,,MATCH(Model!M$4,Reserves!$J$4:$EL$4,0))} -> 0 | N8: {=INDEX(Reserves!$J$12:$EL$12,,MATCH(Model!N$4,Reserves!$J$4:$EL$4,0))} -> 0 | ... EI8: {=INDEX(Reserves!$J$12:$EL$12,,MATCH(Model!EI$4,Reserves!$J$4:$EL$4,0))} -> 0 | EM8: x
B9: =SUM(G9:EI9) -> 2577300 | D9: =+'Hard Costs'!B4 -> Hard Costs | G9: {=INDEX('Hard Costs'!$J$16:$EL$16,,MATCH(Model!G$4,'Hard Costs'!$J$4:$EL$4,0))} -> 20000 | H9: {=INDEX('Hard Costs'!$J$16:$EL$16,,MATCH(Model!H$4,'Hard Costs'!$J$4:$EL$4,0))} -> 0 | I9: {=INDEX('Hard Costs'!$J$16:$EL$16,,MATCH(Model!I$4,'Hard Costs'!$J$4:$EL$4,0))} -> 97652.174 | J9: {=INDEX('Hard Costs'!$J$16:$EL$16,,MATCH(Model!J$4,'Hard Costs'!$J$4:$EL$4,0))} -> 97652.174 | K9: {=INDEX('Hard Costs'!$J$16:$EL$16,,MATCH(Model!K$4,'Hard Costs'!$J$4:$EL$4,0))} -> 97652.174 | L9: {=INDEX('Hard Costs'!$J$16:$EL$16,,MATCH(Model!L$4,'Hard Costs'!$J$4:$EL$4,0))} -> 145152.17 | M9: {=INDEX('Hard Costs'!$J$16:$EL$16,,MATCH(Model!M$4,'Hard Costs'!$J$4:$EL$4,0))} -> 135152.17 | N9: {=INDEX('Hard Costs'!$J$16:$EL$16,,MATCH(Model!N$4,'Hard Costs'!$J$4:$EL$4,0))} -> 97652.174 | ... EI9: {=INDEX('Hard Costs'!$J$16:$EL$16,,MATCH(Model!EI$4,'Hard Costs'!$J$4:$EL$4,0))} -> 0 | EM9: x
B10: =SUM(G10:EI10) -> -19458691 | D10: Total Project Costs | G10: =-SUM(G5:G9) -> -16901391 | H10: =-SUM(H5:H9) -> 0 | I10: =-SUM(I5:I9) -> -97652.174 | J10: =-SUM(J5:J9) -> -97652.174 | K10: =-SUM(K5:K9) -> -97652.174 | L10: =-SUM(L5:L9) -> -145152.17 | M10: =-SUM(M5:M9) -> -135152.17 | N10: =-SUM(N5:N9) -> -97652.174 | ... EI10: =-SUM(EI5:EI9) -> 0 | EM10: x
EM11: x
D12: Condo Sales | EM12: x
D13: Less: Selling Costs | EM13: x
D14: Condo Proceeds, net | EM14: x
EM15: x
D16: Retail Sale | G16: =IF(G$4=Assumptions!$J$174,Assumptions!$J$177,0) -> 0 | H16: =IF(H$4=Assumptions!$J$174,Assumptions!$J$177,0) -> 0 | I16: =IF(I$4=Assumptions!$J$174,Assumptions!$J$177,0) -> 0 | J16: =IF(J$4=Assumptions!$J$174,Assumptions!$J$177,0) -> 0 | K16: =IF(K$4=Assumptions!$J$174,Assumptions!$J$177,0) -> 0 | L16: =IF(L$4=Assumptions!$J$174,Assumptions!$J$177,0) -> 0 | M16: =IF(M$4=Assumptions!$J$174,Assumptions!$J$177,0) -> 0 | N16: =IF(N$4=Assumptions!$J$174,Assumptions!$J$177,0) -> 0 | ... EI16: =IF(EI$4=Assumptions!$J$174,Assumptions!$J$177,0) -> 0 | EM16: x
D17: Less: Selling Costs | G17: =IF(G$4=Assumptions!$J$174,Assumptions!$J$179,0) -> 0 | H17: =IF(H$4=Assumptions!$J$174,Assumptions!$J$179,0) -> 0 | I17: =IF(I$4=Assumptions!$J$174,Assumptions!$J$179,0) -> 0 | J17: =IF(J$4=Assumptions!$J$174,Assumptions!$J$179,0) -> 0 | K17: =IF(K$4=Assumptions!$J$174,Assumptions!$J$179,0) -> 0 | L17: =IF(L$4=Assumptions!$J$174,Assumptions!$J$179,0) -> 0 | M17: =IF(M$4=Assumptions!$J$174,Assumptions!$J$179,0) -> 0 | N17: =IF(N$4=Assumptions!$J$174,Assumptions!$J$179,0) -> 0 | ... EI17: =IF(EI$4=Assumptions!$J$174,Assumptions!$J$179,0) -> 0 | EM17: x
D18: Retail Proceeds, net | G18: =IF(G$4=Assumptions!$J$174,Assumptions!$J$180,0) -> 0 | H18: =IF(H$4=Assumptions!$J$174,Assumptions!$J$180,0) -> 0 | I18: =IF(I$4=Assumptions!$J$174,Assumptions!$J$180,0) -> 0 | J18: =IF(J$4=Assumptions!$J$174,Assumptions!$J$180,0) -> 0 | K18: =IF(K$4=Assumptions!$J$174,Assumptions!$J$180,0) -> 0 | L18: =IF(L$4=Assumptions!$J$174,Assumptions!$J$180,0) -> 0 | M18: =IF(M$4=Assumptions!$J$174,Assumptions!$J$180,0) -> 0 | N18: =IF(N$4=Assumptions!$J$174,Assumptions!$J$180,0) -> 0 | ... EI18: =IF(EI$4=Assumptions!$J$174,Assumptions!$J$180,0) -> 0 | EM18: x
EM19: x
D20: Multifamily Sale | G20: =IF(G4=Assumptions!$E$174,Assumptions!$E$177,0) -> 0 | H20: =IF(H4=Assumptions!$E$174,Assumptions!$E$177,0) -> 0 | I20: =IF(I4=Assumptions!$E$174,Assumptions!$E$177,0) -> 0 | J20: =IF(J4=Assumptions!$E$174,Assumptions!$E$177,0) -> 0 | K20: =IF(K4=Assumptions!$E$174,Assumptions!$E$177,0) -> 0 | L20: =IF(L4=Assumptions!$E$174,Assumptions!$E$177,0) -> 0 | M20: =IF(M4=Assumptions!$E$174,Assumptions!$E$177,0) -> 0 | N20: =IF(N4=Assumptions!$E$174,Assumptions!$E$177,0) -> 0 | ... EI20: =IF(EI4=Assumptions!$E$174,Assumptions!$E$177,0) -> 0 | EM20: x
D21: Less: Selling Costs | G21: =IF(G4=Assumptions!$E$174,Assumptions!$E$179,0) -> 0 | H21: =IF(H4=Assumptions!$E$174,Assumptions!$E$179,0) -> 0 | I21: =IF(I4=Assumptions!$E$174,Assumptions!$E$179,0) -> 0 | J21: =IF(J4=Assumptions!$E$174,Assumptions!$E$179,0) -> 0 | K21: =IF(K4=Assumptions!$E$174,Assumptions!$E$179,0) -> 0 | L21: =IF(L4=Assumptions!$E$174,Assumptions!$E$179,0) -> 0 | M21: =IF(M4=Assumptions!$E$174,Assumptions!$E$179,0) -> 0 | N21: =IF(N4=Assumptions!$E$174,Assumptions!$E$179,0) -> 0 | ... EI21: =IF(EI4=Assumptions!$E$174,Assumptions!$E$179,0) -> 0 | EM21: x
D22: Multifamily Proceeds, net | G22: =IF(G4=Assumptions!$E$174,Assumptions!$E$180,0) -> 0 | H22: =IF(H4=Assumptions!$E$174,Assumptions!$E$180,0) -> 0 | I22: =IF(I4=Assumptions!$E$174,Assumptions!$E$180,0) -> 0 | J22: =IF(J4=Assumptions!$E$174,Assumptions!$E$180,0) -> 0 | K22: =IF(K4=Assumptions!$E$174,Assumptions!$E$180,0) -> 0 | L22: =IF(L4=Assumptions!$E$174,Assumptions!$E$180,0) -> 0 | M22: =IF(M4=Assumptions!$E$174,Assumptions!$E$180,0) -> 0 | N22: =IF(N4=Assumptions!$E$174,Assumptions!$E$180,0) -> 0 | ... EI22: =IF(EI4=Assumptions!$E$174,Assumptions!$E$180,0) -> 0 | EM22: x
EM23: x
D24: Retail Income | G24: {=IFERROR(INDEX('NOI Walk'!$H$61:$EI$61,,MATCH(Model!G$4,'NOI Walk'!$H$16:$EI$16,0)),0)} -> 0 | H24: {=IFERROR(INDEX('NOI Walk'!$H$61:$EI$61,,MATCH(Model!H$4,'NOI Walk'!$H$16:$EI$16,0)),0)} -> 0 | I24: {=IFERROR(INDEX('NOI Walk'!$H$61:$EI$61,,MATCH(Model!I$4,'NOI Walk'!$H$16:$EI$16,0)),0)} -> 0 | J24: {=IFERROR(INDEX('NOI Walk'!$H$61:$EI$61,,MATCH(Model!J$4,'NOI Walk'!$H$16:$EI$16,0)),0)} -> 0 | K24: {=IFERROR(INDEX('NOI Walk'!$H$61:$EI$61,,MATCH(Model!K$4,'NOI Walk'!$H$16:$EI$16,0)),0)} -> 0 | L24: {=IFERROR(INDEX('NOI Walk'!$H$61:$EI$61,,MATCH(Model!L$4,'NOI Walk'!$H$16:$EI$16,0)),0)} -> 0 | M24: {=IFERROR(INDEX('NOI Walk'!$H$61:$EI$61,,MATCH(Model!M$4,'NOI Walk'!$H$16:$EI$16,0)),0)} -> 0 | N24: {=IFERROR(INDEX('NOI Walk'!$H$61:$EI$61,,MATCH(Model!N$4,'NOI Walk'!$H$16:$EI$16,0)),0)} -> 0 | ... EI24: {=IFERROR(INDEX('NOI Walk'!$H$61:$EI$61,,MATCH(Model!EI$4,'NOI Walk'!$H$16:$EI$16,0)),0)} -> 0 | EM24: x
D25: Less: Leasing Cost Reserves | G25: {=-IFERROR(INDEX('NOI Walk'!$H$65:$EI$65,,MATCH(Model!G$4,'NOI Walk'!$H$16:$EI$16,0)),0)} -> 0 | H25: {=-IFERROR(INDEX('NOI Walk'!$H$65:$EI$65,,MATCH(Model!H$4,'NOI Walk'!$H$16:$EI$16,0)),0)} -> 0 | I25: {=-IFERROR(INDEX('NOI Walk'!$H$65:$EI$65,,MATCH(Model!I$4,'NOI Walk'!$H$16:$EI$16,0)),0)} -> 0 | J25: {=-IFERROR(INDEX('NOI Walk'!$H$65:$EI$65,,MATCH(Model!J$4,'NOI Walk'!$H$16:$EI$16,0)),0)} -> 0 | K25: {=-IFERROR(INDEX('NOI Walk'!$H$65:$EI$65,,MATCH(Model!K$4,'NOI Walk'!$H$16:$EI$16,0)),0)} -> 0 | L25: {=-IFERROR(INDEX('NOI Walk'!$H$65:$EI$65,,MATCH(Model!L$4,'NOI Walk'!$H$16:$EI$16,0)),0)} -> 0 | M25: {=-IFERROR(INDEX('NOI Walk'!$H$65:$EI$65,,MATCH(Model!M$4,'NOI Walk'!$H$16:$EI$16,0)),0)} -> 0 | N25: {=-IFERROR(INDEX('NOI Walk'!$H$65:$EI$65,,MATCH(Model!N$4,'NOI Walk'!$H$16:$EI$16,0)),0)} -> 0 | ... EI25: {=-IFERROR(INDEX('NOI Walk'!$H$65:$EI$65,,MATCH(Model!EI$4,'NOI Walk'!$H$16:$EI$16,0)),0)} -> 0 | EM25: x
D26: Retail Cash Flow | G26: =SUM(G24:G25) -> 0 | H26: =SUM(H24:H25) -> 0 | I26: =SUM(I24:I25) -> 0 | J26: =SUM(J24:J25) -> 0 | K26: =SUM(K24:K25) -> 0 | L26: =SUM(L24:L25) -> 0 | M26: =SUM(M24:M25) -> 0 | N26: =SUM(N24:N25) -> 0 | ... EI26: =SUM(EI24:EI25) -> 0 | EM26: x
EM27: x
D28: Multifamily NOI | G28: {=IFERROR(INDEX('NOI Walk'!$H$54:$EI$54,,MATCH(Model!G$4,'NOI Walk'!$H$16:$EI$16,0)),0)} -> 0 | H28: {=IFERROR(INDEX('NOI Walk'!$H$54:$EI$54,,MATCH(Model!H$4,'NOI Walk'!$H$16:$EI$16,0)),0)} -> 80459.495 | I28: {=IFERROR(INDEX('NOI Walk'!$H$54:$EI$54,,MATCH(Model!I$4,'NOI Walk'!$H$16:$EI$16,0)),0)} -> 75837.508 | J28: {=IFERROR(INDEX('NOI Walk'!$H$54:$EI$54,,MATCH(Model!J$4,'NOI Walk'!$H$16:$EI$16,0)),0)} -> 71196.087 | K28: {=IFERROR(INDEX('NOI Walk'!$H$54:$EI$54,,MATCH(Model!K$4,'NOI Walk'!$H$16:$EI$16,0)),0)} -> 66535.171 | L28: {=IFERROR(INDEX('NOI Walk'!$H$54:$EI$54,,MATCH(Model!L$4,'NOI Walk'!$H$16:$EI$16,0)),0)} -> 69219.137 | M28: {=IFERROR(INDEX('NOI Walk'!$H$54:$EI$54,,MATCH(Model!M$4,'NOI Walk'!$H$16:$EI$16,0)),0)} -> 73435.037 | N28: {=IFERROR(INDEX('NOI Walk'!$H$54:$EI$54,,MATCH(Model!N$4,'NOI Walk'!$H$16:$EI$16,0)),0)} -> 76143.347 | ... EI28: {=IFERROR(INDEX('NOI Walk'!$H$54:$EI$54,,MATCH(Model!EI$4,'NOI Walk'!$H$16:$EI$16,0)),0)} -> 196131.31 | EM28: x
D29: Less: CapEx | G29: {=-IFERROR(INDEX('NOI Walk'!$H$59:$EI$59,,MATCH(Model!G$4,'NOI Walk'!$H$16:$EI$16,0)),0)} -> 0 | H29: {=-IFERROR(INDEX('NOI Walk'!$H$59:$EI$59,,MATCH(Model!H$4,'NOI Walk'!$H$16:$EI$16,0)),0)} -> -1359.3679 | I29: {=-IFERROR(INDEX('NOI Walk'!$H$59:$EI$59,,MATCH(Model!I$4,'NOI Walk'!$H$16:$EI$16,0)),0)} -> -1309.7548 | J29: {=-IFERROR(INDEX('NOI Walk'!$H$59:$EI$59,,MATCH(Model!J$4,'NOI Walk'!$H$16:$EI$16,0)),0)} -> -1259.9334 | K29: {=-IFERROR(INDEX('NOI Walk'!$H$59:$EI$59,,MATCH(Model!K$4,'NOI Walk'!$H$16:$EI$16,0)),0)} -> -1209.903 | L29: {=-IFERROR(INDEX('NOI Walk'!$H$59:$EI$59,,MATCH(Model!L$4,'NOI Walk'!$H$16:$EI$16,0)),0)} -> -1238.4461 | M29: {=-IFERROR(INDEX('NOI Walk'!$H$59:$EI$59,,MATCH(Model!M$4,'NOI Walk'!$H$16:$EI$16,0)),0)} -> -1282.7837 | N29: {=-IFERROR(INDEX('NOI Walk'!$H$59:$EI$59,,MATCH(Model!N$4,'NOI Walk'!$H$16:$EI$16,0)),0)} -> -1311.5806 | ... EI29: {=-IFERROR(INDEX('NOI Walk'!$H$59:$EI$59,,MATCH(Model!EI$4,'NOI Walk'!$H$16:$EI$16,0)),0)} -> -2681.0347 | EM29: x
D30: Multifamily Cash Flow | G30: =SUM(G28:G29) -> 0 | H30: =SUM(H28:H29) -> 79100.127 | I30: =SUM(I28:I29) -> 74527.753 | J30: =SUM(J28:J29) -> 69936.153 | K30: =SUM(K28:K29) -> 65325.268 | L30: =SUM(L28:L29) -> 67980.691 | M30: =SUM(M28:M29) -> 72152.254 | N30: =SUM(N28:N29) -> 74831.767 | ... EI30: =SUM(EI28:EI29) -> 193450.28 | EM30: x
EM31: x
D32: Total Unlevered Cash Flow | G32: =IF(G4>Assumptions!$E$174,0,SUM(G30,G26,G10,G22,G18)) -> -16901391 | H32: =IF(H4>Assumptions!$E$174,0,SUM(H30,H26,H10,H22,H18)) -> 79100.127 | I32: =IF(I4>Assumptions!$E$174,0,SUM(I30,I26,I10,I22,I18)) -> -23124.421 | J32: =IF(J4>Assumptions!$E$174,0,SUM(J30,J26,J10,J22,J18)) -> -27716.02 | K32: =IF(K4>Assumptions!$E$174,0,SUM(K30,K26,K10,K22,K18)) -> -32326.906 | L32: =IF(L4>Assumptions!$E$174,0,SUM(L30,L26,L10,L22,L18)) -> -77171.483 | M32: =IF(M4>Assumptions!$E$174,0,SUM(M30,M26,M10,M22,M18)) -> -62999.92 | N32: =IF(N4>Assumptions!$E$174,0,SUM(N30,N26,N10,N22,N18)) -> -22820.407 | ... EI32: =IF(EI4>Assumptions!$E$174,0,SUM(EI30,EI26,EI10,EI22,EI18)) -> 0 | EM32: x
D33: Equity In | F33: =SUM(G33:EI33) -> -19458691 | G33: =+MIN(G10,0) -> -16901391 | H33: =+MIN(H10,0) -> 0 | I33: =+MIN(I10,0) -> -97652.174 | J33: =+MIN(J10,0) -> -97652.174 | K33: =+MIN(K10,0) -> -97652.174 | L33: =+MIN(L10,0) -> -145152.17 | M33: =+MIN(M10,0) -> -135152.17 | N33: =+MIN(N10,0) -> -97652.174 | ... EI33: =+MIN(EI10,0) -> 0 | EM33: x
D34: Profit | F34: =+SUM(G32:OFFSET(G32,,Assumptions!$E$174)) -> 21365755 | EM34: x
D35: Unlevered IRR | F35: =XIRR(G32:EI32,$G$2:$EI$2) -> 0.18511292 | EM35: x
D36: Unlevered MOIC | F36: =-(F34-G33)/G33 -> 2.2641418 | EM36: x
EM37: x
D38: Financable Costs | G38: =-G5-G9 -> -15020000 | H38: =-H5-H9 -> 0 | I38: =-I5-I9 -> -97652.174 | J38: =-J5-J9 -> -97652.174 | K38: =-K5-K9 -> -97652.174 | L38: =-L5-L9 -> -145152.17 | M38: =-M5-M9 -> -135152.17 | N38: =-N5-N9 -> -97652.174 | ... S38: =-S5-S9 -> -96652.174 | T38: =+T33 -> -96652.174 | U38: =+U33 -> -96652.174 | V38: =+V33 -> -96652.174 | W38: =+W33 -> -96652.174 | X38: =+X33 -> -96652.174 | Y38: =+Y33 -> -96652.174 | Z38: =+Z33 -> -96652.174 | AA38: =+AA33 -> -96652.174 | ... EI38: =+EI33 -> 0 | EM38: x
D39: Remaining Costs | G39: =+G33-G38 -> -1881390.8 | H39: =+H33-H38 -> 0 | I39: =+I33-I38 -> 0 | J39: =+J33-J38 -> 0 | K39: =+K33-K38 -> 0 | L39: =+L33-L38 -> 0 | M39: =+M33-M38 -> 0 | N39: =+N33-N38 -> 0 | ... EI39: =+EI33-EI38 -> 0 | EM39: x
D40: Cash Available for DSCR Loan Paydown | G40: =+G58 -> 0 | H40: =+H58 -> 0 | I40: =+I58 -> 0 | J40: =+J58 -> 0 | K40: =+K58 -> 0 | L40: =+L58 -> 0 | M40: =+M58 -> 0 | N40: =+N58 -> 0 | ... BN40: =+BN58 -> 0 | BO40: =IF(AND(Assumptions!$G$34="No",Model!BO4=Assumptions!$E$174),BO32,BO58) -> 0 | BP40: =+BP58 -> 0 | BQ40: =+BQ58 -> 0 | BR40: =+BR58 -> 0 | BS40: =+BS58 -> 0 | BT40: =+BT58 -> 0 | BU40: =+BU58 -> 0 | BV40: =+BV58 -> 0 | BW40: =+BW58 -> 0 | ... EI40: =+EI58 -> 0 | EM40: x
...

Sheet Assumptions
A1: 265-275 Beech St. Hackensack, NJ
B2: Model Start | F2: 45838 | I2: Ownership Splits | N2: Offer | O2: Price | P2: Terms
I3: Sponsor Equity | K3: 0.1 | L3: =+F5 -> 848931.38 | N3: Ask | O3: =+G22 -> 15000000
B4: Sources | F4: $ | G4: % | I4: LP Equity | K4: =1-K3 -> 0.9 | L4: =+F6 -> 7640382.4 | N4: Offer 1
B5: Sponsor Equity | F5: =+F8-SUM(F6:F7) -> 848931.38 | G5: =+F5/$F$8 -> 0.043007137 | I5: Total Equity | K5: =SUM(K3:K4) -> 1 | L5: =SUM(L3:L4) -> 8489313.8
B6: LP Equity | F6: =(F8-SUM(F7:F7))*K4 -> 7640382.4 | G6: =+F6/$F$8 -> 0.38706424
B7: =+B27 -> Acquisition Loan | F7: =+G31 -> 11250000 | G7: =+F7/$F$8 -> 0.56992863
A8: =F8=SUM(F5:F7) -> TRUE | B8: Total Sources | F8: =+F17 -> 19739314 | G8: =+F8/$F$8 -> 1 | I8: Levered IRR | K8: =+E183 -> 0.33942088
I9: Levered MOIC | K9: =+E184 -> 2.7836218
B10: Uses | F10: $ | G10: %
B11: Acquisition of Property | F11: =+G23 -> 15000000 | G11: =+F11/$F$17 -> 0.75990484
B12: Closing Costs | F12: =+'Closing Costs'!E19 -> 1062339.1 | G12: =+F12/$F$17 -> 0.05381844
B13: Legal and Pre-Development | F13: =+'Legal and Pre-Dev'!E12 -> 29925 | G13: =+F13/$F$17 -> 0.0015160101
B14: Reserves | F14: =+Reserves!E12 -> 789126.76 | G14: =+F14/$F$17 -> 0.039977416
B15: Hard Costs | F15: =+'Hard Costs'!E16 -> 2577300 | G15: =+F15/$F$17 -> 0.13056685
B16: Interest Reserve | F16: =+L31 -> 280622.96 | G16: =+F16/$F$17 -> 0.01421645
A17: =F17=SUM(F11:F16) -> TRUE | B17: Total Uses | F17: =SUM(F11:F16) -> 19739314 | G17: =+F17/$F$17 -> 1
I20: Re-leased Cash-on-Cash | L20: {=+INDEX(Model!69:69,,MATCH(G144+3,Model!4:4,0))*12/L5} -> 13.381843
B21: General Property Assumptions | I21: Going-in Cap | L21: =('NOI Walk'!H54*12)/G23 -> 0.064367596
B22: Ask | G22: 15000000 | I22: Going-in Cash-on-Cash | L22: {=+INDEX(Model!69:69,,MATCH(1,Model!4:4,0))*12/L5} -> -0.027743125
B23: Acquisition Price | E23: =+G23/D124 -> 192307.69 | F23: =+G23/O3-1 -> 0 | G23: 15000000 | I23: Net Rentable SF | L23: =SUM(E46:E123)+'Retail Assumptions'!F19 -> 49950 | N23: ="Max "&B27 -> Max Acquisition Loan
B24: Closing on Property | G24: 0 | I24: Efficiency | L24: =+L23/G25 -> 0.90818182 | N24: ="Stabilized Annualized NOI in Month "&1 -> Stabilized Annualized NOI in Month 1 | R24: {=INDEX('NOI Walk'!$H$67:$EI$67,,MATCH(1,'NOI Walk'!$H$16:$EI$16,0))*12} -> 965513.94
B25: Buildable SF | G25: 55000 | I25: Stabilized Yield on Cost | L25: {=INDEX('NOI Walk'!$H$67:$EI$67,,MATCH(Assumptions!G144+1,'NOI Walk'!$H$16:$EI$16,0))*12/F17} -> 0.095658551 | N25: Required DSCR Minimum | R25: 0.25
N26: Max Loan Size Based on DSCR | R26: =+R24/R25/L27 -> 36407269
B27: Acquisition Loan | I27: Loan Constant | L27: =IFERROR(PMT(L29,L30,-1),L29) -> 0.10607925
B28: Origination | G28: 0 | I28: Origination Fee | L28: 0.02 | N28: Acquisition Financing | R28: =+G23 -> 15000000
B29: LTC on Property | G29: =+G31/G23 -> 0.75 | I29: Rate | K29: =(L29-'1-month Term SOFR'!Q16)*10000 -> 596.375 | L29: 0.1 | N29: LTV Max | R29: 0.75
B30: LTC on Hard Costs | G30: 0 | I30: Amortization | L30: 30 | N30: Max Loan Size Based on LTC | R30: =+R29*R28 -> 11250000
B31: Max Loan Size | G31: =+R33 -> 11250000 | I31: Interest Reserve | L31: =-Model!B53 -> 280622.96 | N31: Plus: Hard Cost Advance | R31: =+G30*F15 -> 0
B33: Permanent Loan | I33: Max Loan as Lesser of… | N33: =+N23 -> Max Acquisition Loan | R33: =MIN(R30+R31,R26) -> 11250000
B34: Permanent Loan Issued? | G34: Yes | I34: DSCR Min. | K34: 1.25 | L34: =+L38/K34/L39 -> 20678404
B35: Seasoning Period Post Stabilization | G35: =+G36-G144 -> 3 | I35: Debt Yield Min. | K35: 0.09 | L35: =+L38/K35 -> 21072210
B36: Refinancing Month | G36: 33 | I36: LTV Max | J36: 0.06 | K36: 0.75 | L36: =+L38/J36*K36 -> 23706236
B37: Fixed Interest Rate | G37: {=G38/10000+INDEX(Model!$G$76:$EI$76,,MATCH(Assumptions!G36,Model!$G$4:$EI$4,0))} -> 0.0618393 | I37: Max Perm. Loan | L37: =MIN(L34:L36) -> 20678404
B38: SOFR Spread at Origination | G38: 250 | I38: ="Annualized NOI in Month "&G36 -> Annualized NOI in Month 33 | L38: {=INDEX('NOI Walk'!$H$67:$EI$67,,MATCH(Assumptions!G36,'NOI Walk'!$H$16:$EI$16,0))*12} -> 1896498.9
B39: Amortization | G39: 30 | I39: Loan Factor | L39: =+PMT(G37/12,G39*12,-1)*12 -> 0.073371188
B40: Origination Cost | G40: 0.01 | I40: Perm Loan Proceeds net of fees | L40: =+L37*(1-G40) -> 20471620
I41: Proceeds from Cashout | L41: {=+INDEX(Model!G69:EI69,,MATCH(Assumptions!G36,Model!$G$4:$EI$4,0))} -> 9466888.8
G43: Unlevered ROI | H43: =((I124-H124)*12)/'Hard Costs'!E14 -> 0.3621234
B44: Rental Assumptions
...

Sheet NOI Walk
S1: on Ask Price
B2: =+Assumptions!B45 -> Units | C2: =+Assumptions!D124 -> 78 | H2: Step-Up in Rent | K2: =+C4-C3 -> 860.04308 | M2: =Assumptions!I143 -> Initial Lease-up Cost | O2: =+Assumptions!L144 -> 2430.7692 | Q2: Year 1 NOI | R2: =SUMIFS($H$67:$EI$67,H16:EI16,"<=12") -> 934551.93 | S2: =+R2/Assumptions!$O$3 -> 0.062303462
B3: Current Rent / Unit | C3: =+Assumptions!H124/Assumptions!D124 -> 1570.7262 | H3: =Assumptions!B140 -> Rehab Time | K3: =Assumptions!G140 -> 2 | M3: =+Assumptions!N144 -> Ongoing Lease-up Cost | O3: =+Assumptions!P144 -> 0.016666667 | Q3: Seller's NOI | R3: 865253.4 | S3: =+R3/Assumptions!$O$3 -> 0.05768356
B4: Pro Forma Rent / Unit | C4: =+Assumptions!I124/Assumptions!D124 -> 2430.7692 | H4: =Assumptions!B141 -> Lease-up Time | K4: =Assumptions!G141 -> 1 | M4: =+Assumptions!B136 -> Rental Inflation | O4: =+Assumptions!E136 -> 0.025 | Q4: Change in NOI | R4: =+R2/R3-1 -> 0.080090448
A5: =+Assumptions!E127 -> 0.9 | B5: =+Assumptions!B127 -> Parking | C5: =+Assumptions!H127 -> 75 | H5: =Assumptions!B144 -> Re-Stabilization Occurs | K5: =Assumptions!G144 -> 30 | M5: =+Assumptions!G136 -> Amenity Inflation | O5: =+Assumptions!I136 -> 0.02 | Q5: Stabilized NOI | R5: {=+INDEX('NOI Walk'!H67:EI67,,MATCH(Assumptions!G144,'NOI Walk'!H16:EI16,0))*12} -> 1884115.2 | S5: =+R5/Assumptions!$O$3 -> 0.12560768
A6: =+Assumptions!E128 -> 0.75 | B6: =+Assumptions!B128 -> Storage | C6: =+Assumptions!H128 -> 30 | H6: =Assumptions!B145 -> Bad Debt | K6: =Assumptions!G145 -> 0 | M6: =+Assumptions!B137 -> Expense Inflation | O6: =+Assumptions!E137 -> 0.02
A7: =+Assumptions!E129 -> 1 | B7: =+Assumptions!B129 -> Laundry | C7: =+Assumptions!H129 -> 11 | H7: =Assumptions!B146 -> Vacancy | K7: =Assumptions!G146 -> 0.05
A8: =+Assumptions!E130 -> 0.9 | B8: Parking | C8: =+Assumptions!H130 -> 100
B10: Rent Inflation Factor | H10: =(1+($O$4/12))^H16 -> 1.0020833 | I10: =(1+($O$4/12))^I16 -> 1.004171 | J10: =(1+($O$4/12))^J16 -> 1.006263 | K10: =(1+($O$4/12))^K16 -> 1.0083594 | L10: =(1+($O$4/12))^L16 -> 1.0104602 | M10: =(1+($O$4/12))^M16 -> 1.0125653 | N10: =(1+($O$4/12))^N16 -> 1.0146748 | O10: =(1+($O$4/12))^O16 -> 1.0167887 | ... EI10: =(1+($O$4/12))^EI16 -> 1.3161541
B11: Amenity Inflation Factor | H11: =(1+($O$5/12))^H16 -> 1.0016667 | I11: =(1+($O$5/12))^I16 -> 1.0033361 | J11: =(1+($O$5/12))^J16 -> 1.0050083 | K11: =(1+($O$5/12))^K16 -> 1.0066834 | L11: =(1+($O$5/12))^L16 -> 1.0083612 | M11: =(1+($O$5/12))^M16 -> 1.0100418 | N11: =(1+($O$5/12))^N16 -> 1.0117252 | O11: =(1+($O$5/12))^O16 -> 1.0134114 | ... EI11: =(1+($O$5/12))^EI16 -> 1.2458486
B12: Expenses Inflation Factor | H12: =(1+($O$6/12))^H16 -> 1.0016667 | I12: =(1+($O$6/12))^I16 -> 1.0033361 | J12: =(1+($O$6/12))^J16 -> 1.0050083 | K12: =(1+($O$6/12))^K16 -> 1.0066834 | L12: =(1+($O$6/12))^L16 -> 1.0083612 | M12: =(1+($O$6/12))^M16 -> 1.0100418 | N12: =(1+($O$6/12))^N16 -> 1.0117252 | O12: =(1+($O$6/12))^O16 -> 1.0134114 | ... EI12: =(1+($O$6/12))^EI16 -> 1.2458486
B13: Timeline | H13: =IF(H16<$K$5,"Lease-up",IF(H16=$K$5,"Stabilization","-")) -> Lease-up | I13: =IF(I16<$K$5,"Lease-up",IF(I16=$K$5,"Stabilization","-")) -> Lease-up | J13: =IF(J16<$K$5,"Lease-up",IF(J16=$K$5,"Stabilization","-")) -> Lease-up | K13: =IF(K16<$K$5,"Lease-up",IF(K16=$K$5,"Stabilization","-")) -> Lease-up | L13: =IF(L16<$K$5,"Lease-up",IF(L16=$K$5,"Stabilization","-")) -> Lease-up | M13: =IF(M16<$K$5,"Lease-up",IF(M16=$K$5,"Stabilization","-")) -> Lease-up | N13: =IF(N16<$K$5,"Lease-up",IF(N16=$K$5,"Stabilization","-")) -> Lease-up | O13: =IF(O16<$K$5,"Lease-up",IF(O16=$K$5,"Stabilization","-")) -> Lease-up | ... EI13: =IF(EI16<$K$5,"Lease-up",IF(EI16=$K$5,"Stabilization","-")) -> -
H14: =YEAR(Model!H2) -> 2025 | I14: =YEAR(Model!I2) -> 2025 | J14: =YEAR(Model!J2) -> 2025 | K14: =YEAR(Model!K2) -> 2025 | L14: =YEAR(Model!L2) -> 2025 | M14: =YEAR(Model!M2) -> 2025 | N14: =YEAR(Model!N2) -> 2026 | O14: =YEAR(Model!O2) -> 2026 | ... DV14: =YEAR(Model!DV2) -> 2035 | DW14: =YEAR(Model!#REF!) -> #REF! | DX14: =YEAR(Model!EJ2) -> 1900 | DY14: =YEAR(Model!EK2) -> 1900 | DZ14: =YEAR(Model!EL2) -> 1900 | EA14: =YEAR(Model!EM2) -> #VALUE! | EB14: =YEAR(Model!EN2) -> 1900 | EC14: =YEAR(Model!EO2) -> 1900 | ED14: =YEAR(Model!EP2) -> 1900 | EE14: =YEAR(Model!EQ2) -> 1900 | ... EI14: =YEAR(Model!EU2) -> 1900
H15: =+ROUNDUP(H16/12,0) -> 1 | I15: =+ROUNDUP(I16/12,0) -> 1 | J15: =+ROUNDUP(J16/12,0) -> 1 | K15: =+ROUNDUP(K16/12,0) -> 1 | L15: =+ROUNDUP(L16/12,0) -> 1 | M15: =+ROUNDUP(M16/12,0) -> 1 | N15: =+ROUNDUP(N16/12,0) -> 1 | O15: =+ROUNDUP(O16/12,0) -> 1 | ... EI15: =+ROUNDUP(EI16/12,0) -> 11
H16: 1 | I16: =+H16+1 -> 2 | J16: =+I16+1 -> 3 | K16: =+J16+1 -> 4 | L16: =+K16+1 -> 5 | M16: =+L16+1 -> 6 | N16: =+M16+1 -> 7 | O16: =+N16+1 -> 8 | P16: =+O16+1 -> 9 | ... EI16: =+EH16+1 -> 132
B17: Beg. Units Leased | H17: =COUNTIF(Assumptions!H46:H123,">0") -> 78 | I17: =+H20 -> 78 | J17: =+I20 -> 75 | K17: =+J20 -> 72 | L17: =+K20 -> 69 | M17: =+L20 -> 69 | N17: =+M20 -> 69 | O17: =+N20 -> 69 | P17: =+O20 -> 69 | ... EI17: =+EH20 -> 78
B18: Units Vacated | H18: =-COUNTIFS(Assumptions!$C$46:$C$123,1,Assumptions!$F$46:$F$123,'NOI Walk'!H16,Assumptions!$H$46:$H$123,">0")-COUNTIFS(Assumptions!$C$46:$C$123,2,Assumptions!$F$46:$F$123,H16) -> 0 | I18: =-COUNTIFS(Assumptions!$C$46:$C$123,1,Assumptions!$F$46:$F$123,'NOI Walk'!I16,Assumptions!$H$46:$H$123,">0")-COUNTIFS(Assumptions!$C$46:$C$123,2,Assumptions!$F$46:$F$123,I16) -> -3 | J18: =-COUNTIFS(Assumptions!$C$46:$C$123,1,Assumptions!$F$46:$F$123,'NOI Walk'!J16,Assumptions!$H$46:$H$123,">0")-COUNTIFS(Assumptions!$C$46:$C$123,2,Assumptions!$F$46:$F$123,J16) -> -3 | K18: =-COUNTIFS(Assumptions!$C$46:$C$123,1,Assumptions!$F$46:$F$123,'NOI Walk'!K16,Assumptions!$H$46:$H$123,">0")-COUNTIFS(Assumptions!$C$46:$C$123,2,Assumptions!$F$46:$F$123,K16) -> -3 | L18: =-COUNTIFS(Assumptions!$C$46:$C$123,1,Assumptions!$F$46:$F$123,'NOI Walk'!L16,Assumptions!$H$46:$H$123,">0")-COUNTIFS(Assumptions!$C$46:$C$123,2,Assumptions!$F$46:$F$123,L16) -> -3 | M18: =-COUNTIFS(Assumptions!$C$46:$C$123,1,Assumptions!$F$46:$F$123,'NOI Walk'!M16,Assumptions!$H$46:$H$123,">0")-COUNTIFS(Assumptions!$C$46:$C$123,2,Assumptions!$F$46:$F$123,M16) -> -3 | N18: =-COUNTIFS(Assumptions!$C$46:$C$123,1,Assumptions!$F$46:$F$123,'NOI Walk'!N16,Assumptions!$H$46:$H$123,">0")-COUNTIFS(Assumptions!$C$46:$C$123,2,Assumptions!$F$46:$F$123,N16) -> -3 | O18: =-COUNTIFS(Assumptions!$C$46:$C$123,1,Assumptions!$F$46:$F$123,'NOI Walk'!O16,Assumptions!$H$46:$H$123,">0")-COUNTIFS(Assumptions!$C$46:$C$123,2,Assumptions!$F$46:$F$123,O16) -> -3 | ... EI18: =-COUNTIFS(Assumptions!$C$46:$C$123,1,Assumptions!$F$46:$F$123,'NOI Walk'!EI16,Assumptions!$H$46:$H$123,">0")-COUNTIFS(Assumptions!$C$46:$C$123,2,Assumptions!$F$46:$F$123,EI16) -> 0
B19: New Units Leased | H19: =COUNTIFS(Assumptions!$C$46:$C$123,1,Assumptions!$F$46:$F$123,'NOI Walk'!H16-SUM('NOI Walk'!$K$3:$K$4))+COUNTIFS(Assumptions!$C$46:$C$123,2,Assumptions!$F$46:$F$123,'NOI Walk'!H16) -> 0 | I19: =COUNTIFS(Assumptions!$C$46:$C$123,1,Assumptions!$F$46:$F$123,'NOI Walk'!I16-SUM('NOI Walk'!$K$3:$K$4))+COUNTIFS(Assumptions!$C$46:$C$123,2,Assumptions!$F$46:$F$123,'NOI Walk'!I16) -> 0 | J19: =COUNTIFS(Assumptions!$C$46:$C$123,1,Assumptions!$F$46:$F$123,'NOI Walk'!J16-SUM('NOI Walk'!$K$3:$K$4))+COUNTIFS(Assumptions!$C$46:$C$123,2,Assumptions!$F$46:$F$123,'NOI Walk'!J16) -> 0 | K19: =COUNTIFS(Assumptions!$C$46:$C$123,1,Assumptions!$F$46:$F$123,'NOI Walk'!K16-SUM('NOI Walk'!$K$3:$K$4))+COUNTIFS(Assumptions!$C$46:$C$123,2,Assumptions!$F$46:$F$123,'NOI Walk'!K16) -> 0 | L19: =COUNTIFS(Assumptions!$C$46:$C$123,1,Assumptions!$F$46:$F$123,'NOI Walk'!L16-SUM('NOI Walk'!$K$3:$K$4))+COUNTIFS(Assumptions!$C$46:$C$123,2,Assumptions!$F$46:$F$123,'NOI Walk'!L16) -> 3 | M19: =COUNTIFS(Assumptions!$C$46:$C$123,1,Assumptions!$F$46:$F$123,'NOI Walk'!M16-SUM('NOI Walk'!$K$3:$K$4))+COUNTIFS(Assumptions!$C$46:$C$123,2,Assumptions!$F$46:$F$123,'NOI Walk'!M16) -> 3 | N19: =COUNTIFS(Assumptions!$C$46:$C$123,1,Assumptions!$F$46:$F$123,'NOI Walk'!N16-SUM('NOI Walk'!$K$3:$K$4))+COUNTIFS(Assumptions!$C$46:$C$123,2,Assumptions!$F$46:$F$123,'NOI Walk'!N16) -> 3 | O19: =COUNTIFS(Assumptions!$C$46:$C$123,1,Assumptions!$F$46:$F$123,'NOI Walk'!O16-SUM('NOI Walk'!$K$3:$K$4))+COUNTIFS(Assumptions!$C$46:$C$123,2,Assumptions!$F$46:$F$123,'NOI Walk'!O16) -> 3 | ... EI19: =COUNTIFS(Assumptions!$C$46:$C$123,1,Assumptions!$F$46:$F$123,'NOI Walk'!EI16-SUM('NOI Walk'!$K$3:$K$4))+COUNTIFS(Assumptions!$C$46:$C$123,2,Assumptions!$F$46:$F$123,'NOI Walk'!EI16) -> 0
B20: End. Units Leased | H20: =SUM(H17:H19) -> 78 | I20: =SUM(I17:I19) -> 75 | J20: =SUM(J17:J19) -> 72 | K20: =SUM(K17:K19) -> 69 | L20: =SUM(L17:L19) -> 69 | M20: =SUM(M17:M19) -> 69 | N20: =SUM(N17:N19) -> 69 | O20: =SUM(O17:O19) -> 69 | ... EI20: =SUM(EI17:EI19) -> 78
B22: Gross Potential Rent | H22: =+$C$4*$C$2*H10 -> 189995 | I22: =+$C$4*$C$2*I10 -> 190390.82 | J22: =+$C$4*$C$2*J10 -> 190787.47 | K22: =+$C$4*$C$2*K10 -> 191184.94 | L22: =+$C$4*$C$2*L10 -> 191583.25 | M22: =+$C$4*$C$2*M10 -> 191982.38 | N22: =+$C$4*$C$2*N10 -> 192382.34 | O22: =+$C$4*$C$2*O10 -> 192783.14 | ... EI22: =+$C$4*$C$2*EI10 -> 249542.82
B23: Loss-to-Lease | H23: =($C$3-$C$4)*($C$2-SUM($H$19:H19))*H10 -> -67223.117 | I23: =($C$3-$C$4)*($C$2-SUM($H$19:I19))*I10 -> -67363.165 | J23: =($C$3-$C$4)*($C$2-SUM($H$19:J19))*J10 -> -67503.505 | K23: =($C$3-$C$4)*($C$2-SUM($H$19:K19))*K10 -> -67644.137 | L23: =($C$3-$C$4)*($C$2-SUM($H$19:L19))*L10 -> -65177.945 | M23: =($C$3-$C$4)*($C$2-SUM($H$19:M19))*M10 -> -62701.183 | N23: =($C$3-$C$4)*($C$2-SUM($H$19:N19))*N10 -> -60213.818 | O23: =($C$3-$C$4)*($C$2-SUM($H$19:O19))*O10 -> -57715.818 | ... EI23: =($C$3-$C$4)*($C$2-SUM($H$19:EI19))*EI10 -> 0
B24: In-Place Rental Income | H24: =+$C$3*($C$2+SUM($H$18:H18))*H10 -> 122771.88 | I24: =+$C$3*($C$2+SUM($H$18:I18))*I10 -> 118295.82 | J24: =+$C$3*($C$2+SUM($H$18:J18))*J10 -> 113800.58 | K24: =+$C$3*($C$2+SUM($H$18:K18))*K10 -> 109286.1 | L24: =+$C$3*($C$2+SUM($H$18:L18))*L10 -> 104752.31 | M24: =+$C$3*($C$2+SUM($H$18:M18))*M10 -> 100199.15 | N24: =+$C$3*($C$2+SUM($H$18:N18))*N10 -> 95626.574 | O24: =+$C$3*($C$2+SUM($H$18:O18))*O10 -> 91034.507 | ... EI24: =+$C$3*($C$2+SUM($H$18:EI18))*EI10 -> 0
B25: Pro Forma Rental Income | H25: =+SUM($H$19:H19)*$C$4*H10 -> 0 | I25: =+SUM($H$19:I19)*$C$4*I10 -> 0 | J25: =+SUM($H$19:J19)*$C$4*J10 -> 0 | K25: =+SUM($H$19:K19)*$C$4*K10 -> 0 | L25: =+SUM($H$19:L19)*$C$4*L10 -> 7368.5864 | M25: =+SUM($H$19:M19)*$C$4*M10 -> 14767.875 | N25: =+SUM($H$19:N19)*$C$4*N10 -> 22197.962 | O25: =+SUM($H$19:O19)*$C$4*O10 -> 29658.944 | ... EI25: =+SUM($H$19:EI19)*$C$4*EI10 -> 249542.82
B26: Vacancy | H26: =+IF(H16<$K$5,SUM(H24:H25)/(H22+H23)-1,-$K$7)*SUM(H22:H23) -> 2.7260834e-11 | I26: =+IF(I16<$K$5,SUM(I24:I25)/(I22+I23)-1,-$K$7)*SUM(I22:I23) -> -4731.833 | J26: =+IF(J16<$K$5,SUM(J24:J25)/(J22+J23)-1,-$K$7)*SUM(J22:J23) -> -9483.382 | K26: =+IF(K16<$K$5,SUM(K24:K25)/(K22+K23)-1,-$K$7)*SUM(K22:K23) -> -14254.708 | L26: =+IF(L16<$K$5,SUM(L24:L25)/(L22+L23)-1,-$K$7)*SUM(L22:L23) -> -14284.406 | M26: =+IF(M16<$K$5,SUM(M24:M25)/(M22+M23)-1,-$K$7)*SUM(M22:M23) -> -14314.165 | N26: =+IF(N16<$K$5,SUM(N24:N25)/(N22+N23)-1,-$K$7)*SUM(N22:N23) -> -14343.986 | O26: =+IF(O16<$K$5,SUM(O24:O25)/(O22+O23)-1,-$K$7)*SUM(O22:O23) -> -14373.869 | ... EI26: =+IF(EI16<$K$5,SUM(EI24:EI25)/(EI22+EI23)-1,-$K$7)*SUM(EI22:EI23) -> -12477.141
B27: Vacancy | H27: =-H26/(H22+H23) -> -2.220446e-16 | I27: =-I26/(I22+I23) -> 0.038461538 | J27: =-J26/(J22+J23) -> 0.076923077 | K27: =-K26/(K22+K23) -> 0.11538462 | L27: =-L26/(L22+L23) -> 0.1130048 | M27: =-M26/(M22+M23) -> 0.11072117 | N27: =-N26/(N22+N23) -> 0.10852801 | O27: =-O26/(O22+O23) -> 0.10642004 | ... EI27: =-EI26/(EI22+EI23) -> 0.05
B28: =B5&" Income" -> Parking Income | H28: =IF(H$16<Assumptions!$D127,0,$C5*H$20*H$11*$A5) -> 5273.775 | I28: =IF(I$16<Assumptions!$D127,0,$C5*I$20*I$11*$A5) -> 5079.3891 | J28: =IF(J$16<Assumptions!$D127,0,$C5*J$20*J$11*$A5) -> 4884.3405 | K28: =IF(K$16<Assumptions!$D127,0,$C5*K$20*K$11*$A5) -> 4688.6277 | L28: =IF(L$16<Assumptions!$D127,0,$C5*L$20*L$11*$A5) -> 4696.4421 | M28: =IF(M$16<Assumptions!$D127,0,$C5*M$20*M$11*$A5) -> 4704.2695 | N28: =IF(N$16<Assumptions!$D127,0,$C5*N$20*N$11*$A5) -> 4712.1099 | O28: =IF(O$16<Assumptions!$D127,0,$C5*O$20*O$11*$A5) -> 4719.9635 | ... EI28: =IF(EI$16<Assumptions!$D127,0,$C5*EI$20*EI$11*$A5) -> 6559.3927
B29: =B6&" Income" -> Storage Income | H29: =IF(H$16<Assumptions!$D128,0,$C6*H$20*H$11*$A6) -> 0 | I29: =IF(I$16<Assumptions!$D128,0,$C6*I$20*I$11*$A6) -> 0 | J29: =IF(J$16<Assumptions!$D128,0,$C6*J$20*J$11*$A6) -> 0 | K29: =IF(K$16<Assumptions!$D128,0,$C6*K$20*K$11*$A6) -> 0 | L29: =IF(L$16<Assumptions!$D128,0,$C6*L$20*L$11*$A6) -> 0 | M29: =IF(M$16<Assumptions!$D128,0,$C6*M$20*M$11*$A6) -> 1568.0898 | N29: =IF(N$16<Assumptions!$D128,0,$C6*N$20*N$11*$A6) -> 1570.7033 | O29: =IF(O$16<Assumptions!$D128,0,$C6*O$20*O$11*$A6) -> 1573.3212 | ... EI29: =IF(EI$16<Assumptions!$D128,0,$C6*EI$20*EI$11*$A6) -> 2186.4642
B30: =B7&" Income" -> Laundry Income | H30: =IF(H$16<Assumptions!$D129,0,$C7*H$20*H$11*$A7) -> 859.43 | I30: =IF(I$16<Assumptions!$D129,0,$C7*I$20*I$11*$A7) -> 827.75229 | J30: =IF(J$16<Assumptions!$D129,0,$C7*J$20*J$11*$A7) -> 795.9666 | K30: =IF(K$16<Assumptions!$D129,0,$C7*K$20*K$11*$A7) -> 764.07266 | L30: =IF(L$16<Assumptions!$D129,0,$C7*L$20*L$11*$A7) -> 765.34612 | M30: =IF(M$16<Assumptions!$D129,0,$C7*M$20*M$11*$A7) -> 766.6217 | N30: =IF(N$16<Assumptions!$D129,0,$C7*N$20*N$11*$A7) -> 767.8994 | O30: =IF(O$16<Assumptions!$D129,0,$C7*O$20*O$11*$A7) -> 769.17923 | ... EI30: =IF(EI$16<Assumptions!$D129,0,$C7*EI$20*EI$11*$A7) -> 1068.9381
